[2025-06-23T13:41:09.539+0000] {processor.py:186} INFO - Started process (PID=130) to work on /home/airflow/.local/lib/python3.12/site-packages/airflow/example_dags/subdags/subdag.py
[2025-06-23T13:41:09.540+0000] {processor.py:914} INFO - Processing file /home/airflow/.local/lib/python3.12/site-packages/airflow/example_dags/subdags/subdag.py for tasks to queue
[2025-06-23T13:41:09.545+0000] {logging_mixin.py:190} INFO - [2025-06-23T13:41:09.544+0000] {dagbag.py:588} INFO - Filling up the DagBag from /home/airflow/.local/lib/python3.12/site-packages/airflow/example_dags/subdags/subdag.py
[2025-06-23T13:41:09.549+0000] {processor.py:927} WARNING - No viable dags retrieved from /home/airflow/.local/lib/python3.12/site-packages/airflow/example_dags/subdags/subdag.py
[2025-06-23T13:41:09.574+0000] {processor.py:208} INFO - Processing /home/airflow/.local/lib/python3.12/site-packages/airflow/example_dags/subdags/subdag.py took 0.044 seconds
[2025-06-23T13:41:39.667+0000] {processor.py:186} INFO - Started process (PID=192) to work on /home/airflow/.local/lib/python3.12/site-packages/airflow/example_dags/subdags/subdag.py
[2025-06-23T13:41:39.668+0000] {processor.py:914} INFO - Processing file /home/airflow/.local/lib/python3.12/site-packages/airflow/example_dags/subdags/subdag.py for tasks to queue
[2025-06-23T13:41:39.671+0000] {logging_mixin.py:190} INFO - [2025-06-23T13:41:39.671+0000] {dagbag.py:588} INFO - Filling up the DagBag from /home/airflow/.local/lib/python3.12/site-packages/airflow/example_dags/subdags/subdag.py
[2025-06-23T13:41:39.675+0000] {processor.py:927} WARNING - No viable dags retrieved from /home/airflow/.local/lib/python3.12/site-packages/airflow/example_dags/subdags/subdag.py
[2025-06-23T13:41:39.694+0000] {processor.py:208} INFO - Processing /home/airflow/.local/lib/python3.12/site-packages/airflow/example_dags/subdags/subdag.py took 0.034 seconds
[2025-06-23T13:42:10.350+0000] {processor.py:186} INFO - Started process (PID=256) to work on /home/airflow/.local/lib/python3.12/site-packages/airflow/example_dags/subdags/subdag.py
[2025-06-23T13:42:10.352+0000] {processor.py:914} INFO - Processing file /home/airflow/.local/lib/python3.12/site-packages/airflow/example_dags/subdags/subdag.py for tasks to queue
[2025-06-23T13:42:10.355+0000] {logging_mixin.py:190} INFO - [2025-06-23T13:42:10.355+0000] {dagbag.py:588} INFO - Filling up the DagBag from /home/airflow/.local/lib/python3.12/site-packages/airflow/example_dags/subdags/subdag.py
[2025-06-23T13:42:10.359+0000] {processor.py:927} WARNING - No viable dags retrieved from /home/airflow/.local/lib/python3.12/site-packages/airflow/example_dags/subdags/subdag.py
[2025-06-23T13:42:10.379+0000] {processor.py:208} INFO - Processing /home/airflow/.local/lib/python3.12/site-packages/airflow/example_dags/subdags/subdag.py took 0.036 seconds
[2025-06-23T13:42:55.494+0000] {processor.py:186} INFO - Started process (PID=325) to work on /home/airflow/.local/lib/python3.12/site-packages/airflow/example_dags/subdags/subdag.py
[2025-06-23T13:42:55.500+0000] {processor.py:914} INFO - Processing file /home/airflow/.local/lib/python3.12/site-packages/airflow/example_dags/subdags/subdag.py for tasks to queue
[2025-06-23T13:42:55.512+0000] {logging_mixin.py:190} INFO - [2025-06-23T13:42:55.511+0000] {dagbag.py:588} INFO - Filling up the DagBag from /home/airflow/.local/lib/python3.12/site-packages/airflow/example_dags/subdags/subdag.py
[2025-06-23T13:42:55.531+0000] {processor.py:927} WARNING - No viable dags retrieved from /home/airflow/.local/lib/python3.12/site-packages/airflow/example_dags/subdags/subdag.py
[2025-06-23T13:43:06.058+0000] {processor.py:211} ERROR - Got an exception! Propagating...
Traceback (most recent call last):
  File "/home/airflow/.local/lib/python3.12/site-packages/sqlalchemy/engine/base.py", line 3371, in _wrap_pool_connect
    return fn()
           ^^^^
  File "/home/airflow/.local/lib/python3.12/site-packages/sqlalchemy/pool/base.py", line 327, in connect
    return _ConnectionFairy._checkout(self)
           ^^^^^^^^^^^^^^^^^^^^^^^^^^^^^^^^
  File "/home/airflow/.local/lib/python3.12/site-packages/sqlalchemy/pool/base.py", line 894, in _checkout
    fairy = _ConnectionRecord.checkout(pool)
            ^^^^^^^^^^^^^^^^^^^^^^^^^^^^^^^^
  File "/home/airflow/.local/lib/python3.12/site-packages/sqlalchemy/pool/base.py", line 493, in checkout
    rec = pool._do_get()
          ^^^^^^^^^^^^^^
  File "/home/airflow/.local/lib/python3.12/site-packages/sqlalchemy/pool/impl.py", line 145, in _do_get
    with util.safe_reraise():
         ^^^^^^^^^^^^^^^^^^^
  File "/home/airflow/.local/lib/python3.12/site-packages/sqlalchemy/util/langhelpers.py", line 70, in __exit__
    compat.raise_(
  File "/home/airflow/.local/lib/python3.12/site-packages/sqlalchemy/util/compat.py", line 211, in raise_
    raise exception
  File "/home/airflow/.local/lib/python3.12/site-packages/sqlalchemy/pool/impl.py", line 143, in _do_get
    return self._create_connection()
           ^^^^^^^^^^^^^^^^^^^^^^^^^
  File "/home/airflow/.local/lib/python3.12/site-packages/sqlalchemy/pool/base.py", line 273, in _create_connection
    return _ConnectionRecord(self)
           ^^^^^^^^^^^^^^^^^^^^^^^
  File "/home/airflow/.local/lib/python3.12/site-packages/sqlalchemy/pool/base.py", line 388, in __init__
    self.__connect()
  File "/home/airflow/.local/lib/python3.12/site-packages/sqlalchemy/pool/base.py", line 690, in __connect
    with util.safe_reraise():
         ^^^^^^^^^^^^^^^^^^^
  File "/home/airflow/.local/lib/python3.12/site-packages/sqlalchemy/util/langhelpers.py", line 70, in __exit__
    compat.raise_(
  File "/home/airflow/.local/lib/python3.12/site-packages/sqlalchemy/util/compat.py", line 211, in raise_
    raise exception
  File "/home/airflow/.local/lib/python3.12/site-packages/sqlalchemy/pool/base.py", line 686, in __connect
    self.dbapi_connection = connection = pool._invoke_creator(self)
                                         ^^^^^^^^^^^^^^^^^^^^^^^^^^
  File "/home/airflow/.local/lib/python3.12/site-packages/sqlalchemy/engine/create.py", line 574, in connect
    return dialect.connect(*cargs, **cparams)
           ^^^^^^^^^^^^^^^^^^^^^^^^^^^^^^^^^^
  File "/home/airflow/.local/lib/python3.12/site-packages/sqlalchemy/engine/default.py", line 598, in connect
    return self.dbapi.connect(*cargs, **cparams)
           ^^^^^^^^^^^^^^^^^^^^^^^^^^^^^^^^^^^^^
  File "/home/airflow/.local/lib/python3.12/site-packages/psycopg2/__init__.py", line 122, in connect
    conn = _connect(dsn, connection_factory=connection_factory, **kwasync)
           ^^^^^^^^^^^^^^^^^^^^^^^^^^^^^^^^^^^^^^^^^^^^^^^^^^^^^^^^^^^^^^^
psycopg2.OperationalError: could not translate host name "postgres" to address: Temporary failure in name resolution


The above exception was the direct cause of the following exception:

Traceback (most recent call last):
  File "/home/airflow/.local/lib/python3.12/site-packages/airflow/dag_processing/processor.py", line 207, in _run_file_processor
    _handle_dag_file_processing()
  File "/home/airflow/.local/lib/python3.12/site-packages/airflow/dag_processing/processor.py", line 188, in _handle_dag_file_processing
    result: tuple[int, int, int] = dag_file_processor.process_file(
                                   ^^^^^^^^^^^^^^^^^^^^^^^^^^^^^^^^
  File "/home/airflow/.local/lib/python3.12/site-packages/airflow/utils/session.py", line 97, in wrapper
    return func(*args, session=session, **kwargs)
           ^^^^^^^^^^^^^^^^^^^^^^^^^^^^^^^^^^^^^^
  File "/home/airflow/.local/lib/python3.12/site-packages/airflow/dag_processing/processor.py", line 928, in process_file
    DagFileProcessor.update_import_errors(
  File "/home/airflow/.local/lib/python3.12/site-packages/airflow/api_internal/internal_api_call.py", line 166, in wrapper
    return func(*args, **kwargs)
           ^^^^^^^^^^^^^^^^^^^^^
  File "/home/airflow/.local/lib/python3.12/site-packages/airflow/utils/session.py", line 97, in wrapper
    return func(*args, session=session, **kwargs)
           ^^^^^^^^^^^^^^^^^^^^^^^^^^^^^^^^^^^^^^
  File "/home/airflow/.local/lib/python3.12/site-packages/airflow/dag_processing/processor.py", line 641, in update_import_errors
    session.execute(
  File "/home/airflow/.local/lib/python3.12/site-packages/sqlalchemy/orm/session.py", line 1716, in execute
    conn = self._connection_for_bind(bind)
           ^^^^^^^^^^^^^^^^^^^^^^^^^^^^^^^
  File "/home/airflow/.local/lib/python3.12/site-packages/sqlalchemy/orm/session.py", line 1555, in _connection_for_bind
    return self._transaction._connection_for_bind(
           ^^^^^^^^^^^^^^^^^^^^^^^^^^^^^^^^^^^^^^^
  File "/home/airflow/.local/lib/python3.12/site-packages/sqlalchemy/orm/session.py", line 750, in _connection_for_bind
    conn = bind.connect()
           ^^^^^^^^^^^^^^
  File "/home/airflow/.local/lib/python3.12/site-packages/sqlalchemy/future/engine.py", line 412, in connect
    return super(Engine, self).connect()
           ^^^^^^^^^^^^^^^^^^^^^^^^^^^^^
  File "/home/airflow/.local/lib/python3.12/site-packages/sqlalchemy/engine/base.py", line 3325, in connect
    return self._connection_cls(self, close_with_result=close_with_result)
           ^^^^^^^^^^^^^^^^^^^^^^^^^^^^^^^^^^^^^^^^^^^^^^^^^^^^^^^^^^^^^^^
  File "/home/airflow/.local/lib/python3.12/site-packages/sqlalchemy/engine/base.py", line 96, in __init__
    else engine.raw_connection()
         ^^^^^^^^^^^^^^^^^^^^^^^
  File "/home/airflow/.local/lib/python3.12/site-packages/sqlalchemy/engine/base.py", line 3404, in raw_connection
    return self._wrap_pool_connect(self.pool.connect, _connection)
           ^^^^^^^^^^^^^^^^^^^^^^^^^^^^^^^^^^^^^^^^^^^^^^^^^^^^^^^
  File "/home/airflow/.local/lib/python3.12/site-packages/sqlalchemy/engine/base.py", line 3374, in _wrap_pool_connect
    Connection._handle_dbapi_exception_noconnection(
  File "/home/airflow/.local/lib/python3.12/site-packages/sqlalchemy/engine/base.py", line 2208, in _handle_dbapi_exception_noconnection
    util.raise_(
  File "/home/airflow/.local/lib/python3.12/site-packages/sqlalchemy/util/compat.py", line 211, in raise_
    raise exception
  File "/home/airflow/.local/lib/python3.12/site-packages/sqlalchemy/engine/base.py", line 3371, in _wrap_pool_connect
    return fn()
           ^^^^
  File "/home/airflow/.local/lib/python3.12/site-packages/sqlalchemy/pool/base.py", line 327, in connect
    return _ConnectionFairy._checkout(self)
           ^^^^^^^^^^^^^^^^^^^^^^^^^^^^^^^^
  File "/home/airflow/.local/lib/python3.12/site-packages/sqlalchemy/pool/base.py", line 894, in _checkout
    fairy = _ConnectionRecord.checkout(pool)
            ^^^^^^^^^^^^^^^^^^^^^^^^^^^^^^^^
  File "/home/airflow/.local/lib/python3.12/site-packages/sqlalchemy/pool/base.py", line 493, in checkout
    rec = pool._do_get()
          ^^^^^^^^^^^^^^
  File "/home/airflow/.local/lib/python3.12/site-packages/sqlalchemy/pool/impl.py", line 145, in _do_get
    with util.safe_reraise():
         ^^^^^^^^^^^^^^^^^^^
  File "/home/airflow/.local/lib/python3.12/site-packages/sqlalchemy/util/langhelpers.py", line 70, in __exit__
    compat.raise_(
  File "/home/airflow/.local/lib/python3.12/site-packages/sqlalchemy/util/compat.py", line 211, in raise_
    raise exception
  File "/home/airflow/.local/lib/python3.12/site-packages/sqlalchemy/pool/impl.py", line 143, in _do_get
    return self._create_connection()
           ^^^^^^^^^^^^^^^^^^^^^^^^^
  File "/home/airflow/.local/lib/python3.12/site-packages/sqlalchemy/pool/base.py", line 273, in _create_connection
    return _ConnectionRecord(self)
           ^^^^^^^^^^^^^^^^^^^^^^^
  File "/home/airflow/.local/lib/python3.12/site-packages/sqlalchemy/pool/base.py", line 388, in __init__
    self.__connect()
  File "/home/airflow/.local/lib/python3.12/site-packages/sqlalchemy/pool/base.py", line 690, in __connect
    with util.safe_reraise():
         ^^^^^^^^^^^^^^^^^^^
  File "/home/airflow/.local/lib/python3.12/site-packages/sqlalchemy/util/langhelpers.py", line 70, in __exit__
    compat.raise_(
  File "/home/airflow/.local/lib/python3.12/site-packages/sqlalchemy/util/compat.py", line 211, in raise_
    raise exception
  File "/home/airflow/.local/lib/python3.12/site-packages/sqlalchemy/pool/base.py", line 686, in __connect
    self.dbapi_connection = connection = pool._invoke_creator(self)
                                         ^^^^^^^^^^^^^^^^^^^^^^^^^^
  File "/home/airflow/.local/lib/python3.12/site-packages/sqlalchemy/engine/create.py", line 574, in connect
    return dialect.connect(*cargs, **cparams)
           ^^^^^^^^^^^^^^^^^^^^^^^^^^^^^^^^^^
  File "/home/airflow/.local/lib/python3.12/site-packages/sqlalchemy/engine/default.py", line 598, in connect
    return self.dbapi.connect(*cargs, **cparams)
           ^^^^^^^^^^^^^^^^^^^^^^^^^^^^^^^^^^^^^
  File "/home/airflow/.local/lib/python3.12/site-packages/psycopg2/__init__.py", line 122, in connect
    conn = _connect(dsn, connection_factory=connection_factory, **kwasync)
           ^^^^^^^^^^^^^^^^^^^^^^^^^^^^^^^^^^^^^^^^^^^^^^^^^^^^^^^^^^^^^^^
sqlalchemy.exc.OperationalError: (psycopg2.OperationalError) could not translate host name "postgres" to address: Temporary failure in name resolution

(Background on this error at: https://sqlalche.me/e/14/e3q8)
[2025-06-23T13:43:45.446+0000] {processor.py:186} INFO - Started process (PID=387) to work on /home/airflow/.local/lib/python3.12/site-packages/airflow/example_dags/subdags/subdag.py
[2025-06-23T13:43:45.448+0000] {processor.py:914} INFO - Processing file /home/airflow/.local/lib/python3.12/site-packages/airflow/example_dags/subdags/subdag.py for tasks to queue
[2025-06-23T13:43:45.453+0000] {logging_mixin.py:190} INFO - [2025-06-23T13:43:45.451+0000] {dagbag.py:588} INFO - Filling up the DagBag from /home/airflow/.local/lib/python3.12/site-packages/airflow/example_dags/subdags/subdag.py
[2025-06-23T13:43:45.459+0000] {processor.py:927} WARNING - No viable dags retrieved from /home/airflow/.local/lib/python3.12/site-packages/airflow/example_dags/subdags/subdag.py
[2025-06-23T13:43:45.493+0000] {processor.py:208} INFO - Processing /home/airflow/.local/lib/python3.12/site-packages/airflow/example_dags/subdags/subdag.py took 0.058 seconds
[2025-06-23T13:44:16.186+0000] {processor.py:186} INFO - Started process (PID=450) to work on /home/airflow/.local/lib/python3.12/site-packages/airflow/example_dags/subdags/subdag.py
[2025-06-23T13:44:16.188+0000] {processor.py:914} INFO - Processing file /home/airflow/.local/lib/python3.12/site-packages/airflow/example_dags/subdags/subdag.py for tasks to queue
[2025-06-23T13:44:16.191+0000] {logging_mixin.py:190} INFO - [2025-06-23T13:44:16.191+0000] {dagbag.py:588} INFO - Filling up the DagBag from /home/airflow/.local/lib/python3.12/site-packages/airflow/example_dags/subdags/subdag.py
[2025-06-23T13:44:16.195+0000] {processor.py:927} WARNING - No viable dags retrieved from /home/airflow/.local/lib/python3.12/site-packages/airflow/example_dags/subdags/subdag.py
[2025-06-23T13:44:16.219+0000] {processor.py:208} INFO - Processing /home/airflow/.local/lib/python3.12/site-packages/airflow/example_dags/subdags/subdag.py took 0.042 seconds
[2025-06-23T13:44:46.306+0000] {processor.py:186} INFO - Started process (PID=513) to work on /home/airflow/.local/lib/python3.12/site-packages/airflow/example_dags/subdags/subdag.py
[2025-06-23T13:44:46.307+0000] {processor.py:914} INFO - Processing file /home/airflow/.local/lib/python3.12/site-packages/airflow/example_dags/subdags/subdag.py for tasks to queue
[2025-06-23T13:44:46.311+0000] {logging_mixin.py:190} INFO - [2025-06-23T13:44:46.311+0000] {dagbag.py:588} INFO - Filling up the DagBag from /home/airflow/.local/lib/python3.12/site-packages/airflow/example_dags/subdags/subdag.py
[2025-06-23T13:44:46.316+0000] {processor.py:927} WARNING - No viable dags retrieved from /home/airflow/.local/lib/python3.12/site-packages/airflow/example_dags/subdags/subdag.py
[2025-06-23T13:44:46.336+0000] {processor.py:208} INFO - Processing /home/airflow/.local/lib/python3.12/site-packages/airflow/example_dags/subdags/subdag.py took 0.041 seconds
