[2025-08-18T22:23:59.242+0000] {processor.py:161} INFO - Started process (PID=206) to work on /opt/airflow/dags/generate_data.py
[2025-08-18T22:23:59.244+0000] {processor.py:830} INFO - Processing file /opt/airflow/dags/generate_data.py for tasks to queue
[2025-08-18T22:23:59.247+0000] {logging_mixin.py:188} INFO - [2025-08-18T22:23:59.246+0000] {dagbag.py:540} INFO - Filling up the DagBag from /opt/airflow/dags/generate_data.py
[2025-08-18T22:24:01.096+0000] {processor.py:840} INFO - DAG(s) 'generate_data' retrieved from /opt/airflow/dags/generate_data.py
[2025-08-18T22:24:01.978+0000] {logging_mixin.py:188} INFO - [2025-08-18T22:24:01.976+0000] {override.py:1769} INFO - Created Permission View: can delete on DAG:generate_data
[2025-08-18T22:24:02.022+0000] {logging_mixin.py:188} INFO - [2025-08-18T22:24:02.020+0000] {override.py:1769} INFO - Created Permission View: can edit on DAG:generate_data
[2025-08-18T22:24:02.047+0000] {logging_mixin.py:188} INFO - [2025-08-18T22:24:02.046+0000] {override.py:1769} INFO - Created Permission View: can read on DAG:generate_data
[2025-08-18T22:24:02.050+0000] {logging_mixin.py:188} INFO - [2025-08-18T22:24:02.049+0000] {dag.py:3047} INFO - Sync 1 DAGs
[2025-08-18T22:24:02.123+0000] {logging_mixin.py:188} INFO - [2025-08-18T22:24:02.122+0000] {dag.py:3069} INFO - Creating ORM DAG for generate_data
[2025-08-18T22:24:02.187+0000] {logging_mixin.py:188} INFO - [2025-08-18T22:24:02.186+0000] {dag.py:3834} INFO - Setting next_dagrun for generate_data to 2025-08-17 00:00:00+00:00, run_after=2025-08-18 00:00:00+00:00
[2025-08-18T22:24:02.247+0000] {processor.py:183} INFO - Processing /opt/airflow/dags/generate_data.py took 3.021 seconds
[2025-08-18T22:24:32.520+0000] {processor.py:161} INFO - Started process (PID=217) to work on /opt/airflow/dags/generate_data.py
[2025-08-18T22:24:32.522+0000] {processor.py:830} INFO - Processing file /opt/airflow/dags/generate_data.py for tasks to queue
[2025-08-18T22:24:32.526+0000] {logging_mixin.py:188} INFO - [2025-08-18T22:24:32.524+0000] {dagbag.py:540} INFO - Filling up the DagBag from /opt/airflow/dags/generate_data.py
[2025-08-18T22:24:32.875+0000] {processor.py:840} INFO - DAG(s) 'generate_data' retrieved from /opt/airflow/dags/generate_data.py
[2025-08-18T22:24:32.984+0000] {logging_mixin.py:188} INFO - [2025-08-18T22:24:32.984+0000] {dag.py:3047} INFO - Sync 1 DAGs
[2025-08-18T22:24:33.117+0000] {logging_mixin.py:188} INFO - [2025-08-18T22:24:33.117+0000] {dag.py:3834} INFO - Setting next_dagrun for generate_data to 2025-08-17 00:00:00+00:00, run_after=2025-08-18 00:00:00+00:00
[2025-08-18T22:24:33.189+0000] {processor.py:183} INFO - Processing /opt/airflow/dags/generate_data.py took 0.675 seconds
[2025-08-18T22:25:03.538+0000] {processor.py:161} INFO - Started process (PID=229) to work on /opt/airflow/dags/generate_data.py
[2025-08-18T22:25:03.539+0000] {processor.py:830} INFO - Processing file /opt/airflow/dags/generate_data.py for tasks to queue
[2025-08-18T22:25:03.541+0000] {logging_mixin.py:188} INFO - [2025-08-18T22:25:03.540+0000] {dagbag.py:540} INFO - Filling up the DagBag from /opt/airflow/dags/generate_data.py
[2025-08-18T22:25:03.874+0000] {processor.py:840} INFO - DAG(s) 'generate_data' retrieved from /opt/airflow/dags/generate_data.py
[2025-08-18T22:25:03.931+0000] {logging_mixin.py:188} INFO - [2025-08-18T22:25:03.930+0000] {dag.py:3047} INFO - Sync 1 DAGs
[2025-08-18T22:25:03.978+0000] {logging_mixin.py:188} INFO - [2025-08-18T22:25:03.977+0000] {dag.py:3834} INFO - Setting next_dagrun for generate_data to 2025-08-17 00:00:00+00:00, run_after=2025-08-18 00:00:00+00:00
[2025-08-18T22:25:04.014+0000] {processor.py:183} INFO - Processing /opt/airflow/dags/generate_data.py took 0.480 seconds
[2025-08-18T22:25:34.155+0000] {processor.py:161} INFO - Started process (PID=240) to work on /opt/airflow/dags/generate_data.py
[2025-08-18T22:25:34.156+0000] {processor.py:830} INFO - Processing file /opt/airflow/dags/generate_data.py for tasks to queue
[2025-08-18T22:25:34.158+0000] {logging_mixin.py:188} INFO - [2025-08-18T22:25:34.157+0000] {dagbag.py:540} INFO - Filling up the DagBag from /opt/airflow/dags/generate_data.py
[2025-08-18T22:25:34.564+0000] {processor.py:840} INFO - DAG(s) 'generate_data' retrieved from /opt/airflow/dags/generate_data.py
[2025-08-18T22:25:34.631+0000] {logging_mixin.py:188} INFO - [2025-08-18T22:25:34.631+0000] {dag.py:3047} INFO - Sync 1 DAGs
[2025-08-18T22:25:34.702+0000] {logging_mixin.py:188} INFO - [2025-08-18T22:25:34.702+0000] {dag.py:3834} INFO - Setting next_dagrun for generate_data to 2025-08-17 00:00:00+00:00, run_after=2025-08-18 00:00:00+00:00
[2025-08-18T22:25:34.745+0000] {processor.py:183} INFO - Processing /opt/airflow/dags/generate_data.py took 0.594 seconds
[2025-08-18T22:26:05.169+0000] {processor.py:161} INFO - Started process (PID=251) to work on /opt/airflow/dags/generate_data.py
[2025-08-18T22:26:05.172+0000] {processor.py:830} INFO - Processing file /opt/airflow/dags/generate_data.py for tasks to queue
[2025-08-18T22:26:05.176+0000] {logging_mixin.py:188} INFO - [2025-08-18T22:26:05.175+0000] {dagbag.py:540} INFO - Filling up the DagBag from /opt/airflow/dags/generate_data.py
[2025-08-18T22:26:05.643+0000] {processor.py:840} INFO - DAG(s) 'generate_data' retrieved from /opt/airflow/dags/generate_data.py
[2025-08-18T22:26:05.731+0000] {logging_mixin.py:188} INFO - [2025-08-18T22:26:05.731+0000] {dag.py:3047} INFO - Sync 1 DAGs
[2025-08-18T22:26:05.794+0000] {logging_mixin.py:188} INFO - [2025-08-18T22:26:05.793+0000] {dag.py:3834} INFO - Setting next_dagrun for generate_data to 2025-08-17 00:00:00+00:00, run_after=2025-08-18 00:00:00+00:00
[2025-08-18T22:26:05.841+0000] {processor.py:183} INFO - Processing /opt/airflow/dags/generate_data.py took 0.685 seconds
[2025-08-18T22:26:36.064+0000] {processor.py:161} INFO - Started process (PID=263) to work on /opt/airflow/dags/generate_data.py
[2025-08-18T22:26:36.065+0000] {processor.py:830} INFO - Processing file /opt/airflow/dags/generate_data.py for tasks to queue
[2025-08-18T22:26:36.066+0000] {logging_mixin.py:188} INFO - [2025-08-18T22:26:36.066+0000] {dagbag.py:540} INFO - Filling up the DagBag from /opt/airflow/dags/generate_data.py
[2025-08-18T22:26:36.256+0000] {processor.py:840} INFO - DAG(s) 'generate_data' retrieved from /opt/airflow/dags/generate_data.py
[2025-08-18T22:26:36.292+0000] {logging_mixin.py:188} INFO - [2025-08-18T22:26:36.292+0000] {dag.py:3047} INFO - Sync 1 DAGs
[2025-08-18T22:26:36.325+0000] {logging_mixin.py:188} INFO - [2025-08-18T22:26:36.324+0000] {dag.py:3834} INFO - Setting next_dagrun for generate_data to 2025-08-17 00:00:00+00:00, run_after=2025-08-18 00:00:00+00:00
[2025-08-18T22:26:36.357+0000] {processor.py:183} INFO - Processing /opt/airflow/dags/generate_data.py took 0.298 seconds
[2025-08-18T22:27:06.615+0000] {processor.py:161} INFO - Started process (PID=275) to work on /opt/airflow/dags/generate_data.py
[2025-08-18T22:27:06.617+0000] {processor.py:830} INFO - Processing file /opt/airflow/dags/generate_data.py for tasks to queue
[2025-08-18T22:27:06.620+0000] {logging_mixin.py:188} INFO - [2025-08-18T22:27:06.619+0000] {dagbag.py:540} INFO - Filling up the DagBag from /opt/airflow/dags/generate_data.py
[2025-08-18T22:27:06.973+0000] {processor.py:840} INFO - DAG(s) 'generate_data' retrieved from /opt/airflow/dags/generate_data.py
[2025-08-18T22:27:07.022+0000] {logging_mixin.py:188} INFO - [2025-08-18T22:27:07.022+0000] {dag.py:3047} INFO - Sync 1 DAGs
[2025-08-18T22:27:07.057+0000] {logging_mixin.py:188} INFO - [2025-08-18T22:27:07.056+0000] {dag.py:3834} INFO - Setting next_dagrun for generate_data to 2025-08-17 00:00:00+00:00, run_after=2025-08-18 00:00:00+00:00
[2025-08-18T22:27:07.090+0000] {processor.py:183} INFO - Processing /opt/airflow/dags/generate_data.py took 0.482 seconds
[2025-08-18T22:27:37.418+0000] {processor.py:161} INFO - Started process (PID=286) to work on /opt/airflow/dags/generate_data.py
[2025-08-18T22:27:37.419+0000] {processor.py:830} INFO - Processing file /opt/airflow/dags/generate_data.py for tasks to queue
[2025-08-18T22:27:37.421+0000] {logging_mixin.py:188} INFO - [2025-08-18T22:27:37.420+0000] {dagbag.py:540} INFO - Filling up the DagBag from /opt/airflow/dags/generate_data.py
[2025-08-18T22:27:37.743+0000] {processor.py:840} INFO - DAG(s) 'generate_data' retrieved from /opt/airflow/dags/generate_data.py
[2025-08-18T22:27:37.818+0000] {logging_mixin.py:188} INFO - [2025-08-18T22:27:37.818+0000] {dag.py:3047} INFO - Sync 1 DAGs
[2025-08-18T22:27:37.871+0000] {logging_mixin.py:188} INFO - [2025-08-18T22:27:37.870+0000] {dag.py:3834} INFO - Setting next_dagrun for generate_data to 2025-08-17 00:00:00+00:00, run_after=2025-08-18 00:00:00+00:00
[2025-08-18T22:27:37.921+0000] {processor.py:183} INFO - Processing /opt/airflow/dags/generate_data.py took 0.508 seconds
[2025-08-18T22:28:08.287+0000] {processor.py:161} INFO - Started process (PID=301) to work on /opt/airflow/dags/generate_data.py
[2025-08-18T22:28:08.288+0000] {processor.py:830} INFO - Processing file /opt/airflow/dags/generate_data.py for tasks to queue
[2025-08-18T22:28:08.291+0000] {logging_mixin.py:188} INFO - [2025-08-18T22:28:08.289+0000] {dagbag.py:540} INFO - Filling up the DagBag from /opt/airflow/dags/generate_data.py
[2025-08-18T22:28:08.563+0000] {processor.py:840} INFO - DAG(s) 'generate_data' retrieved from /opt/airflow/dags/generate_data.py
[2025-08-18T22:28:08.671+0000] {logging_mixin.py:188} INFO - [2025-08-18T22:28:08.671+0000] {dag.py:3047} INFO - Sync 1 DAGs
[2025-08-18T22:28:08.716+0000] {logging_mixin.py:188} INFO - [2025-08-18T22:28:08.716+0000] {dag.py:3834} INFO - Setting next_dagrun for generate_data to 2025-08-18 00:00:00+00:00, run_after=2025-08-19 00:00:00+00:00
[2025-08-18T22:28:08.750+0000] {processor.py:183} INFO - Processing /opt/airflow/dags/generate_data.py took 0.469 seconds
[2025-08-18T22:28:39.028+0000] {processor.py:161} INFO - Started process (PID=312) to work on /opt/airflow/dags/generate_data.py
[2025-08-18T22:28:39.030+0000] {processor.py:830} INFO - Processing file /opt/airflow/dags/generate_data.py for tasks to queue
[2025-08-18T22:28:39.032+0000] {logging_mixin.py:188} INFO - [2025-08-18T22:28:39.031+0000] {dagbag.py:540} INFO - Filling up the DagBag from /opt/airflow/dags/generate_data.py
[2025-08-18T22:28:39.398+0000] {processor.py:840} INFO - DAG(s) 'generate_data' retrieved from /opt/airflow/dags/generate_data.py
[2025-08-18T22:28:39.573+0000] {logging_mixin.py:188} INFO - [2025-08-18T22:28:39.572+0000] {dag.py:3047} INFO - Sync 1 DAGs
[2025-08-18T22:28:39.672+0000] {logging_mixin.py:188} INFO - [2025-08-18T22:28:39.672+0000] {dag.py:3834} INFO - Setting next_dagrun for generate_data to 2025-08-18 00:00:00+00:00, run_after=2025-08-19 00:00:00+00:00
[2025-08-18T22:28:39.735+0000] {processor.py:183} INFO - Processing /opt/airflow/dags/generate_data.py took 0.714 seconds
[2025-08-18T22:29:10.249+0000] {processor.py:161} INFO - Started process (PID=323) to work on /opt/airflow/dags/generate_data.py
[2025-08-18T22:29:10.251+0000] {processor.py:830} INFO - Processing file /opt/airflow/dags/generate_data.py for tasks to queue
[2025-08-18T22:29:10.254+0000] {logging_mixin.py:188} INFO - [2025-08-18T22:29:10.253+0000] {dagbag.py:540} INFO - Filling up the DagBag from /opt/airflow/dags/generate_data.py
[2025-08-18T22:29:10.641+0000] {processor.py:840} INFO - DAG(s) 'generate_data' retrieved from /opt/airflow/dags/generate_data.py
[2025-08-18T22:29:10.757+0000] {logging_mixin.py:188} INFO - [2025-08-18T22:29:10.757+0000] {dag.py:3047} INFO - Sync 1 DAGs
[2025-08-18T22:29:10.794+0000] {logging_mixin.py:188} INFO - [2025-08-18T22:29:10.794+0000] {dag.py:3834} INFO - Setting next_dagrun for generate_data to 2025-08-18 00:00:00+00:00, run_after=2025-08-19 00:00:00+00:00
[2025-08-18T22:29:10.829+0000] {processor.py:183} INFO - Processing /opt/airflow/dags/generate_data.py took 0.588 seconds
[2025-08-18T22:29:41.165+0000] {processor.py:161} INFO - Started process (PID=334) to work on /opt/airflow/dags/generate_data.py
[2025-08-18T22:29:41.166+0000] {processor.py:830} INFO - Processing file /opt/airflow/dags/generate_data.py for tasks to queue
[2025-08-18T22:29:41.168+0000] {logging_mixin.py:188} INFO - [2025-08-18T22:29:41.167+0000] {dagbag.py:540} INFO - Filling up the DagBag from /opt/airflow/dags/generate_data.py
[2025-08-18T22:29:41.430+0000] {processor.py:840} INFO - DAG(s) 'generate_data' retrieved from /opt/airflow/dags/generate_data.py
[2025-08-18T22:29:41.486+0000] {logging_mixin.py:188} INFO - [2025-08-18T22:29:41.485+0000] {dag.py:3047} INFO - Sync 1 DAGs
[2025-08-18T22:29:41.524+0000] {logging_mixin.py:188} INFO - [2025-08-18T22:29:41.524+0000] {dag.py:3834} INFO - Setting next_dagrun for generate_data to 2025-08-18 00:00:00+00:00, run_after=2025-08-19 00:00:00+00:00
[2025-08-18T22:29:41.560+0000] {processor.py:183} INFO - Processing /opt/airflow/dags/generate_data.py took 0.401 seconds
[2025-08-18T22:30:11.966+0000] {processor.py:161} INFO - Started process (PID=345) to work on /opt/airflow/dags/generate_data.py
[2025-08-18T22:30:11.967+0000] {processor.py:830} INFO - Processing file /opt/airflow/dags/generate_data.py for tasks to queue
[2025-08-18T22:30:11.970+0000] {logging_mixin.py:188} INFO - [2025-08-18T22:30:11.968+0000] {dagbag.py:540} INFO - Filling up the DagBag from /opt/airflow/dags/generate_data.py
[2025-08-18T22:30:12.400+0000] {processor.py:840} INFO - DAG(s) 'generate_data' retrieved from /opt/airflow/dags/generate_data.py
[2025-08-18T22:30:12.491+0000] {logging_mixin.py:188} INFO - [2025-08-18T22:30:12.490+0000] {dag.py:3047} INFO - Sync 1 DAGs
[2025-08-18T22:30:12.526+0000] {logging_mixin.py:188} INFO - [2025-08-18T22:30:12.525+0000] {dag.py:3834} INFO - Setting next_dagrun for generate_data to 2025-08-18 00:00:00+00:00, run_after=2025-08-19 00:00:00+00:00
[2025-08-18T22:30:12.556+0000] {processor.py:183} INFO - Processing /opt/airflow/dags/generate_data.py took 0.600 seconds
[2025-08-18T22:30:42.845+0000] {processor.py:161} INFO - Started process (PID=360) to work on /opt/airflow/dags/generate_data.py
[2025-08-18T22:30:42.846+0000] {processor.py:830} INFO - Processing file /opt/airflow/dags/generate_data.py for tasks to queue
[2025-08-18T22:30:42.848+0000] {logging_mixin.py:188} INFO - [2025-08-18T22:30:42.847+0000] {dagbag.py:540} INFO - Filling up the DagBag from /opt/airflow/dags/generate_data.py
[2025-08-18T22:30:43.150+0000] {processor.py:840} INFO - DAG(s) 'generate_data' retrieved from /opt/airflow/dags/generate_data.py
[2025-08-18T22:30:43.225+0000] {logging_mixin.py:188} INFO - [2025-08-18T22:30:43.224+0000] {dag.py:3047} INFO - Sync 1 DAGs
[2025-08-18T22:30:43.258+0000] {logging_mixin.py:188} INFO - [2025-08-18T22:30:43.258+0000] {dag.py:3834} INFO - Setting next_dagrun for generate_data to 2025-08-18 00:00:00+00:00, run_after=2025-08-19 00:00:00+00:00
[2025-08-18T22:30:43.290+0000] {processor.py:183} INFO - Processing /opt/airflow/dags/generate_data.py took 0.451 seconds
[2025-08-18T22:31:13.620+0000] {processor.py:161} INFO - Started process (PID=371) to work on /opt/airflow/dags/generate_data.py
[2025-08-18T22:31:13.621+0000] {processor.py:830} INFO - Processing file /opt/airflow/dags/generate_data.py for tasks to queue
[2025-08-18T22:31:13.628+0000] {logging_mixin.py:188} INFO - [2025-08-18T22:31:13.623+0000] {dagbag.py:540} INFO - Filling up the DagBag from /opt/airflow/dags/generate_data.py
[2025-08-18T22:31:13.932+0000] {processor.py:840} INFO - DAG(s) 'generate_data' retrieved from /opt/airflow/dags/generate_data.py
[2025-08-18T22:31:14.067+0000] {logging_mixin.py:188} INFO - [2025-08-18T22:31:14.067+0000] {dag.py:3047} INFO - Sync 1 DAGs
[2025-08-18T22:31:14.108+0000] {logging_mixin.py:188} INFO - [2025-08-18T22:31:14.108+0000] {dag.py:3834} INFO - Setting next_dagrun for generate_data to 2025-08-18 00:00:00+00:00, run_after=2025-08-19 00:00:00+00:00
[2025-08-18T22:31:14.148+0000] {processor.py:183} INFO - Processing /opt/airflow/dags/generate_data.py took 0.536 seconds
[2025-08-18T22:31:44.469+0000] {processor.py:161} INFO - Started process (PID=382) to work on /opt/airflow/dags/generate_data.py
[2025-08-18T22:31:44.470+0000] {processor.py:830} INFO - Processing file /opt/airflow/dags/generate_data.py for tasks to queue
[2025-08-18T22:31:44.474+0000] {logging_mixin.py:188} INFO - [2025-08-18T22:31:44.471+0000] {dagbag.py:540} INFO - Filling up the DagBag from /opt/airflow/dags/generate_data.py
[2025-08-18T22:31:44.881+0000] {processor.py:840} INFO - DAG(s) 'generate_data' retrieved from /opt/airflow/dags/generate_data.py
[2025-08-18T22:31:44.952+0000] {logging_mixin.py:188} INFO - [2025-08-18T22:31:44.951+0000] {dag.py:3047} INFO - Sync 1 DAGs
[2025-08-18T22:31:45.001+0000] {logging_mixin.py:188} INFO - [2025-08-18T22:31:45.001+0000] {dag.py:3834} INFO - Setting next_dagrun for generate_data to 2025-08-18 00:00:00+00:00, run_after=2025-08-19 00:00:00+00:00
[2025-08-18T22:31:45.052+0000] {processor.py:183} INFO - Processing /opt/airflow/dags/generate_data.py took 0.590 seconds
[2025-08-18T22:32:15.538+0000] {processor.py:161} INFO - Started process (PID=393) to work on /opt/airflow/dags/generate_data.py
[2025-08-18T22:32:15.541+0000] {processor.py:830} INFO - Processing file /opt/airflow/dags/generate_data.py for tasks to queue
[2025-08-18T22:32:15.550+0000] {logging_mixin.py:188} INFO - [2025-08-18T22:32:15.545+0000] {dagbag.py:540} INFO - Filling up the DagBag from /opt/airflow/dags/generate_data.py
[2025-08-18T22:32:16.148+0000] {processor.py:840} INFO - DAG(s) 'generate_data' retrieved from /opt/airflow/dags/generate_data.py
[2025-08-18T22:32:16.267+0000] {logging_mixin.py:188} INFO - [2025-08-18T22:32:16.267+0000] {dag.py:3047} INFO - Sync 1 DAGs
[2025-08-18T22:32:16.314+0000] {logging_mixin.py:188} INFO - [2025-08-18T22:32:16.313+0000] {dag.py:3834} INFO - Setting next_dagrun for generate_data to 2025-08-18 00:00:00+00:00, run_after=2025-08-19 00:00:00+00:00
[2025-08-18T22:32:16.360+0000] {processor.py:183} INFO - Processing /opt/airflow/dags/generate_data.py took 0.834 seconds
[2025-08-18T22:32:46.815+0000] {processor.py:161} INFO - Started process (PID=404) to work on /opt/airflow/dags/generate_data.py
[2025-08-18T22:32:46.817+0000] {processor.py:830} INFO - Processing file /opt/airflow/dags/generate_data.py for tasks to queue
[2025-08-18T22:32:46.821+0000] {logging_mixin.py:188} INFO - [2025-08-18T22:32:46.818+0000] {dagbag.py:540} INFO - Filling up the DagBag from /opt/airflow/dags/generate_data.py
[2025-08-18T22:32:47.209+0000] {processor.py:840} INFO - DAG(s) 'generate_data' retrieved from /opt/airflow/dags/generate_data.py
[2025-08-18T22:32:47.323+0000] {logging_mixin.py:188} INFO - [2025-08-18T22:32:47.323+0000] {dag.py:3047} INFO - Sync 1 DAGs
[2025-08-18T22:32:47.364+0000] {logging_mixin.py:188} INFO - [2025-08-18T22:32:47.363+0000] {dag.py:3834} INFO - Setting next_dagrun for generate_data to 2025-08-18 00:00:00+00:00, run_after=2025-08-19 00:00:00+00:00
[2025-08-18T22:32:47.398+0000] {processor.py:183} INFO - Processing /opt/airflow/dags/generate_data.py took 0.601 seconds
[2025-08-18T22:33:17.545+0000] {processor.py:161} INFO - Started process (PID=415) to work on /opt/airflow/dags/generate_data.py
[2025-08-18T22:33:17.548+0000] {processor.py:830} INFO - Processing file /opt/airflow/dags/generate_data.py for tasks to queue
[2025-08-18T22:33:17.561+0000] {logging_mixin.py:188} INFO - [2025-08-18T22:33:17.558+0000] {dagbag.py:540} INFO - Filling up the DagBag from /opt/airflow/dags/generate_data.py
[2025-08-18T22:33:18.014+0000] {processor.py:840} INFO - DAG(s) 'generate_data' retrieved from /opt/airflow/dags/generate_data.py
[2025-08-18T22:33:18.142+0000] {logging_mixin.py:188} INFO - [2025-08-18T22:33:18.141+0000] {dag.py:3047} INFO - Sync 1 DAGs
[2025-08-18T22:33:18.181+0000] {logging_mixin.py:188} INFO - [2025-08-18T22:33:18.180+0000] {dag.py:3834} INFO - Setting next_dagrun for generate_data to 2025-08-18 00:00:00+00:00, run_after=2025-08-19 00:00:00+00:00
[2025-08-18T22:33:18.216+0000] {processor.py:183} INFO - Processing /opt/airflow/dags/generate_data.py took 0.687 seconds
[2025-08-18T22:33:48.630+0000] {processor.py:161} INFO - Started process (PID=426) to work on /opt/airflow/dags/generate_data.py
[2025-08-18T22:33:48.709+0000] {processor.py:830} INFO - Processing file /opt/airflow/dags/generate_data.py for tasks to queue
[2025-08-18T22:33:48.715+0000] {logging_mixin.py:188} INFO - [2025-08-18T22:33:48.712+0000] {dagbag.py:540} INFO - Filling up the DagBag from /opt/airflow/dags/generate_data.py
[2025-08-18T22:33:49.304+0000] {processor.py:840} INFO - DAG(s) 'generate_data' retrieved from /opt/airflow/dags/generate_data.py
[2025-08-18T22:33:49.452+0000] {logging_mixin.py:188} INFO - [2025-08-18T22:33:49.452+0000] {dag.py:3047} INFO - Sync 1 DAGs
[2025-08-18T22:33:49.511+0000] {logging_mixin.py:188} INFO - [2025-08-18T22:33:49.510+0000] {dag.py:3834} INFO - Setting next_dagrun for generate_data to 2025-08-18 00:00:00+00:00, run_after=2025-08-19 00:00:00+00:00
[2025-08-18T22:33:49.558+0000] {processor.py:183} INFO - Processing /opt/airflow/dags/generate_data.py took 0.947 seconds
[2025-08-18T22:34:20.035+0000] {processor.py:161} INFO - Started process (PID=443) to work on /opt/airflow/dags/generate_data.py
[2025-08-18T22:34:20.037+0000] {processor.py:830} INFO - Processing file /opt/airflow/dags/generate_data.py for tasks to queue
[2025-08-18T22:34:20.041+0000] {logging_mixin.py:188} INFO - [2025-08-18T22:34:20.038+0000] {dagbag.py:540} INFO - Filling up the DagBag from /opt/airflow/dags/generate_data.py
[2025-08-18T22:34:20.506+0000] {processor.py:840} INFO - DAG(s) 'generate_data' retrieved from /opt/airflow/dags/generate_data.py
[2025-08-18T22:34:20.640+0000] {logging_mixin.py:188} INFO - [2025-08-18T22:34:20.640+0000] {dag.py:3047} INFO - Sync 1 DAGs
[2025-08-18T22:34:20.691+0000] {logging_mixin.py:188} INFO - [2025-08-18T22:34:20.690+0000] {dag.py:3834} INFO - Setting next_dagrun for generate_data to 2025-08-18 00:00:00+00:00, run_after=2025-08-19 00:00:00+00:00
[2025-08-18T22:34:20.735+0000] {processor.py:183} INFO - Processing /opt/airflow/dags/generate_data.py took 0.715 seconds
[2025-08-18T22:34:51.274+0000] {processor.py:161} INFO - Started process (PID=454) to work on /opt/airflow/dags/generate_data.py
[2025-08-18T22:34:51.287+0000] {processor.py:830} INFO - Processing file /opt/airflow/dags/generate_data.py for tasks to queue
[2025-08-18T22:34:51.291+0000] {logging_mixin.py:188} INFO - [2025-08-18T22:34:51.290+0000] {dagbag.py:540} INFO - Filling up the DagBag from /opt/airflow/dags/generate_data.py
[2025-08-18T22:34:51.680+0000] {processor.py:840} INFO - DAG(s) 'generate_data' retrieved from /opt/airflow/dags/generate_data.py
[2025-08-18T22:34:51.806+0000] {logging_mixin.py:188} INFO - [2025-08-18T22:34:51.806+0000] {dag.py:3047} INFO - Sync 1 DAGs
[2025-08-18T22:34:51.877+0000] {logging_mixin.py:188} INFO - [2025-08-18T22:34:51.877+0000] {dag.py:3834} INFO - Setting next_dagrun for generate_data to 2025-08-18 00:00:00+00:00, run_after=2025-08-19 00:00:00+00:00
[2025-08-18T22:34:51.924+0000] {processor.py:183} INFO - Processing /opt/airflow/dags/generate_data.py took 0.674 seconds
[2025-08-18T22:35:22.384+0000] {processor.py:161} INFO - Started process (PID=465) to work on /opt/airflow/dags/generate_data.py
[2025-08-18T22:35:22.385+0000] {processor.py:830} INFO - Processing file /opt/airflow/dags/generate_data.py for tasks to queue
[2025-08-18T22:35:22.390+0000] {logging_mixin.py:188} INFO - [2025-08-18T22:35:22.388+0000] {dagbag.py:540} INFO - Filling up the DagBag from /opt/airflow/dags/generate_data.py
[2025-08-18T22:35:23.280+0000] {processor.py:840} INFO - DAG(s) 'generate_data' retrieved from /opt/airflow/dags/generate_data.py
[2025-08-18T22:35:23.461+0000] {logging_mixin.py:188} INFO - [2025-08-18T22:35:23.461+0000] {dag.py:3047} INFO - Sync 1 DAGs
[2025-08-18T22:35:23.551+0000] {logging_mixin.py:188} INFO - [2025-08-18T22:35:23.548+0000] {dag.py:3834} INFO - Setting next_dagrun for generate_data to 2025-08-18 00:00:00+00:00, run_after=2025-08-19 00:00:00+00:00
[2025-08-18T22:35:23.613+0000] {processor.py:183} INFO - Processing /opt/airflow/dags/generate_data.py took 1.243 seconds
[2025-08-18T22:35:53.749+0000] {processor.py:161} INFO - Started process (PID=476) to work on /opt/airflow/dags/generate_data.py
[2025-08-18T22:35:53.752+0000] {processor.py:830} INFO - Processing file /opt/airflow/dags/generate_data.py for tasks to queue
[2025-08-18T22:35:53.755+0000] {logging_mixin.py:188} INFO - [2025-08-18T22:35:53.754+0000] {dagbag.py:540} INFO - Filling up the DagBag from /opt/airflow/dags/generate_data.py
[2025-08-18T22:35:54.201+0000] {processor.py:840} INFO - DAG(s) 'generate_data' retrieved from /opt/airflow/dags/generate_data.py
[2025-08-18T22:35:54.324+0000] {logging_mixin.py:188} INFO - [2025-08-18T22:35:54.323+0000] {dag.py:3047} INFO - Sync 1 DAGs
[2025-08-18T22:35:54.393+0000] {logging_mixin.py:188} INFO - [2025-08-18T22:35:54.393+0000] {dag.py:3834} INFO - Setting next_dagrun for generate_data to 2025-08-18 00:00:00+00:00, run_after=2025-08-19 00:00:00+00:00
[2025-08-18T22:35:54.442+0000] {processor.py:183} INFO - Processing /opt/airflow/dags/generate_data.py took 0.705 seconds
[2025-08-18T22:36:24.633+0000] {processor.py:161} INFO - Started process (PID=488) to work on /opt/airflow/dags/generate_data.py
[2025-08-18T22:36:24.638+0000] {processor.py:830} INFO - Processing file /opt/airflow/dags/generate_data.py for tasks to queue
[2025-08-18T22:36:24.646+0000] {logging_mixin.py:188} INFO - [2025-08-18T22:36:24.641+0000] {dagbag.py:540} INFO - Filling up the DagBag from /opt/airflow/dags/generate_data.py
[2025-08-18T22:36:25.328+0000] {processor.py:840} INFO - DAG(s) 'generate_data' retrieved from /opt/airflow/dags/generate_data.py
[2025-08-18T22:36:25.439+0000] {logging_mixin.py:188} INFO - [2025-08-18T22:36:25.439+0000] {dag.py:3047} INFO - Sync 1 DAGs
[2025-08-18T22:36:25.509+0000] {logging_mixin.py:188} INFO - [2025-08-18T22:36:25.508+0000] {dag.py:3834} INFO - Setting next_dagrun for generate_data to 2025-08-18 00:00:00+00:00, run_after=2025-08-19 00:00:00+00:00
[2025-08-18T22:36:25.566+0000] {processor.py:183} INFO - Processing /opt/airflow/dags/generate_data.py took 0.959 seconds
[2025-08-18T22:36:56.064+0000] {processor.py:161} INFO - Started process (PID=500) to work on /opt/airflow/dags/generate_data.py
[2025-08-18T22:36:56.066+0000] {processor.py:830} INFO - Processing file /opt/airflow/dags/generate_data.py for tasks to queue
[2025-08-18T22:36:56.070+0000] {logging_mixin.py:188} INFO - [2025-08-18T22:36:56.069+0000] {dagbag.py:540} INFO - Filling up the DagBag from /opt/airflow/dags/generate_data.py
[2025-08-18T22:36:56.698+0000] {processor.py:840} INFO - DAG(s) 'generate_data' retrieved from /opt/airflow/dags/generate_data.py
[2025-08-18T22:36:56.790+0000] {logging_mixin.py:188} INFO - [2025-08-18T22:36:56.789+0000] {dag.py:3047} INFO - Sync 1 DAGs
[2025-08-18T22:36:56.834+0000] {logging_mixin.py:188} INFO - [2025-08-18T22:36:56.833+0000] {dag.py:3834} INFO - Setting next_dagrun for generate_data to 2025-08-18 00:00:00+00:00, run_after=2025-08-19 00:00:00+00:00
[2025-08-18T22:36:56.869+0000] {processor.py:183} INFO - Processing /opt/airflow/dags/generate_data.py took 0.812 seconds
[2025-08-18T22:37:27.342+0000] {processor.py:161} INFO - Started process (PID=511) to work on /opt/airflow/dags/generate_data.py
[2025-08-18T22:37:27.351+0000] {processor.py:830} INFO - Processing file /opt/airflow/dags/generate_data.py for tasks to queue
[2025-08-18T22:37:27.361+0000] {logging_mixin.py:188} INFO - [2025-08-18T22:37:27.356+0000] {dagbag.py:540} INFO - Filling up the DagBag from /opt/airflow/dags/generate_data.py
[2025-08-18T22:37:27.887+0000] {processor.py:840} INFO - DAG(s) 'generate_data' retrieved from /opt/airflow/dags/generate_data.py
[2025-08-18T22:37:28.024+0000] {logging_mixin.py:188} INFO - [2025-08-18T22:37:28.023+0000] {dag.py:3047} INFO - Sync 1 DAGs
[2025-08-18T22:37:28.086+0000] {logging_mixin.py:188} INFO - [2025-08-18T22:37:28.085+0000] {dag.py:3834} INFO - Setting next_dagrun for generate_data to 2025-08-18 00:00:00+00:00, run_after=2025-08-19 00:00:00+00:00
[2025-08-18T22:37:28.156+0000] {processor.py:183} INFO - Processing /opt/airflow/dags/generate_data.py took 0.829 seconds
[2025-08-18T22:37:58.562+0000] {processor.py:161} INFO - Started process (PID=523) to work on /opt/airflow/dags/generate_data.py
[2025-08-18T22:37:58.565+0000] {processor.py:830} INFO - Processing file /opt/airflow/dags/generate_data.py for tasks to queue
[2025-08-18T22:37:58.568+0000] {logging_mixin.py:188} INFO - [2025-08-18T22:37:58.566+0000] {dagbag.py:540} INFO - Filling up the DagBag from /opt/airflow/dags/generate_data.py
[2025-08-18T22:37:59.000+0000] {processor.py:840} INFO - DAG(s) 'generate_data' retrieved from /opt/airflow/dags/generate_data.py
[2025-08-18T22:37:59.161+0000] {logging_mixin.py:188} INFO - [2025-08-18T22:37:59.161+0000] {dag.py:3047} INFO - Sync 1 DAGs
[2025-08-18T22:37:59.207+0000] {logging_mixin.py:188} INFO - [2025-08-18T22:37:59.207+0000] {dag.py:3834} INFO - Setting next_dagrun for generate_data to 2025-08-18 00:00:00+00:00, run_after=2025-08-19 00:00:00+00:00
[2025-08-18T22:37:59.246+0000] {processor.py:183} INFO - Processing /opt/airflow/dags/generate_data.py took 0.694 seconds
[2025-08-18T22:38:29.643+0000] {processor.py:161} INFO - Started process (PID=533) to work on /opt/airflow/dags/generate_data.py
[2025-08-18T22:38:29.645+0000] {processor.py:830} INFO - Processing file /opt/airflow/dags/generate_data.py for tasks to queue
[2025-08-18T22:38:29.648+0000] {logging_mixin.py:188} INFO - [2025-08-18T22:38:29.646+0000] {dagbag.py:540} INFO - Filling up the DagBag from /opt/airflow/dags/generate_data.py
[2025-08-18T22:38:30.103+0000] {processor.py:840} INFO - DAG(s) 'generate_data' retrieved from /opt/airflow/dags/generate_data.py
[2025-08-18T22:38:30.271+0000] {logging_mixin.py:188} INFO - [2025-08-18T22:38:30.270+0000] {dag.py:3047} INFO - Sync 1 DAGs
[2025-08-18T22:38:30.331+0000] {logging_mixin.py:188} INFO - [2025-08-18T22:38:30.330+0000] {dag.py:3834} INFO - Setting next_dagrun for generate_data to 2025-08-18 00:00:00+00:00, run_after=2025-08-19 00:00:00+00:00
[2025-08-18T22:38:30.395+0000] {processor.py:183} INFO - Processing /opt/airflow/dags/generate_data.py took 0.764 seconds
[2025-08-18T22:39:00.927+0000] {processor.py:161} INFO - Started process (PID=544) to work on /opt/airflow/dags/generate_data.py
[2025-08-18T22:39:00.929+0000] {processor.py:830} INFO - Processing file /opt/airflow/dags/generate_data.py for tasks to queue
[2025-08-18T22:39:00.931+0000] {logging_mixin.py:188} INFO - [2025-08-18T22:39:00.931+0000] {dagbag.py:540} INFO - Filling up the DagBag from /opt/airflow/dags/generate_data.py
[2025-08-18T22:39:01.396+0000] {processor.py:840} INFO - DAG(s) 'generate_data' retrieved from /opt/airflow/dags/generate_data.py
[2025-08-18T22:39:01.491+0000] {logging_mixin.py:188} INFO - [2025-08-18T22:39:01.490+0000] {dag.py:3047} INFO - Sync 1 DAGs
[2025-08-18T22:39:01.537+0000] {logging_mixin.py:188} INFO - [2025-08-18T22:39:01.537+0000] {dag.py:3834} INFO - Setting next_dagrun for generate_data to 2025-08-18 00:00:00+00:00, run_after=2025-08-19 00:00:00+00:00
[2025-08-18T22:39:01.580+0000] {processor.py:183} INFO - Processing /opt/airflow/dags/generate_data.py took 0.662 seconds
[2025-08-18T22:39:31.780+0000] {processor.py:161} INFO - Started process (PID=555) to work on /opt/airflow/dags/generate_data.py
[2025-08-18T22:39:31.782+0000] {processor.py:830} INFO - Processing file /opt/airflow/dags/generate_data.py for tasks to queue
[2025-08-18T22:39:31.786+0000] {logging_mixin.py:188} INFO - [2025-08-18T22:39:31.783+0000] {dagbag.py:540} INFO - Filling up the DagBag from /opt/airflow/dags/generate_data.py
[2025-08-18T22:39:32.245+0000] {processor.py:840} INFO - DAG(s) 'generate_data' retrieved from /opt/airflow/dags/generate_data.py
[2025-08-18T22:39:32.342+0000] {logging_mixin.py:188} INFO - [2025-08-18T22:39:32.342+0000] {dag.py:3047} INFO - Sync 1 DAGs
[2025-08-18T22:39:32.381+0000] {logging_mixin.py:188} INFO - [2025-08-18T22:39:32.381+0000] {dag.py:3834} INFO - Setting next_dagrun for generate_data to 2025-08-18 00:00:00+00:00, run_after=2025-08-19 00:00:00+00:00
[2025-08-18T22:39:32.408+0000] {processor.py:183} INFO - Processing /opt/airflow/dags/generate_data.py took 0.645 seconds
[2025-08-18T22:40:02.830+0000] {processor.py:161} INFO - Started process (PID=566) to work on /opt/airflow/dags/generate_data.py
[2025-08-18T22:40:02.832+0000] {processor.py:830} INFO - Processing file /opt/airflow/dags/generate_data.py for tasks to queue
[2025-08-18T22:40:02.837+0000] {logging_mixin.py:188} INFO - [2025-08-18T22:40:02.834+0000] {dagbag.py:540} INFO - Filling up the DagBag from /opt/airflow/dags/generate_data.py
[2025-08-18T22:40:03.312+0000] {processor.py:840} INFO - DAG(s) 'generate_data' retrieved from /opt/airflow/dags/generate_data.py
[2025-08-18T22:40:03.456+0000] {logging_mixin.py:188} INFO - [2025-08-18T22:40:03.456+0000] {dag.py:3047} INFO - Sync 1 DAGs
[2025-08-18T22:40:03.509+0000] {logging_mixin.py:188} INFO - [2025-08-18T22:40:03.507+0000] {dag.py:3834} INFO - Setting next_dagrun for generate_data to 2025-08-18 00:00:00+00:00, run_after=2025-08-19 00:00:00+00:00
[2025-08-18T22:40:03.559+0000] {processor.py:183} INFO - Processing /opt/airflow/dags/generate_data.py took 0.740 seconds
[2025-08-18T22:40:33.970+0000] {processor.py:161} INFO - Started process (PID=578) to work on /opt/airflow/dags/generate_data.py
[2025-08-18T22:40:33.972+0000] {processor.py:830} INFO - Processing file /opt/airflow/dags/generate_data.py for tasks to queue
[2025-08-18T22:40:33.975+0000] {logging_mixin.py:188} INFO - [2025-08-18T22:40:33.974+0000] {dagbag.py:540} INFO - Filling up the DagBag from /opt/airflow/dags/generate_data.py
[2025-08-18T22:40:34.320+0000] {processor.py:840} INFO - DAG(s) 'generate_data' retrieved from /opt/airflow/dags/generate_data.py
[2025-08-18T22:40:34.458+0000] {logging_mixin.py:188} INFO - [2025-08-18T22:40:34.458+0000] {dag.py:3047} INFO - Sync 1 DAGs
[2025-08-18T22:40:34.508+0000] {logging_mixin.py:188} INFO - [2025-08-18T22:40:34.508+0000] {dag.py:3834} INFO - Setting next_dagrun for generate_data to 2025-08-18 00:00:00+00:00, run_after=2025-08-19 00:00:00+00:00
[2025-08-18T22:40:34.552+0000] {processor.py:183} INFO - Processing /opt/airflow/dags/generate_data.py took 0.592 seconds
[2025-08-18T22:41:05.088+0000] {processor.py:161} INFO - Started process (PID=589) to work on /opt/airflow/dags/generate_data.py
[2025-08-18T22:41:05.089+0000] {processor.py:830} INFO - Processing file /opt/airflow/dags/generate_data.py for tasks to queue
[2025-08-18T22:41:05.091+0000] {logging_mixin.py:188} INFO - [2025-08-18T22:41:05.091+0000] {dagbag.py:540} INFO - Filling up the DagBag from /opt/airflow/dags/generate_data.py
[2025-08-18T22:41:05.476+0000] {processor.py:840} INFO - DAG(s) 'generate_data' retrieved from /opt/airflow/dags/generate_data.py
[2025-08-18T22:41:05.556+0000] {logging_mixin.py:188} INFO - [2025-08-18T22:41:05.555+0000] {dag.py:3047} INFO - Sync 1 DAGs
[2025-08-18T22:41:05.590+0000] {logging_mixin.py:188} INFO - [2025-08-18T22:41:05.589+0000] {dag.py:3834} INFO - Setting next_dagrun for generate_data to 2025-08-18 00:00:00+00:00, run_after=2025-08-19 00:00:00+00:00
[2025-08-18T22:41:05.620+0000] {processor.py:183} INFO - Processing /opt/airflow/dags/generate_data.py took 0.540 seconds
[2025-08-18T22:41:36.096+0000] {processor.py:161} INFO - Started process (PID=601) to work on /opt/airflow/dags/generate_data.py
[2025-08-18T22:41:36.100+0000] {processor.py:830} INFO - Processing file /opt/airflow/dags/generate_data.py for tasks to queue
[2025-08-18T22:41:36.104+0000] {logging_mixin.py:188} INFO - [2025-08-18T22:41:36.102+0000] {dagbag.py:540} INFO - Filling up the DagBag from /opt/airflow/dags/generate_data.py
[2025-08-18T22:41:36.545+0000] {processor.py:840} INFO - DAG(s) 'generate_data' retrieved from /opt/airflow/dags/generate_data.py
[2025-08-18T22:41:36.755+0000] {logging_mixin.py:188} INFO - [2025-08-18T22:41:36.754+0000] {dag.py:3047} INFO - Sync 1 DAGs
[2025-08-18T22:41:36.871+0000] {logging_mixin.py:188} INFO - [2025-08-18T22:41:36.870+0000] {dag.py:3834} INFO - Setting next_dagrun for generate_data to 2025-08-18 00:00:00+00:00, run_after=2025-08-19 00:00:00+00:00
[2025-08-18T22:41:36.939+0000] {processor.py:183} INFO - Processing /opt/airflow/dags/generate_data.py took 0.852 seconds
[2025-08-18T22:42:07.469+0000] {processor.py:161} INFO - Started process (PID=612) to work on /opt/airflow/dags/generate_data.py
[2025-08-18T22:42:07.471+0000] {processor.py:830} INFO - Processing file /opt/airflow/dags/generate_data.py for tasks to queue
[2025-08-18T22:42:07.478+0000] {logging_mixin.py:188} INFO - [2025-08-18T22:42:07.475+0000] {dagbag.py:540} INFO - Filling up the DagBag from /opt/airflow/dags/generate_data.py
[2025-08-18T22:42:07.929+0000] {processor.py:840} INFO - DAG(s) 'generate_data' retrieved from /opt/airflow/dags/generate_data.py
[2025-08-18T22:42:08.063+0000] {logging_mixin.py:188} INFO - [2025-08-18T22:42:08.062+0000] {dag.py:3047} INFO - Sync 1 DAGs
[2025-08-18T22:42:08.114+0000] {logging_mixin.py:188} INFO - [2025-08-18T22:42:08.113+0000] {dag.py:3834} INFO - Setting next_dagrun for generate_data to 2025-08-18 00:00:00+00:00, run_after=2025-08-19 00:00:00+00:00
[2025-08-18T22:42:08.155+0000] {processor.py:183} INFO - Processing /opt/airflow/dags/generate_data.py took 0.700 seconds
[2025-08-18T22:42:38.285+0000] {processor.py:161} INFO - Started process (PID=623) to work on /opt/airflow/dags/generate_data.py
[2025-08-18T22:42:38.287+0000] {processor.py:830} INFO - Processing file /opt/airflow/dags/generate_data.py for tasks to queue
[2025-08-18T22:42:38.292+0000] {logging_mixin.py:188} INFO - [2025-08-18T22:42:38.288+0000] {dagbag.py:540} INFO - Filling up the DagBag from /opt/airflow/dags/generate_data.py
[2025-08-18T22:42:38.740+0000] {processor.py:840} INFO - DAG(s) 'generate_data' retrieved from /opt/airflow/dags/generate_data.py
[2025-08-18T22:42:39.072+0000] {logging_mixin.py:188} INFO - [2025-08-18T22:42:39.065+0000] {dag.py:3047} INFO - Sync 1 DAGs
[2025-08-18T22:42:39.210+0000] {logging_mixin.py:188} INFO - [2025-08-18T22:42:39.208+0000] {dag.py:3834} INFO - Setting next_dagrun for generate_data to 2025-08-18 00:00:00+00:00, run_after=2025-08-19 00:00:00+00:00
[2025-08-18T22:42:39.326+0000] {processor.py:183} INFO - Processing /opt/airflow/dags/generate_data.py took 1.056 seconds
[2025-08-18T22:43:09.664+0000] {processor.py:161} INFO - Started process (PID=634) to work on /opt/airflow/dags/generate_data.py
[2025-08-18T22:43:09.665+0000] {processor.py:830} INFO - Processing file /opt/airflow/dags/generate_data.py for tasks to queue
[2025-08-18T22:43:09.668+0000] {logging_mixin.py:188} INFO - [2025-08-18T22:43:09.667+0000] {dagbag.py:540} INFO - Filling up the DagBag from /opt/airflow/dags/generate_data.py
[2025-08-18T22:43:10.112+0000] {processor.py:840} INFO - DAG(s) 'generate_data' retrieved from /opt/airflow/dags/generate_data.py
[2025-08-18T22:43:10.198+0000] {logging_mixin.py:188} INFO - [2025-08-18T22:43:10.197+0000] {dag.py:3047} INFO - Sync 1 DAGs
[2025-08-18T22:43:10.287+0000] {logging_mixin.py:188} INFO - [2025-08-18T22:43:10.286+0000] {dag.py:3834} INFO - Setting next_dagrun for generate_data to 2025-08-18 00:00:00+00:00, run_after=2025-08-19 00:00:00+00:00
[2025-08-18T22:43:10.397+0000] {processor.py:183} INFO - Processing /opt/airflow/dags/generate_data.py took 0.743 seconds
[2025-08-18T22:43:40.923+0000] {processor.py:161} INFO - Started process (PID=645) to work on /opt/airflow/dags/generate_data.py
[2025-08-18T22:43:40.925+0000] {processor.py:830} INFO - Processing file /opt/airflow/dags/generate_data.py for tasks to queue
[2025-08-18T22:43:40.930+0000] {logging_mixin.py:188} INFO - [2025-08-18T22:43:40.927+0000] {dagbag.py:540} INFO - Filling up the DagBag from /opt/airflow/dags/generate_data.py
[2025-08-18T22:43:41.576+0000] {processor.py:840} INFO - DAG(s) 'generate_data' retrieved from /opt/airflow/dags/generate_data.py
[2025-08-18T22:43:41.743+0000] {logging_mixin.py:188} INFO - [2025-08-18T22:43:41.742+0000] {dag.py:3047} INFO - Sync 1 DAGs
[2025-08-18T22:43:41.822+0000] {logging_mixin.py:188} INFO - [2025-08-18T22:43:41.821+0000] {dag.py:3834} INFO - Setting next_dagrun for generate_data to 2025-08-18 00:00:00+00:00, run_after=2025-08-19 00:00:00+00:00
[2025-08-18T22:43:41.875+0000] {processor.py:183} INFO - Processing /opt/airflow/dags/generate_data.py took 0.973 seconds
[2025-08-18T22:44:12.491+0000] {processor.py:161} INFO - Started process (PID=658) to work on /opt/airflow/dags/generate_data.py
[2025-08-18T22:44:12.493+0000] {processor.py:830} INFO - Processing file /opt/airflow/dags/generate_data.py for tasks to queue
[2025-08-18T22:44:12.497+0000] {logging_mixin.py:188} INFO - [2025-08-18T22:44:12.495+0000] {dagbag.py:540} INFO - Filling up the DagBag from /opt/airflow/dags/generate_data.py
[2025-08-18T22:44:12.932+0000] {processor.py:840} INFO - DAG(s) 'generate_data' retrieved from /opt/airflow/dags/generate_data.py
[2025-08-18T22:44:13.045+0000] {logging_mixin.py:188} INFO - [2025-08-18T22:44:13.044+0000] {dag.py:3047} INFO - Sync 1 DAGs
[2025-08-18T22:44:13.095+0000] {logging_mixin.py:188} INFO - [2025-08-18T22:44:13.095+0000] {dag.py:3834} INFO - Setting next_dagrun for generate_data to 2025-08-18 00:00:00+00:00, run_after=2025-08-19 00:00:00+00:00
[2025-08-18T22:44:13.141+0000] {processor.py:183} INFO - Processing /opt/airflow/dags/generate_data.py took 0.661 seconds
[2025-08-18T22:44:43.692+0000] {processor.py:161} INFO - Started process (PID=669) to work on /opt/airflow/dags/generate_data.py
[2025-08-18T22:44:43.694+0000] {processor.py:830} INFO - Processing file /opt/airflow/dags/generate_data.py for tasks to queue
[2025-08-18T22:44:43.699+0000] {logging_mixin.py:188} INFO - [2025-08-18T22:44:43.696+0000] {dagbag.py:540} INFO - Filling up the DagBag from /opt/airflow/dags/generate_data.py
[2025-08-18T22:44:44.212+0000] {processor.py:840} INFO - DAG(s) 'generate_data' retrieved from /opt/airflow/dags/generate_data.py
[2025-08-18T22:44:44.470+0000] {logging_mixin.py:188} INFO - [2025-08-18T22:44:44.465+0000] {dag.py:3047} INFO - Sync 1 DAGs
[2025-08-18T22:44:44.562+0000] {logging_mixin.py:188} INFO - [2025-08-18T22:44:44.561+0000] {dag.py:3834} INFO - Setting next_dagrun for generate_data to 2025-08-18 00:00:00+00:00, run_after=2025-08-19 00:00:00+00:00
[2025-08-18T22:44:44.645+0000] {processor.py:183} INFO - Processing /opt/airflow/dags/generate_data.py took 0.965 seconds
[2025-08-18T22:45:15.061+0000] {processor.py:161} INFO - Started process (PID=680) to work on /opt/airflow/dags/generate_data.py
[2025-08-18T22:45:15.063+0000] {processor.py:830} INFO - Processing file /opt/airflow/dags/generate_data.py for tasks to queue
[2025-08-18T22:45:15.065+0000] {logging_mixin.py:188} INFO - [2025-08-18T22:45:15.064+0000] {dagbag.py:540} INFO - Filling up the DagBag from /opt/airflow/dags/generate_data.py
[2025-08-18T22:45:15.462+0000] {processor.py:840} INFO - DAG(s) 'generate_data' retrieved from /opt/airflow/dags/generate_data.py
[2025-08-18T22:45:15.650+0000] {logging_mixin.py:188} INFO - [2025-08-18T22:45:15.646+0000] {dag.py:3047} INFO - Sync 1 DAGs
[2025-08-18T22:45:15.742+0000] {logging_mixin.py:188} INFO - [2025-08-18T22:45:15.741+0000] {dag.py:3834} INFO - Setting next_dagrun for generate_data to 2025-08-18 00:00:00+00:00, run_after=2025-08-19 00:00:00+00:00
[2025-08-18T22:45:15.839+0000] {processor.py:183} INFO - Processing /opt/airflow/dags/generate_data.py took 0.786 seconds
[2025-08-18T22:45:46.996+0000] {processor.py:161} INFO - Started process (PID=691) to work on /opt/airflow/dags/generate_data.py
[2025-08-18T22:45:46.999+0000] {processor.py:830} INFO - Processing file /opt/airflow/dags/generate_data.py for tasks to queue
[2025-08-18T22:45:47.006+0000] {logging_mixin.py:188} INFO - [2025-08-18T22:45:47.003+0000] {dagbag.py:540} INFO - Filling up the DagBag from /opt/airflow/dags/generate_data.py
[2025-08-18T22:45:47.527+0000] {processor.py:840} INFO - DAG(s) 'generate_data' retrieved from /opt/airflow/dags/generate_data.py
[2025-08-18T22:45:47.673+0000] {logging_mixin.py:188} INFO - [2025-08-18T22:45:47.673+0000] {dag.py:3047} INFO - Sync 1 DAGs
[2025-08-18T22:45:47.760+0000] {logging_mixin.py:188} INFO - [2025-08-18T22:45:47.760+0000] {dag.py:3834} INFO - Setting next_dagrun for generate_data to 2025-08-18 00:00:00+00:00, run_after=2025-08-19 00:00:00+00:00
[2025-08-18T22:45:47.834+0000] {processor.py:183} INFO - Processing /opt/airflow/dags/generate_data.py took 0.858 seconds
[2025-08-18T22:46:18.613+0000] {processor.py:161} INFO - Started process (PID=703) to work on /opt/airflow/dags/generate_data.py
[2025-08-18T22:46:18.615+0000] {processor.py:830} INFO - Processing file /opt/airflow/dags/generate_data.py for tasks to queue
[2025-08-18T22:46:18.621+0000] {logging_mixin.py:188} INFO - [2025-08-18T22:46:18.618+0000] {dagbag.py:540} INFO - Filling up the DagBag from /opt/airflow/dags/generate_data.py
[2025-08-18T22:46:19.427+0000] {processor.py:840} INFO - DAG(s) 'generate_data' retrieved from /opt/airflow/dags/generate_data.py
[2025-08-18T22:46:33.478+0000] {logging_mixin.py:188} INFO - [2025-08-18T22:46:33.467+0000] {dag.py:3047} INFO - Sync 1 DAGs
[2025-08-18T22:46:33.650+0000] {logging_mixin.py:188} INFO - [2025-08-18T22:46:33.649+0000] {dag.py:3834} INFO - Setting next_dagrun for generate_data to 2025-08-18 00:00:00+00:00, run_after=2025-08-19 00:00:00+00:00
[2025-08-18T22:46:33.717+0000] {processor.py:183} INFO - Processing /opt/airflow/dags/generate_data.py took 15.115 seconds
[2025-08-18T22:47:04.177+0000] {processor.py:161} INFO - Started process (PID=714) to work on /opt/airflow/dags/generate_data.py
[2025-08-18T22:47:04.179+0000] {processor.py:830} INFO - Processing file /opt/airflow/dags/generate_data.py for tasks to queue
[2025-08-18T22:47:04.185+0000] {logging_mixin.py:188} INFO - [2025-08-18T22:47:04.183+0000] {dagbag.py:540} INFO - Filling up the DagBag from /opt/airflow/dags/generate_data.py
[2025-08-18T22:47:04.783+0000] {processor.py:840} INFO - DAG(s) 'generate_data' retrieved from /opt/airflow/dags/generate_data.py
[2025-08-18T22:47:05.112+0000] {logging_mixin.py:188} INFO - [2025-08-18T22:47:05.101+0000] {dag.py:3047} INFO - Sync 1 DAGs
[2025-08-18T22:47:05.173+0000] {logging_mixin.py:188} INFO - [2025-08-18T22:47:05.171+0000] {dag.py:3834} INFO - Setting next_dagrun for generate_data to 2025-08-18 00:00:00+00:00, run_after=2025-08-19 00:00:00+00:00
[2025-08-18T22:47:05.245+0000] {processor.py:183} INFO - Processing /opt/airflow/dags/generate_data.py took 1.081 seconds
[2025-08-18T22:47:35.505+0000] {processor.py:161} INFO - Started process (PID=725) to work on /opt/airflow/dags/generate_data.py
[2025-08-18T22:47:35.509+0000] {processor.py:830} INFO - Processing file /opt/airflow/dags/generate_data.py for tasks to queue
[2025-08-18T22:47:35.518+0000] {logging_mixin.py:188} INFO - [2025-08-18T22:47:35.512+0000] {dagbag.py:540} INFO - Filling up the DagBag from /opt/airflow/dags/generate_data.py
[2025-08-18T22:47:35.997+0000] {processor.py:840} INFO - DAG(s) 'generate_data' retrieved from /opt/airflow/dags/generate_data.py
[2025-08-18T22:47:36.160+0000] {logging_mixin.py:188} INFO - [2025-08-18T22:47:36.160+0000] {dag.py:3047} INFO - Sync 1 DAGs
[2025-08-18T22:47:36.200+0000] {logging_mixin.py:188} INFO - [2025-08-18T22:47:36.200+0000] {dag.py:3834} INFO - Setting next_dagrun for generate_data to 2025-08-18 00:00:00+00:00, run_after=2025-08-19 00:00:00+00:00
[2025-08-18T22:47:36.236+0000] {processor.py:183} INFO - Processing /opt/airflow/dags/generate_data.py took 0.746 seconds
[2025-08-18T22:48:06.683+0000] {processor.py:161} INFO - Started process (PID=735) to work on /opt/airflow/dags/generate_data.py
[2025-08-18T22:48:06.684+0000] {processor.py:830} INFO - Processing file /opt/airflow/dags/generate_data.py for tasks to queue
[2025-08-18T22:48:06.687+0000] {logging_mixin.py:188} INFO - [2025-08-18T22:48:06.686+0000] {dagbag.py:540} INFO - Filling up the DagBag from /opt/airflow/dags/generate_data.py
[2025-08-18T22:48:07.246+0000] {processor.py:840} INFO - DAG(s) 'generate_data' retrieved from /opt/airflow/dags/generate_data.py
[2025-08-18T22:48:26.010+0000] {logging_mixin.py:188} INFO - [2025-08-18T22:48:26.005+0000] {dag.py:3047} INFO - Sync 1 DAGs
[2025-08-18T22:48:26.086+0000] {logging_mixin.py:188} INFO - [2025-08-18T22:48:26.085+0000] {dag.py:3834} INFO - Setting next_dagrun for generate_data to 2025-08-18 00:00:00+00:00, run_after=2025-08-19 00:00:00+00:00
[2025-08-18T22:48:26.145+0000] {processor.py:183} INFO - Processing /opt/airflow/dags/generate_data.py took 19.472 seconds
[2025-08-18T22:48:56.605+0000] {processor.py:161} INFO - Started process (PID=747) to work on /opt/airflow/dags/generate_data.py
[2025-08-18T22:48:56.607+0000] {processor.py:830} INFO - Processing file /opt/airflow/dags/generate_data.py for tasks to queue
[2025-08-18T22:48:56.611+0000] {logging_mixin.py:188} INFO - [2025-08-18T22:48:56.610+0000] {dagbag.py:540} INFO - Filling up the DagBag from /opt/airflow/dags/generate_data.py
[2025-08-18T22:48:57.100+0000] {processor.py:840} INFO - DAG(s) 'generate_data' retrieved from /opt/airflow/dags/generate_data.py
[2025-08-18T22:48:57.247+0000] {logging_mixin.py:188} INFO - [2025-08-18T22:48:57.246+0000] {dag.py:3047} INFO - Sync 1 DAGs
[2025-08-18T22:48:57.367+0000] {logging_mixin.py:188} INFO - [2025-08-18T22:48:57.366+0000] {dag.py:3834} INFO - Setting next_dagrun for generate_data to 2025-08-18 00:00:00+00:00, run_after=2025-08-19 00:00:00+00:00
[2025-08-18T22:48:57.432+0000] {processor.py:183} INFO - Processing /opt/airflow/dags/generate_data.py took 0.835 seconds
[2025-08-18T22:49:28.567+0000] {processor.py:161} INFO - Started process (PID=759) to work on /opt/airflow/dags/generate_data.py
[2025-08-18T22:49:28.569+0000] {processor.py:830} INFO - Processing file /opt/airflow/dags/generate_data.py for tasks to queue
[2025-08-18T22:49:28.576+0000] {logging_mixin.py:188} INFO - [2025-08-18T22:49:28.572+0000] {dagbag.py:540} INFO - Filling up the DagBag from /opt/airflow/dags/generate_data.py
[2025-08-18T22:49:29.176+0000] {processor.py:840} INFO - DAG(s) 'generate_data' retrieved from /opt/airflow/dags/generate_data.py
[2025-08-18T22:49:29.363+0000] {logging_mixin.py:188} INFO - [2025-08-18T22:49:29.359+0000] {dag.py:3047} INFO - Sync 1 DAGs
[2025-08-18T22:49:29.483+0000] {logging_mixin.py:188} INFO - [2025-08-18T22:49:29.482+0000] {dag.py:3834} INFO - Setting next_dagrun for generate_data to 2025-08-18 00:00:00+00:00, run_after=2025-08-19 00:00:00+00:00
[2025-08-18T22:49:29.557+0000] {processor.py:183} INFO - Processing /opt/airflow/dags/generate_data.py took 1.006 seconds
[2025-08-18T22:50:00.473+0000] {processor.py:161} INFO - Started process (PID=770) to work on /opt/airflow/dags/generate_data.py
[2025-08-18T22:50:00.475+0000] {processor.py:830} INFO - Processing file /opt/airflow/dags/generate_data.py for tasks to queue
[2025-08-18T22:50:00.482+0000] {logging_mixin.py:188} INFO - [2025-08-18T22:50:00.477+0000] {dagbag.py:540} INFO - Filling up the DagBag from /opt/airflow/dags/generate_data.py
[2025-08-18T22:51:06.814+0000] {logging_mixin.py:188} INFO - [2025-08-18T22:50:32.035+0000] {timeout.py:68} ERROR - Process timed out, PID: 770
[2025-08-18T22:51:41.202+0000] {processor.py:161} INFO - Started process (PID=773) to work on /opt/airflow/dags/generate_data.py
[2025-08-18T22:51:43.946+0000] {processor.py:830} INFO - Processing file /opt/airflow/dags/generate_data.py for tasks to queue
[2025-08-18T22:51:50.479+0000] {logging_mixin.py:188} INFO - [2025-08-18T22:51:47.334+0000] {dagbag.py:540} INFO - Filling up the DagBag from /opt/airflow/dags/generate_data.py
[2025-08-18T22:53:35.398+0000] {logging_mixin.py:188} INFO - [2025-08-18T22:53:01.245+0000] {timeout.py:68} ERROR - Process timed out, PID: 773
[2025-08-18T22:54:06.421+0000] {processor.py:161} INFO - Started process (PID=782) to work on /opt/airflow/dags/generate_data.py
[2025-08-18T22:54:06.423+0000] {processor.py:830} INFO - Processing file /opt/airflow/dags/generate_data.py for tasks to queue
[2025-08-18T22:54:06.433+0000] {logging_mixin.py:188} INFO - [2025-08-18T22:54:06.430+0000] {dagbag.py:540} INFO - Filling up the DagBag from /opt/airflow/dags/generate_data.py
[2025-08-18T22:54:07.903+0000] {processor.py:840} INFO - DAG(s) 'generate_data' retrieved from /opt/airflow/dags/generate_data.py
[2025-08-18T22:54:10.451+0000] {logging_mixin.py:188} INFO - [2025-08-18T22:54:10.450+0000] {dag.py:3047} INFO - Sync 1 DAGs
[2025-08-18T22:54:10.867+0000] {logging_mixin.py:188} INFO - [2025-08-18T22:54:10.866+0000] {dag.py:3834} INFO - Setting next_dagrun for generate_data to 2025-08-18 00:00:00+00:00, run_after=2025-08-19 00:00:00+00:00
[2025-08-18T22:54:11.358+0000] {processor.py:183} INFO - Processing /opt/airflow/dags/generate_data.py took 4.962 seconds
[2025-08-18T22:54:41.997+0000] {processor.py:161} INFO - Started process (PID=799) to work on /opt/airflow/dags/generate_data.py
[2025-08-18T22:54:41.999+0000] {processor.py:830} INFO - Processing file /opt/airflow/dags/generate_data.py for tasks to queue
[2025-08-18T22:54:42.002+0000] {logging_mixin.py:188} INFO - [2025-08-18T22:54:42.000+0000] {dagbag.py:540} INFO - Filling up the DagBag from /opt/airflow/dags/generate_data.py
[2025-08-18T22:54:42.370+0000] {processor.py:840} INFO - DAG(s) 'generate_data' retrieved from /opt/airflow/dags/generate_data.py
[2025-08-18T22:54:42.450+0000] {logging_mixin.py:188} INFO - [2025-08-18T22:54:42.450+0000] {dag.py:3047} INFO - Sync 1 DAGs
[2025-08-18T22:54:42.496+0000] {logging_mixin.py:188} INFO - [2025-08-18T22:54:42.495+0000] {dag.py:3834} INFO - Setting next_dagrun for generate_data to 2025-08-18 00:00:00+00:00, run_after=2025-08-19 00:00:00+00:00
[2025-08-18T22:54:42.537+0000] {processor.py:183} INFO - Processing /opt/airflow/dags/generate_data.py took 0.547 seconds
[2025-08-18T22:55:12.978+0000] {processor.py:161} INFO - Started process (PID=810) to work on /opt/airflow/dags/generate_data.py
[2025-08-18T22:55:12.980+0000] {processor.py:830} INFO - Processing file /opt/airflow/dags/generate_data.py for tasks to queue
[2025-08-18T22:55:12.985+0000] {logging_mixin.py:188} INFO - [2025-08-18T22:55:12.982+0000] {dagbag.py:540} INFO - Filling up the DagBag from /opt/airflow/dags/generate_data.py
[2025-08-18T22:55:13.314+0000] {processor.py:840} INFO - DAG(s) 'generate_data' retrieved from /opt/airflow/dags/generate_data.py
[2025-08-18T22:55:13.404+0000] {logging_mixin.py:188} INFO - [2025-08-18T22:55:13.404+0000] {dag.py:3047} INFO - Sync 1 DAGs
[2025-08-18T22:55:13.445+0000] {logging_mixin.py:188} INFO - [2025-08-18T22:55:13.445+0000] {dag.py:3834} INFO - Setting next_dagrun for generate_data to 2025-08-18 00:00:00+00:00, run_after=2025-08-19 00:00:00+00:00
[2025-08-18T22:55:13.474+0000] {processor.py:183} INFO - Processing /opt/airflow/dags/generate_data.py took 0.507 seconds
[2025-08-18T22:55:44.007+0000] {processor.py:161} INFO - Started process (PID=822) to work on /opt/airflow/dags/generate_data.py
[2025-08-18T22:55:44.009+0000] {processor.py:830} INFO - Processing file /opt/airflow/dags/generate_data.py for tasks to queue
[2025-08-18T22:55:44.014+0000] {logging_mixin.py:188} INFO - [2025-08-18T22:55:44.011+0000] {dagbag.py:540} INFO - Filling up the DagBag from /opt/airflow/dags/generate_data.py
[2025-08-18T22:55:44.519+0000] {processor.py:840} INFO - DAG(s) 'generate_data' retrieved from /opt/airflow/dags/generate_data.py
[2025-08-18T22:55:44.601+0000] {logging_mixin.py:188} INFO - [2025-08-18T22:55:44.601+0000] {dag.py:3047} INFO - Sync 1 DAGs
[2025-08-18T22:55:44.644+0000] {logging_mixin.py:188} INFO - [2025-08-18T22:55:44.643+0000] {dag.py:3834} INFO - Setting next_dagrun for generate_data to 2025-08-18 00:00:00+00:00, run_after=2025-08-19 00:00:00+00:00
[2025-08-18T22:55:44.681+0000] {processor.py:183} INFO - Processing /opt/airflow/dags/generate_data.py took 0.683 seconds
[2025-08-18T22:56:15.109+0000] {processor.py:161} INFO - Started process (PID=833) to work on /opt/airflow/dags/generate_data.py
[2025-08-18T22:56:15.111+0000] {processor.py:830} INFO - Processing file /opt/airflow/dags/generate_data.py for tasks to queue
[2025-08-18T22:56:15.114+0000] {logging_mixin.py:188} INFO - [2025-08-18T22:56:15.112+0000] {dagbag.py:540} INFO - Filling up the DagBag from /opt/airflow/dags/generate_data.py
[2025-08-18T22:56:15.516+0000] {processor.py:840} INFO - DAG(s) 'generate_data' retrieved from /opt/airflow/dags/generate_data.py
[2025-08-18T22:56:16.061+0000] {logging_mixin.py:188} INFO - [2025-08-18T22:56:16.054+0000] {dag.py:3047} INFO - Sync 1 DAGs
[2025-08-18T22:56:16.148+0000] {logging_mixin.py:188} INFO - [2025-08-18T22:56:16.147+0000] {dag.py:3834} INFO - Setting next_dagrun for generate_data to 2025-08-18 00:00:00+00:00, run_after=2025-08-19 00:00:00+00:00
[2025-08-18T22:56:16.200+0000] {processor.py:183} INFO - Processing /opt/airflow/dags/generate_data.py took 1.099 seconds
[2025-08-18T22:56:47.224+0000] {processor.py:161} INFO - Started process (PID=844) to work on /opt/airflow/dags/generate_data.py
[2025-08-18T22:56:47.227+0000] {processor.py:830} INFO - Processing file /opt/airflow/dags/generate_data.py for tasks to queue
[2025-08-18T22:56:47.233+0000] {logging_mixin.py:188} INFO - [2025-08-18T22:56:47.229+0000] {dagbag.py:540} INFO - Filling up the DagBag from /opt/airflow/dags/generate_data.py
[2025-08-18T22:56:47.941+0000] {processor.py:840} INFO - DAG(s) 'generate_data' retrieved from /opt/airflow/dags/generate_data.py
[2025-08-18T22:56:48.191+0000] {logging_mixin.py:188} INFO - [2025-08-18T22:56:48.188+0000] {dag.py:3047} INFO - Sync 1 DAGs
[2025-08-18T22:56:48.280+0000] {logging_mixin.py:188} INFO - [2025-08-18T22:56:48.279+0000] {dag.py:3834} INFO - Setting next_dagrun for generate_data to 2025-08-18 00:00:00+00:00, run_after=2025-08-19 00:00:00+00:00
[2025-08-18T22:56:48.363+0000] {processor.py:183} INFO - Processing /opt/airflow/dags/generate_data.py took 1.158 seconds
[2025-08-18T22:57:56.433+0000] {processor.py:161} INFO - Started process (PID=849) to work on /opt/airflow/dags/generate_data.py
[2025-08-18T22:57:56.443+0000] {processor.py:830} INFO - Processing file /opt/airflow/dags/generate_data.py for tasks to queue
[2025-08-18T22:57:56.448+0000] {logging_mixin.py:188} INFO - [2025-08-18T22:57:56.446+0000] {dagbag.py:540} INFO - Filling up the DagBag from /opt/airflow/dags/generate_data.py
[2025-08-18T22:57:57.771+0000] {processor.py:840} INFO - DAG(s) 'generate_data' retrieved from /opt/airflow/dags/generate_data.py
[2025-08-18T22:57:57.920+0000] {logging_mixin.py:188} INFO - [2025-08-18T22:57:57.919+0000] {dag.py:3047} INFO - Sync 1 DAGs
[2025-08-18T22:57:58.003+0000] {logging_mixin.py:188} INFO - [2025-08-18T22:57:58.002+0000] {dag.py:3834} INFO - Setting next_dagrun for generate_data to 2025-08-18 00:00:00+00:00, run_after=2025-08-19 00:00:00+00:00
[2025-08-18T22:57:58.072+0000] {processor.py:183} INFO - Processing /opt/airflow/dags/generate_data.py took 1.721 seconds
[2025-08-18T22:58:28.461+0000] {processor.py:161} INFO - Started process (PID=866) to work on /opt/airflow/dags/generate_data.py
[2025-08-18T22:58:28.462+0000] {processor.py:830} INFO - Processing file /opt/airflow/dags/generate_data.py for tasks to queue
[2025-08-18T22:58:28.465+0000] {logging_mixin.py:188} INFO - [2025-08-18T22:58:28.464+0000] {dagbag.py:540} INFO - Filling up the DagBag from /opt/airflow/dags/generate_data.py
[2025-08-18T22:58:28.852+0000] {processor.py:840} INFO - DAG(s) 'generate_data' retrieved from /opt/airflow/dags/generate_data.py
[2025-08-18T22:58:28.953+0000] {logging_mixin.py:188} INFO - [2025-08-18T22:58:28.952+0000] {dag.py:3047} INFO - Sync 1 DAGs
[2025-08-18T22:58:29.041+0000] {logging_mixin.py:188} INFO - [2025-08-18T22:58:29.040+0000] {dag.py:3834} INFO - Setting next_dagrun for generate_data to 2025-08-18 00:00:00+00:00, run_after=2025-08-19 00:00:00+00:00
[2025-08-18T22:58:29.098+0000] {processor.py:183} INFO - Processing /opt/airflow/dags/generate_data.py took 0.645 seconds
[2025-08-18T22:58:59.443+0000] {processor.py:161} INFO - Started process (PID=877) to work on /opt/airflow/dags/generate_data.py
[2025-08-18T22:58:59.444+0000] {processor.py:830} INFO - Processing file /opt/airflow/dags/generate_data.py for tasks to queue
[2025-08-18T22:58:59.447+0000] {logging_mixin.py:188} INFO - [2025-08-18T22:58:59.446+0000] {dagbag.py:540} INFO - Filling up the DagBag from /opt/airflow/dags/generate_data.py
[2025-08-18T22:58:59.921+0000] {processor.py:840} INFO - DAG(s) 'generate_data' retrieved from /opt/airflow/dags/generate_data.py
[2025-08-18T22:59:00.023+0000] {logging_mixin.py:188} INFO - [2025-08-18T22:59:00.022+0000] {dag.py:3047} INFO - Sync 1 DAGs
[2025-08-18T22:59:00.070+0000] {logging_mixin.py:188} INFO - [2025-08-18T22:59:00.069+0000] {dag.py:3834} INFO - Setting next_dagrun for generate_data to 2025-08-18 00:00:00+00:00, run_after=2025-08-19 00:00:00+00:00
[2025-08-18T22:59:00.117+0000] {processor.py:183} INFO - Processing /opt/airflow/dags/generate_data.py took 0.681 seconds
[2025-08-18T22:59:30.633+0000] {processor.py:161} INFO - Started process (PID=888) to work on /opt/airflow/dags/generate_data.py
[2025-08-18T22:59:30.635+0000] {processor.py:830} INFO - Processing file /opt/airflow/dags/generate_data.py for tasks to queue
[2025-08-18T22:59:30.639+0000] {logging_mixin.py:188} INFO - [2025-08-18T22:59:30.636+0000] {dagbag.py:540} INFO - Filling up the DagBag from /opt/airflow/dags/generate_data.py
[2025-08-18T22:59:31.039+0000] {processor.py:840} INFO - DAG(s) 'generate_data' retrieved from /opt/airflow/dags/generate_data.py
[2025-08-18T22:59:31.124+0000] {logging_mixin.py:188} INFO - [2025-08-18T22:59:31.124+0000] {dag.py:3047} INFO - Sync 1 DAGs
[2025-08-18T22:59:31.198+0000] {logging_mixin.py:188} INFO - [2025-08-18T22:59:31.197+0000] {dag.py:3834} INFO - Setting next_dagrun for generate_data to 2025-08-18 00:00:00+00:00, run_after=2025-08-19 00:00:00+00:00
[2025-08-18T22:59:31.280+0000] {processor.py:183} INFO - Processing /opt/airflow/dags/generate_data.py took 0.653 seconds
[2025-08-18T23:00:01.708+0000] {processor.py:161} INFO - Started process (PID=899) to work on /opt/airflow/dags/generate_data.py
[2025-08-18T23:00:01.709+0000] {processor.py:830} INFO - Processing file /opt/airflow/dags/generate_data.py for tasks to queue
[2025-08-18T23:00:01.711+0000] {logging_mixin.py:188} INFO - [2025-08-18T23:00:01.711+0000] {dagbag.py:540} INFO - Filling up the DagBag from /opt/airflow/dags/generate_data.py
[2025-08-18T23:00:02.124+0000] {processor.py:840} INFO - DAG(s) 'generate_data' retrieved from /opt/airflow/dags/generate_data.py
[2025-08-18T23:00:02.213+0000] {logging_mixin.py:188} INFO - [2025-08-18T23:00:02.212+0000] {dag.py:3047} INFO - Sync 1 DAGs
[2025-08-18T23:00:02.276+0000] {logging_mixin.py:188} INFO - [2025-08-18T23:00:02.275+0000] {dag.py:3834} INFO - Setting next_dagrun for generate_data to 2025-08-18 00:00:00+00:00, run_after=2025-08-19 00:00:00+00:00
[2025-08-18T23:00:02.325+0000] {processor.py:183} INFO - Processing /opt/airflow/dags/generate_data.py took 0.625 seconds
[2025-08-18T23:00:32.915+0000] {processor.py:161} INFO - Started process (PID=910) to work on /opt/airflow/dags/generate_data.py
[2025-08-18T23:00:32.917+0000] {processor.py:830} INFO - Processing file /opt/airflow/dags/generate_data.py for tasks to queue
[2025-08-18T23:00:32.923+0000] {logging_mixin.py:188} INFO - [2025-08-18T23:00:32.919+0000] {dagbag.py:540} INFO - Filling up the DagBag from /opt/airflow/dags/generate_data.py
[2025-08-18T23:00:33.592+0000] {processor.py:840} INFO - DAG(s) 'generate_data' retrieved from /opt/airflow/dags/generate_data.py
[2025-08-18T23:00:50.040+0000] {logging_mixin.py:188} INFO - [2025-08-18T23:00:50.031+0000] {dag.py:3047} INFO - Sync 1 DAGs
[2025-08-18T23:00:50.121+0000] {logging_mixin.py:188} INFO - [2025-08-18T23:00:50.121+0000] {dag.py:3834} INFO - Setting next_dagrun for generate_data to 2025-08-18 00:00:00+00:00, run_after=2025-08-19 00:00:00+00:00
[2025-08-18T23:00:50.164+0000] {processor.py:183} INFO - Processing /opt/airflow/dags/generate_data.py took 17.261 seconds
[2025-08-18T23:01:20.522+0000] {processor.py:161} INFO - Started process (PID=915) to work on /opt/airflow/dags/generate_data.py
[2025-08-18T23:01:20.524+0000] {processor.py:830} INFO - Processing file /opt/airflow/dags/generate_data.py for tasks to queue
[2025-08-18T23:01:20.533+0000] {logging_mixin.py:188} INFO - [2025-08-18T23:01:20.530+0000] {dagbag.py:540} INFO - Filling up the DagBag from /opt/airflow/dags/generate_data.py
[2025-08-18T23:01:21.245+0000] {processor.py:840} INFO - DAG(s) 'generate_data' retrieved from /opt/airflow/dags/generate_data.py
[2025-08-18T23:01:21.824+0000] {logging_mixin.py:188} INFO - [2025-08-18T23:01:21.816+0000] {dag.py:3047} INFO - Sync 1 DAGs
[2025-08-18T23:01:21.927+0000] {logging_mixin.py:188} INFO - [2025-08-18T23:01:21.926+0000] {dag.py:3834} INFO - Setting next_dagrun for generate_data to 2025-08-18 00:00:00+00:00, run_after=2025-08-19 00:00:00+00:00
[2025-08-18T23:01:21.980+0000] {processor.py:183} INFO - Processing /opt/airflow/dags/generate_data.py took 1.471 seconds
[2025-08-18T23:01:54.427+0000] {processor.py:161} INFO - Started process (PID=926) to work on /opt/airflow/dags/generate_data.py
[2025-08-18T23:01:54.762+0000] {processor.py:830} INFO - Processing file /opt/airflow/dags/generate_data.py for tasks to queue
[2025-08-18T23:01:55.335+0000] {logging_mixin.py:188} INFO - [2025-08-18T23:01:55.142+0000] {dagbag.py:540} INFO - Filling up the DagBag from /opt/airflow/dags/generate_data.py
[2025-08-18T23:02:33.446+0000] {logging_mixin.py:188} INFO - [2025-08-18T23:02:33.333+0000] {timeout.py:68} ERROR - Process timed out, PID: 926
[2025-08-18T23:03:07.926+0000] {processor.py:161} INFO - Started process (PID=937) to work on /opt/airflow/dags/generate_data.py
[2025-08-18T23:03:07.927+0000] {processor.py:830} INFO - Processing file /opt/airflow/dags/generate_data.py for tasks to queue
[2025-08-18T23:03:07.932+0000] {logging_mixin.py:188} INFO - [2025-08-18T23:03:07.931+0000] {dagbag.py:540} INFO - Filling up the DagBag from /opt/airflow/dags/generate_data.py
[2025-08-18T23:03:08.586+0000] {processor.py:840} INFO - DAG(s) 'generate_data' retrieved from /opt/airflow/dags/generate_data.py
[2025-08-18T23:03:08.814+0000] {logging_mixin.py:188} INFO - [2025-08-18T23:03:08.810+0000] {dag.py:3047} INFO - Sync 1 DAGs
[2025-08-18T23:03:09.018+0000] {logging_mixin.py:188} INFO - [2025-08-18T23:03:09.018+0000] {dag.py:3834} INFO - Setting next_dagrun for generate_data to 2025-08-18 00:00:00+00:00, run_after=2025-08-19 00:00:00+00:00
[2025-08-18T23:03:09.109+0000] {processor.py:183} INFO - Processing /opt/airflow/dags/generate_data.py took 1.196 seconds
[2025-08-18T23:03:39.552+0000] {processor.py:161} INFO - Started process (PID=948) to work on /opt/airflow/dags/generate_data.py
[2025-08-18T23:03:39.567+0000] {processor.py:830} INFO - Processing file /opt/airflow/dags/generate_data.py for tasks to queue
[2025-08-18T23:03:39.588+0000] {logging_mixin.py:188} INFO - [2025-08-18T23:03:39.572+0000] {dagbag.py:540} INFO - Filling up the DagBag from /opt/airflow/dags/generate_data.py
[2025-08-18T23:04:57.263+0000] {logging_mixin.py:188} INFO - [2025-08-18T23:04:29.529+0000] {timeout.py:68} ERROR - Process timed out, PID: 948
[2025-08-18T23:07:55.964+0000] {processor.py:161} INFO - Started process (PID=959) to work on /opt/airflow/dags/generate_data.py
[2025-08-18T23:07:55.966+0000] {processor.py:830} INFO - Processing file /opt/airflow/dags/generate_data.py for tasks to queue
[2025-08-18T23:07:55.972+0000] {logging_mixin.py:188} INFO - [2025-08-18T23:07:55.968+0000] {dagbag.py:540} INFO - Filling up the DagBag from /opt/airflow/dags/generate_data.py
[2025-08-18T23:07:56.651+0000] {processor.py:840} INFO - DAG(s) 'generate_data' retrieved from /opt/airflow/dags/generate_data.py
[2025-08-18T23:07:57.885+0000] {logging_mixin.py:188} INFO - [2025-08-18T23:07:57.867+0000] {dag.py:3047} INFO - Sync 1 DAGs
[2025-08-18T23:07:58.166+0000] {logging_mixin.py:188} INFO - [2025-08-18T23:07:58.155+0000] {dag.py:3834} INFO - Setting next_dagrun for generate_data to 2025-08-18 00:00:00+00:00, run_after=2025-08-19 00:00:00+00:00
[2025-08-18T23:07:58.981+0000] {processor.py:183} INFO - Processing /opt/airflow/dags/generate_data.py took 3.031 seconds
[2025-08-18T23:08:29.817+0000] {processor.py:161} INFO - Started process (PID=964) to work on /opt/airflow/dags/generate_data.py
[2025-08-18T23:08:29.819+0000] {processor.py:830} INFO - Processing file /opt/airflow/dags/generate_data.py for tasks to queue
[2025-08-18T23:08:29.824+0000] {logging_mixin.py:188} INFO - [2025-08-18T23:08:29.822+0000] {dagbag.py:540} INFO - Filling up the DagBag from /opt/airflow/dags/generate_data.py
[2025-08-18T23:08:30.397+0000] {processor.py:840} INFO - DAG(s) 'generate_data' retrieved from /opt/airflow/dags/generate_data.py
[2025-08-18T23:09:01.681+0000] {processor.py:186} ERROR - Got an exception! Propagating...
Traceback (most recent call last):
  File "/home/airflow/.local/lib/python3.8/site-packages/sqlalchemy/engine/base.py", line 3371, in _wrap_pool_connect
    return fn()
  File "/home/airflow/.local/lib/python3.8/site-packages/sqlalchemy/pool/base.py", line 327, in connect
    return _ConnectionFairy._checkout(self)
  File "/home/airflow/.local/lib/python3.8/site-packages/sqlalchemy/pool/base.py", line 894, in _checkout
    fairy = _ConnectionRecord.checkout(pool)
  File "/home/airflow/.local/lib/python3.8/site-packages/sqlalchemy/pool/base.py", line 493, in checkout
    rec = pool._do_get()
  File "/home/airflow/.local/lib/python3.8/site-packages/sqlalchemy/pool/impl.py", line 146, in _do_get
    self._dec_overflow()
  File "/home/airflow/.local/lib/python3.8/site-packages/sqlalchemy/util/langhelpers.py", line 70, in __exit__
    compat.raise_(
  File "/home/airflow/.local/lib/python3.8/site-packages/sqlalchemy/util/compat.py", line 211, in raise_
    raise exception
  File "/home/airflow/.local/lib/python3.8/site-packages/sqlalchemy/pool/impl.py", line 143, in _do_get
    return self._create_connection()
  File "/home/airflow/.local/lib/python3.8/site-packages/sqlalchemy/pool/base.py", line 273, in _create_connection
    return _ConnectionRecord(self)
  File "/home/airflow/.local/lib/python3.8/site-packages/sqlalchemy/pool/base.py", line 388, in __init__
    self.__connect()
  File "/home/airflow/.local/lib/python3.8/site-packages/sqlalchemy/pool/base.py", line 691, in __connect
    pool.logger.debug("Error on connect(): %s", e)
  File "/home/airflow/.local/lib/python3.8/site-packages/sqlalchemy/util/langhelpers.py", line 70, in __exit__
    compat.raise_(
  File "/home/airflow/.local/lib/python3.8/site-packages/sqlalchemy/util/compat.py", line 211, in raise_
    raise exception
  File "/home/airflow/.local/lib/python3.8/site-packages/sqlalchemy/pool/base.py", line 686, in __connect
    self.dbapi_connection = connection = pool._invoke_creator(self)
  File "/home/airflow/.local/lib/python3.8/site-packages/sqlalchemy/engine/create.py", line 574, in connect
    return dialect.connect(*cargs, **cparams)
  File "/home/airflow/.local/lib/python3.8/site-packages/sqlalchemy/engine/default.py", line 598, in connect
    return self.dbapi.connect(*cargs, **cparams)
  File "/home/airflow/.local/lib/python3.8/site-packages/psycopg2/__init__.py", line 122, in connect
    conn = _connect(dsn, connection_factory=connection_factory, **kwasync)
psycopg2.OperationalError: could not translate host name "db" to address: Temporary failure in name resolution


The above exception was the direct cause of the following exception:

Traceback (most recent call last):
  File "/home/airflow/.local/lib/python3.8/site-packages/airflow/dag_processing/processor.py", line 182, in _run_file_processor
    _handle_dag_file_processing()
  File "/home/airflow/.local/lib/python3.8/site-packages/airflow/dag_processing/processor.py", line 163, in _handle_dag_file_processing
    result: tuple[int, int] = dag_file_processor.process_file(
  File "/home/airflow/.local/lib/python3.8/site-packages/airflow/utils/session.py", line 79, in wrapper
    return func(*args, session=session, **kwargs)
  File "/home/airflow/.local/lib/python3.8/site-packages/airflow/dag_processing/processor.py", line 859, in process_file
    serialize_errors = DagFileProcessor.save_dag_to_db(
  File "/home/airflow/.local/lib/python3.8/site-packages/airflow/api_internal/internal_api_call.py", line 114, in wrapper
    return func(*args, **kwargs)
  File "/home/airflow/.local/lib/python3.8/site-packages/airflow/utils/session.py", line 79, in wrapper
    return func(*args, session=session, **kwargs)
  File "/home/airflow/.local/lib/python3.8/site-packages/airflow/dag_processing/processor.py", line 895, in save_dag_to_db
    import_errors = DagBag._sync_to_db(dags=dags, processor_subdir=dag_directory, session=session)
  File "/home/airflow/.local/lib/python3.8/site-packages/airflow/utils/session.py", line 76, in wrapper
    return func(*args, **kwargs)
  File "/home/airflow/.local/lib/python3.8/site-packages/airflow/models/dagbag.py", line 659, in _sync_to_db
    for attempt in run_with_db_retries(logger=log):
  File "/home/airflow/.local/lib/python3.8/site-packages/tenacity/__init__.py", line 347, in __iter__
    do = self.iter(retry_state=retry_state)
  File "/home/airflow/.local/lib/python3.8/site-packages/tenacity/__init__.py", line 325, in iter
    raise retry_exc.reraise()
  File "/home/airflow/.local/lib/python3.8/site-packages/tenacity/__init__.py", line 158, in reraise
    raise self.last_attempt.result()
  File "/usr/local/lib/python3.8/concurrent/futures/_base.py", line 437, in result
    return self.__get_result()
  File "/usr/local/lib/python3.8/concurrent/futures/_base.py", line 389, in __get_result
    raise self._exception
  File "/home/airflow/.local/lib/python3.8/site-packages/airflow/models/dagbag.py", line 672, in _sync_to_db
    _serialize_dag_capturing_errors(dag, session, processor_subdir)
  File "/home/airflow/.local/lib/python3.8/site-packages/airflow/models/dagbag.py", line 637, in _serialize_dag_capturing_errors
    dag_was_updated = SerializedDagModel.write_dag(
  File "/home/airflow/.local/lib/python3.8/site-packages/airflow/utils/session.py", line 76, in wrapper
    return func(*args, **kwargs)
  File "/home/airflow/.local/lib/python3.8/site-packages/airflow/models/serialized_dag.py", line 157, in write_dag
    if session.scalar(
  File "/home/airflow/.local/lib/python3.8/site-packages/sqlalchemy/orm/session.py", line 1747, in scalar
    return self.execute(
  File "/home/airflow/.local/lib/python3.8/site-packages/sqlalchemy/orm/session.py", line 1716, in execute
    conn = self._connection_for_bind(bind)
  File "/home/airflow/.local/lib/python3.8/site-packages/sqlalchemy/orm/session.py", line 1555, in _connection_for_bind
    return self._transaction._connection_for_bind(
  File "/home/airflow/.local/lib/python3.8/site-packages/sqlalchemy/orm/session.py", line 750, in _connection_for_bind
    conn = bind.connect()
  File "/home/airflow/.local/lib/python3.8/site-packages/sqlalchemy/future/engine.py", line 412, in connect
    return super(Engine, self).connect()
  File "/home/airflow/.local/lib/python3.8/site-packages/sqlalchemy/engine/base.py", line 3325, in connect
    return self._connection_cls(self, close_with_result=close_with_result)
  File "/home/airflow/.local/lib/python3.8/site-packages/sqlalchemy/engine/base.py", line 96, in __init__
    else engine.raw_connection()
  File "/home/airflow/.local/lib/python3.8/site-packages/sqlalchemy/engine/base.py", line 3404, in raw_connection
    return self._wrap_pool_connect(self.pool.connect, _connection)
  File "/home/airflow/.local/lib/python3.8/site-packages/sqlalchemy/engine/base.py", line 3374, in _wrap_pool_connect
    Connection._handle_dbapi_exception_noconnection(
  File "/home/airflow/.local/lib/python3.8/site-packages/sqlalchemy/engine/base.py", line 2208, in _handle_dbapi_exception_noconnection
    util.raise_(
  File "/home/airflow/.local/lib/python3.8/site-packages/sqlalchemy/util/compat.py", line 211, in raise_
    raise exception
  File "/home/airflow/.local/lib/python3.8/site-packages/sqlalchemy/engine/base.py", line 3371, in _wrap_pool_connect
    return fn()
  File "/home/airflow/.local/lib/python3.8/site-packages/sqlalchemy/pool/base.py", line 327, in connect
    return _ConnectionFairy._checkout(self)
  File "/home/airflow/.local/lib/python3.8/site-packages/sqlalchemy/pool/base.py", line 894, in _checkout
    fairy = _ConnectionRecord.checkout(pool)
  File "/home/airflow/.local/lib/python3.8/site-packages/sqlalchemy/pool/base.py", line 493, in checkout
    rec = pool._do_get()
  File "/home/airflow/.local/lib/python3.8/site-packages/sqlalchemy/pool/impl.py", line 146, in _do_get
    self._dec_overflow()
  File "/home/airflow/.local/lib/python3.8/site-packages/sqlalchemy/util/langhelpers.py", line 70, in __exit__
    compat.raise_(
  File "/home/airflow/.local/lib/python3.8/site-packages/sqlalchemy/util/compat.py", line 211, in raise_
    raise exception
  File "/home/airflow/.local/lib/python3.8/site-packages/sqlalchemy/pool/impl.py", line 143, in _do_get
    return self._create_connection()
  File "/home/airflow/.local/lib/python3.8/site-packages/sqlalchemy/pool/base.py", line 273, in _create_connection
    return _ConnectionRecord(self)
  File "/home/airflow/.local/lib/python3.8/site-packages/sqlalchemy/pool/base.py", line 388, in __init__
    self.__connect()
  File "/home/airflow/.local/lib/python3.8/site-packages/sqlalchemy/pool/base.py", line 691, in __connect
    pool.logger.debug("Error on connect(): %s", e)
  File "/home/airflow/.local/lib/python3.8/site-packages/sqlalchemy/util/langhelpers.py", line 70, in __exit__
    compat.raise_(
  File "/home/airflow/.local/lib/python3.8/site-packages/sqlalchemy/util/compat.py", line 211, in raise_
    raise exception
  File "/home/airflow/.local/lib/python3.8/site-packages/sqlalchemy/pool/base.py", line 686, in __connect
    self.dbapi_connection = connection = pool._invoke_creator(self)
  File "/home/airflow/.local/lib/python3.8/site-packages/sqlalchemy/engine/create.py", line 574, in connect
    return dialect.connect(*cargs, **cparams)
  File "/home/airflow/.local/lib/python3.8/site-packages/sqlalchemy/engine/default.py", line 598, in connect
    return self.dbapi.connect(*cargs, **cparams)
  File "/home/airflow/.local/lib/python3.8/site-packages/psycopg2/__init__.py", line 122, in connect
    conn = _connect(dsn, connection_factory=connection_factory, **kwasync)
sqlalchemy.exc.OperationalError: (psycopg2.OperationalError) could not translate host name "db" to address: Temporary failure in name resolution

(Background on this error at: https://sqlalche.me/e/14/e3q8)
[2025-08-18T23:09:32.357+0000] {processor.py:161} INFO - Started process (PID=969) to work on /opt/airflow/dags/generate_data.py
[2025-08-18T23:09:32.364+0000] {processor.py:830} INFO - Processing file /opt/airflow/dags/generate_data.py for tasks to queue
[2025-08-18T23:09:32.371+0000] {logging_mixin.py:188} INFO - [2025-08-18T23:09:32.366+0000] {dagbag.py:540} INFO - Filling up the DagBag from /opt/airflow/dags/generate_data.py
[2025-08-18T23:09:33.440+0000] {processor.py:840} INFO - DAG(s) 'generate_data' retrieved from /opt/airflow/dags/generate_data.py
[2025-08-18T23:10:04.004+0000] {processor.py:186} ERROR - Got an exception! Propagating...
Traceback (most recent call last):
  File "/home/airflow/.local/lib/python3.8/site-packages/sqlalchemy/engine/base.py", line 3371, in _wrap_pool_connect
    return fn()
  File "/home/airflow/.local/lib/python3.8/site-packages/sqlalchemy/pool/base.py", line 327, in connect
    return _ConnectionFairy._checkout(self)
  File "/home/airflow/.local/lib/python3.8/site-packages/sqlalchemy/pool/base.py", line 894, in _checkout
    fairy = _ConnectionRecord.checkout(pool)
  File "/home/airflow/.local/lib/python3.8/site-packages/sqlalchemy/pool/base.py", line 493, in checkout
    rec = pool._do_get()
  File "/home/airflow/.local/lib/python3.8/site-packages/sqlalchemy/pool/impl.py", line 146, in _do_get
    self._dec_overflow()
  File "/home/airflow/.local/lib/python3.8/site-packages/sqlalchemy/util/langhelpers.py", line 70, in __exit__
    compat.raise_(
  File "/home/airflow/.local/lib/python3.8/site-packages/sqlalchemy/util/compat.py", line 211, in raise_
    raise exception
  File "/home/airflow/.local/lib/python3.8/site-packages/sqlalchemy/pool/impl.py", line 143, in _do_get
    return self._create_connection()
  File "/home/airflow/.local/lib/python3.8/site-packages/sqlalchemy/pool/base.py", line 273, in _create_connection
    return _ConnectionRecord(self)
  File "/home/airflow/.local/lib/python3.8/site-packages/sqlalchemy/pool/base.py", line 388, in __init__
    self.__connect()
  File "/home/airflow/.local/lib/python3.8/site-packages/sqlalchemy/pool/base.py", line 691, in __connect
    pool.logger.debug("Error on connect(): %s", e)
  File "/home/airflow/.local/lib/python3.8/site-packages/sqlalchemy/util/langhelpers.py", line 70, in __exit__
    compat.raise_(
  File "/home/airflow/.local/lib/python3.8/site-packages/sqlalchemy/util/compat.py", line 211, in raise_
    raise exception
  File "/home/airflow/.local/lib/python3.8/site-packages/sqlalchemy/pool/base.py", line 686, in __connect
    self.dbapi_connection = connection = pool._invoke_creator(self)
  File "/home/airflow/.local/lib/python3.8/site-packages/sqlalchemy/engine/create.py", line 574, in connect
    return dialect.connect(*cargs, **cparams)
  File "/home/airflow/.local/lib/python3.8/site-packages/sqlalchemy/engine/default.py", line 598, in connect
    return self.dbapi.connect(*cargs, **cparams)
  File "/home/airflow/.local/lib/python3.8/site-packages/psycopg2/__init__.py", line 122, in connect
    conn = _connect(dsn, connection_factory=connection_factory, **kwasync)
psycopg2.OperationalError: could not translate host name "db" to address: Temporary failure in name resolution


The above exception was the direct cause of the following exception:

Traceback (most recent call last):
  File "/home/airflow/.local/lib/python3.8/site-packages/airflow/dag_processing/processor.py", line 182, in _run_file_processor
    _handle_dag_file_processing()
  File "/home/airflow/.local/lib/python3.8/site-packages/airflow/dag_processing/processor.py", line 163, in _handle_dag_file_processing
    result: tuple[int, int] = dag_file_processor.process_file(
  File "/home/airflow/.local/lib/python3.8/site-packages/airflow/utils/session.py", line 79, in wrapper
    return func(*args, session=session, **kwargs)
  File "/home/airflow/.local/lib/python3.8/site-packages/airflow/dag_processing/processor.py", line 859, in process_file
    serialize_errors = DagFileProcessor.save_dag_to_db(
  File "/home/airflow/.local/lib/python3.8/site-packages/airflow/api_internal/internal_api_call.py", line 114, in wrapper
    return func(*args, **kwargs)
  File "/home/airflow/.local/lib/python3.8/site-packages/airflow/utils/session.py", line 79, in wrapper
    return func(*args, session=session, **kwargs)
  File "/home/airflow/.local/lib/python3.8/site-packages/airflow/dag_processing/processor.py", line 895, in save_dag_to_db
    import_errors = DagBag._sync_to_db(dags=dags, processor_subdir=dag_directory, session=session)
  File "/home/airflow/.local/lib/python3.8/site-packages/airflow/utils/session.py", line 76, in wrapper
    return func(*args, **kwargs)
  File "/home/airflow/.local/lib/python3.8/site-packages/airflow/models/dagbag.py", line 659, in _sync_to_db
    for attempt in run_with_db_retries(logger=log):
  File "/home/airflow/.local/lib/python3.8/site-packages/tenacity/__init__.py", line 347, in __iter__
    do = self.iter(retry_state=retry_state)
  File "/home/airflow/.local/lib/python3.8/site-packages/tenacity/__init__.py", line 325, in iter
    raise retry_exc.reraise()
  File "/home/airflow/.local/lib/python3.8/site-packages/tenacity/__init__.py", line 158, in reraise
    raise self.last_attempt.result()
  File "/usr/local/lib/python3.8/concurrent/futures/_base.py", line 437, in result
    return self.__get_result()
  File "/usr/local/lib/python3.8/concurrent/futures/_base.py", line 389, in __get_result
    raise self._exception
  File "/home/airflow/.local/lib/python3.8/site-packages/airflow/models/dagbag.py", line 672, in _sync_to_db
    _serialize_dag_capturing_errors(dag, session, processor_subdir)
  File "/home/airflow/.local/lib/python3.8/site-packages/airflow/models/dagbag.py", line 637, in _serialize_dag_capturing_errors
    dag_was_updated = SerializedDagModel.write_dag(
  File "/home/airflow/.local/lib/python3.8/site-packages/airflow/utils/session.py", line 76, in wrapper
    return func(*args, **kwargs)
  File "/home/airflow/.local/lib/python3.8/site-packages/airflow/models/serialized_dag.py", line 157, in write_dag
    if session.scalar(
  File "/home/airflow/.local/lib/python3.8/site-packages/sqlalchemy/orm/session.py", line 1747, in scalar
    return self.execute(
  File "/home/airflow/.local/lib/python3.8/site-packages/sqlalchemy/orm/session.py", line 1716, in execute
    conn = self._connection_for_bind(bind)
  File "/home/airflow/.local/lib/python3.8/site-packages/sqlalchemy/orm/session.py", line 1555, in _connection_for_bind
    return self._transaction._connection_for_bind(
  File "/home/airflow/.local/lib/python3.8/site-packages/sqlalchemy/orm/session.py", line 750, in _connection_for_bind
    conn = bind.connect()
  File "/home/airflow/.local/lib/python3.8/site-packages/sqlalchemy/future/engine.py", line 412, in connect
    return super(Engine, self).connect()
  File "/home/airflow/.local/lib/python3.8/site-packages/sqlalchemy/engine/base.py", line 3325, in connect
    return self._connection_cls(self, close_with_result=close_with_result)
  File "/home/airflow/.local/lib/python3.8/site-packages/sqlalchemy/engine/base.py", line 96, in __init__
    else engine.raw_connection()
  File "/home/airflow/.local/lib/python3.8/site-packages/sqlalchemy/engine/base.py", line 3404, in raw_connection
    return self._wrap_pool_connect(self.pool.connect, _connection)
  File "/home/airflow/.local/lib/python3.8/site-packages/sqlalchemy/engine/base.py", line 3374, in _wrap_pool_connect
    Connection._handle_dbapi_exception_noconnection(
  File "/home/airflow/.local/lib/python3.8/site-packages/sqlalchemy/engine/base.py", line 2208, in _handle_dbapi_exception_noconnection
    util.raise_(
  File "/home/airflow/.local/lib/python3.8/site-packages/sqlalchemy/util/compat.py", line 211, in raise_
    raise exception
  File "/home/airflow/.local/lib/python3.8/site-packages/sqlalchemy/engine/base.py", line 3371, in _wrap_pool_connect
    return fn()
  File "/home/airflow/.local/lib/python3.8/site-packages/sqlalchemy/pool/base.py", line 327, in connect
    return _ConnectionFairy._checkout(self)
  File "/home/airflow/.local/lib/python3.8/site-packages/sqlalchemy/pool/base.py", line 894, in _checkout
    fairy = _ConnectionRecord.checkout(pool)
  File "/home/airflow/.local/lib/python3.8/site-packages/sqlalchemy/pool/base.py", line 493, in checkout
    rec = pool._do_get()
  File "/home/airflow/.local/lib/python3.8/site-packages/sqlalchemy/pool/impl.py", line 146, in _do_get
    self._dec_overflow()
  File "/home/airflow/.local/lib/python3.8/site-packages/sqlalchemy/util/langhelpers.py", line 70, in __exit__
    compat.raise_(
  File "/home/airflow/.local/lib/python3.8/site-packages/sqlalchemy/util/compat.py", line 211, in raise_
    raise exception
  File "/home/airflow/.local/lib/python3.8/site-packages/sqlalchemy/pool/impl.py", line 143, in _do_get
    return self._create_connection()
  File "/home/airflow/.local/lib/python3.8/site-packages/sqlalchemy/pool/base.py", line 273, in _create_connection
    return _ConnectionRecord(self)
  File "/home/airflow/.local/lib/python3.8/site-packages/sqlalchemy/pool/base.py", line 388, in __init__
    self.__connect()
  File "/home/airflow/.local/lib/python3.8/site-packages/sqlalchemy/pool/base.py", line 691, in __connect
    pool.logger.debug("Error on connect(): %s", e)
  File "/home/airflow/.local/lib/python3.8/site-packages/sqlalchemy/util/langhelpers.py", line 70, in __exit__
    compat.raise_(
  File "/home/airflow/.local/lib/python3.8/site-packages/sqlalchemy/util/compat.py", line 211, in raise_
    raise exception
  File "/home/airflow/.local/lib/python3.8/site-packages/sqlalchemy/pool/base.py", line 686, in __connect
    self.dbapi_connection = connection = pool._invoke_creator(self)
  File "/home/airflow/.local/lib/python3.8/site-packages/sqlalchemy/engine/create.py", line 574, in connect
    return dialect.connect(*cargs, **cparams)
  File "/home/airflow/.local/lib/python3.8/site-packages/sqlalchemy/engine/default.py", line 598, in connect
    return self.dbapi.connect(*cargs, **cparams)
  File "/home/airflow/.local/lib/python3.8/site-packages/psycopg2/__init__.py", line 122, in connect
    conn = _connect(dsn, connection_factory=connection_factory, **kwasync)
sqlalchemy.exc.OperationalError: (psycopg2.OperationalError) could not translate host name "db" to address: Temporary failure in name resolution

(Background on this error at: https://sqlalche.me/e/14/e3q8)
[2025-08-18T23:10:34.966+0000] {processor.py:161} INFO - Started process (PID=974) to work on /opt/airflow/dags/generate_data.py
[2025-08-18T23:10:34.971+0000] {processor.py:830} INFO - Processing file /opt/airflow/dags/generate_data.py for tasks to queue
[2025-08-18T23:10:34.980+0000] {logging_mixin.py:188} INFO - [2025-08-18T23:10:34.975+0000] {dagbag.py:540} INFO - Filling up the DagBag from /opt/airflow/dags/generate_data.py
[2025-08-18T23:10:36.252+0000] {processor.py:840} INFO - DAG(s) 'generate_data' retrieved from /opt/airflow/dags/generate_data.py
[2025-08-18T23:11:08.478+0000] {processor.py:186} ERROR - Got an exception! Propagating...
Traceback (most recent call last):
  File "/home/airflow/.local/lib/python3.8/site-packages/sqlalchemy/engine/base.py", line 3371, in _wrap_pool_connect
    return fn()
  File "/home/airflow/.local/lib/python3.8/site-packages/sqlalchemy/pool/base.py", line 327, in connect
    return _ConnectionFairy._checkout(self)
  File "/home/airflow/.local/lib/python3.8/site-packages/sqlalchemy/pool/base.py", line 894, in _checkout
    fairy = _ConnectionRecord.checkout(pool)
  File "/home/airflow/.local/lib/python3.8/site-packages/sqlalchemy/pool/base.py", line 493, in checkout
    rec = pool._do_get()
  File "/home/airflow/.local/lib/python3.8/site-packages/sqlalchemy/pool/impl.py", line 146, in _do_get
    self._dec_overflow()
  File "/home/airflow/.local/lib/python3.8/site-packages/sqlalchemy/util/langhelpers.py", line 70, in __exit__
    compat.raise_(
  File "/home/airflow/.local/lib/python3.8/site-packages/sqlalchemy/util/compat.py", line 211, in raise_
    raise exception
  File "/home/airflow/.local/lib/python3.8/site-packages/sqlalchemy/pool/impl.py", line 143, in _do_get
    return self._create_connection()
  File "/home/airflow/.local/lib/python3.8/site-packages/sqlalchemy/pool/base.py", line 273, in _create_connection
    return _ConnectionRecord(self)
  File "/home/airflow/.local/lib/python3.8/site-packages/sqlalchemy/pool/base.py", line 388, in __init__
    self.__connect()
  File "/home/airflow/.local/lib/python3.8/site-packages/sqlalchemy/pool/base.py", line 691, in __connect
    pool.logger.debug("Error on connect(): %s", e)
  File "/home/airflow/.local/lib/python3.8/site-packages/sqlalchemy/util/langhelpers.py", line 70, in __exit__
    compat.raise_(
  File "/home/airflow/.local/lib/python3.8/site-packages/sqlalchemy/util/compat.py", line 211, in raise_
    raise exception
  File "/home/airflow/.local/lib/python3.8/site-packages/sqlalchemy/pool/base.py", line 686, in __connect
    self.dbapi_connection = connection = pool._invoke_creator(self)
  File "/home/airflow/.local/lib/python3.8/site-packages/sqlalchemy/engine/create.py", line 574, in connect
    return dialect.connect(*cargs, **cparams)
  File "/home/airflow/.local/lib/python3.8/site-packages/sqlalchemy/engine/default.py", line 598, in connect
    return self.dbapi.connect(*cargs, **cparams)
  File "/home/airflow/.local/lib/python3.8/site-packages/psycopg2/__init__.py", line 122, in connect
    conn = _connect(dsn, connection_factory=connection_factory, **kwasync)
psycopg2.OperationalError: could not translate host name "db" to address: Temporary failure in name resolution


The above exception was the direct cause of the following exception:

Traceback (most recent call last):
  File "/home/airflow/.local/lib/python3.8/site-packages/airflow/dag_processing/processor.py", line 182, in _run_file_processor
    _handle_dag_file_processing()
  File "/home/airflow/.local/lib/python3.8/site-packages/airflow/dag_processing/processor.py", line 163, in _handle_dag_file_processing
    result: tuple[int, int] = dag_file_processor.process_file(
  File "/home/airflow/.local/lib/python3.8/site-packages/airflow/utils/session.py", line 79, in wrapper
    return func(*args, session=session, **kwargs)
  File "/home/airflow/.local/lib/python3.8/site-packages/airflow/dag_processing/processor.py", line 859, in process_file
    serialize_errors = DagFileProcessor.save_dag_to_db(
  File "/home/airflow/.local/lib/python3.8/site-packages/airflow/api_internal/internal_api_call.py", line 114, in wrapper
    return func(*args, **kwargs)
  File "/home/airflow/.local/lib/python3.8/site-packages/airflow/utils/session.py", line 79, in wrapper
    return func(*args, session=session, **kwargs)
  File "/home/airflow/.local/lib/python3.8/site-packages/airflow/dag_processing/processor.py", line 895, in save_dag_to_db
    import_errors = DagBag._sync_to_db(dags=dags, processor_subdir=dag_directory, session=session)
  File "/home/airflow/.local/lib/python3.8/site-packages/airflow/utils/session.py", line 76, in wrapper
    return func(*args, **kwargs)
  File "/home/airflow/.local/lib/python3.8/site-packages/airflow/models/dagbag.py", line 659, in _sync_to_db
    for attempt in run_with_db_retries(logger=log):
  File "/home/airflow/.local/lib/python3.8/site-packages/tenacity/__init__.py", line 347, in __iter__
    do = self.iter(retry_state=retry_state)
  File "/home/airflow/.local/lib/python3.8/site-packages/tenacity/__init__.py", line 325, in iter
    raise retry_exc.reraise()
  File "/home/airflow/.local/lib/python3.8/site-packages/tenacity/__init__.py", line 158, in reraise
    raise self.last_attempt.result()
  File "/usr/local/lib/python3.8/concurrent/futures/_base.py", line 437, in result
    return self.__get_result()
  File "/usr/local/lib/python3.8/concurrent/futures/_base.py", line 389, in __get_result
    raise self._exception
  File "/home/airflow/.local/lib/python3.8/site-packages/airflow/models/dagbag.py", line 672, in _sync_to_db
    _serialize_dag_capturing_errors(dag, session, processor_subdir)
  File "/home/airflow/.local/lib/python3.8/site-packages/airflow/models/dagbag.py", line 637, in _serialize_dag_capturing_errors
    dag_was_updated = SerializedDagModel.write_dag(
  File "/home/airflow/.local/lib/python3.8/site-packages/airflow/utils/session.py", line 76, in wrapper
    return func(*args, **kwargs)
  File "/home/airflow/.local/lib/python3.8/site-packages/airflow/models/serialized_dag.py", line 157, in write_dag
    if session.scalar(
  File "/home/airflow/.local/lib/python3.8/site-packages/sqlalchemy/orm/session.py", line 1747, in scalar
    return self.execute(
  File "/home/airflow/.local/lib/python3.8/site-packages/sqlalchemy/orm/session.py", line 1716, in execute
    conn = self._connection_for_bind(bind)
  File "/home/airflow/.local/lib/python3.8/site-packages/sqlalchemy/orm/session.py", line 1555, in _connection_for_bind
    return self._transaction._connection_for_bind(
  File "/home/airflow/.local/lib/python3.8/site-packages/sqlalchemy/orm/session.py", line 750, in _connection_for_bind
    conn = bind.connect()
  File "/home/airflow/.local/lib/python3.8/site-packages/sqlalchemy/future/engine.py", line 412, in connect
    return super(Engine, self).connect()
  File "/home/airflow/.local/lib/python3.8/site-packages/sqlalchemy/engine/base.py", line 3325, in connect
    return self._connection_cls(self, close_with_result=close_with_result)
  File "/home/airflow/.local/lib/python3.8/site-packages/sqlalchemy/engine/base.py", line 96, in __init__
    else engine.raw_connection()
  File "/home/airflow/.local/lib/python3.8/site-packages/sqlalchemy/engine/base.py", line 3404, in raw_connection
    return self._wrap_pool_connect(self.pool.connect, _connection)
  File "/home/airflow/.local/lib/python3.8/site-packages/sqlalchemy/engine/base.py", line 3374, in _wrap_pool_connect
    Connection._handle_dbapi_exception_noconnection(
  File "/home/airflow/.local/lib/python3.8/site-packages/sqlalchemy/engine/base.py", line 2208, in _handle_dbapi_exception_noconnection
    util.raise_(
  File "/home/airflow/.local/lib/python3.8/site-packages/sqlalchemy/util/compat.py", line 211, in raise_
    raise exception
  File "/home/airflow/.local/lib/python3.8/site-packages/sqlalchemy/engine/base.py", line 3371, in _wrap_pool_connect
    return fn()
  File "/home/airflow/.local/lib/python3.8/site-packages/sqlalchemy/pool/base.py", line 327, in connect
    return _ConnectionFairy._checkout(self)
  File "/home/airflow/.local/lib/python3.8/site-packages/sqlalchemy/pool/base.py", line 894, in _checkout
    fairy = _ConnectionRecord.checkout(pool)
  File "/home/airflow/.local/lib/python3.8/site-packages/sqlalchemy/pool/base.py", line 493, in checkout
    rec = pool._do_get()
  File "/home/airflow/.local/lib/python3.8/site-packages/sqlalchemy/pool/impl.py", line 146, in _do_get
    self._dec_overflow()
  File "/home/airflow/.local/lib/python3.8/site-packages/sqlalchemy/util/langhelpers.py", line 70, in __exit__
    compat.raise_(
  File "/home/airflow/.local/lib/python3.8/site-packages/sqlalchemy/util/compat.py", line 211, in raise_
    raise exception
  File "/home/airflow/.local/lib/python3.8/site-packages/sqlalchemy/pool/impl.py", line 143, in _do_get
    return self._create_connection()
  File "/home/airflow/.local/lib/python3.8/site-packages/sqlalchemy/pool/base.py", line 273, in _create_connection
    return _ConnectionRecord(self)
  File "/home/airflow/.local/lib/python3.8/site-packages/sqlalchemy/pool/base.py", line 388, in __init__
    self.__connect()
  File "/home/airflow/.local/lib/python3.8/site-packages/sqlalchemy/pool/base.py", line 691, in __connect
    pool.logger.debug("Error on connect(): %s", e)
  File "/home/airflow/.local/lib/python3.8/site-packages/sqlalchemy/util/langhelpers.py", line 70, in __exit__
    compat.raise_(
  File "/home/airflow/.local/lib/python3.8/site-packages/sqlalchemy/util/compat.py", line 211, in raise_
    raise exception
  File "/home/airflow/.local/lib/python3.8/site-packages/sqlalchemy/pool/base.py", line 686, in __connect
    self.dbapi_connection = connection = pool._invoke_creator(self)
  File "/home/airflow/.local/lib/python3.8/site-packages/sqlalchemy/engine/create.py", line 574, in connect
    return dialect.connect(*cargs, **cparams)
  File "/home/airflow/.local/lib/python3.8/site-packages/sqlalchemy/engine/default.py", line 598, in connect
    return self.dbapi.connect(*cargs, **cparams)
  File "/home/airflow/.local/lib/python3.8/site-packages/psycopg2/__init__.py", line 122, in connect
    conn = _connect(dsn, connection_factory=connection_factory, **kwasync)
sqlalchemy.exc.OperationalError: (psycopg2.OperationalError) could not translate host name "db" to address: Temporary failure in name resolution

(Background on this error at: https://sqlalche.me/e/14/e3q8)
[2025-08-18T23:12:18.237+0000] {processor.py:161} INFO - Started process (PID=979) to work on /opt/airflow/dags/generate_data.py
[2025-08-18T23:12:18.241+0000] {processor.py:830} INFO - Processing file /opt/airflow/dags/generate_data.py for tasks to queue
[2025-08-18T23:12:18.248+0000] {logging_mixin.py:188} INFO - [2025-08-18T23:12:18.243+0000] {dagbag.py:540} INFO - Filling up the DagBag from /opt/airflow/dags/generate_data.py
[2025-08-18T23:13:22.322+0000] {processor.py:840} INFO - DAG(s) 'generate_data' retrieved from /opt/airflow/dags/generate_data.py
[2025-08-18T23:14:17.750+0000] {processor.py:161} INFO - Started process (PID=982) to work on /opt/airflow/dags/generate_data.py
[2025-08-18T23:14:17.758+0000] {processor.py:830} INFO - Processing file /opt/airflow/dags/generate_data.py for tasks to queue
[2025-08-18T23:14:17.771+0000] {logging_mixin.py:188} INFO - [2025-08-18T23:14:17.766+0000] {dagbag.py:540} INFO - Filling up the DagBag from /opt/airflow/dags/generate_data.py
[2025-08-18T23:14:19.569+0000] {processor.py:840} INFO - DAG(s) 'generate_data' retrieved from /opt/airflow/dags/generate_data.py
[2025-08-18T23:14:50.482+0000] {processor.py:186} ERROR - Got an exception! Propagating...
Traceback (most recent call last):
  File "/home/airflow/.local/lib/python3.8/site-packages/sqlalchemy/engine/base.py", line 3371, in _wrap_pool_connect
    return fn()
  File "/home/airflow/.local/lib/python3.8/site-packages/sqlalchemy/pool/base.py", line 327, in connect
    return _ConnectionFairy._checkout(self)
  File "/home/airflow/.local/lib/python3.8/site-packages/sqlalchemy/pool/base.py", line 894, in _checkout
    fairy = _ConnectionRecord.checkout(pool)
  File "/home/airflow/.local/lib/python3.8/site-packages/sqlalchemy/pool/base.py", line 493, in checkout
    rec = pool._do_get()
  File "/home/airflow/.local/lib/python3.8/site-packages/sqlalchemy/pool/impl.py", line 146, in _do_get
    self._dec_overflow()
  File "/home/airflow/.local/lib/python3.8/site-packages/sqlalchemy/util/langhelpers.py", line 70, in __exit__
    compat.raise_(
  File "/home/airflow/.local/lib/python3.8/site-packages/sqlalchemy/util/compat.py", line 211, in raise_
    raise exception
  File "/home/airflow/.local/lib/python3.8/site-packages/sqlalchemy/pool/impl.py", line 143, in _do_get
    return self._create_connection()
  File "/home/airflow/.local/lib/python3.8/site-packages/sqlalchemy/pool/base.py", line 273, in _create_connection
    return _ConnectionRecord(self)
  File "/home/airflow/.local/lib/python3.8/site-packages/sqlalchemy/pool/base.py", line 388, in __init__
    self.__connect()
  File "/home/airflow/.local/lib/python3.8/site-packages/sqlalchemy/pool/base.py", line 691, in __connect
    pool.logger.debug("Error on connect(): %s", e)
  File "/home/airflow/.local/lib/python3.8/site-packages/sqlalchemy/util/langhelpers.py", line 70, in __exit__
    compat.raise_(
  File "/home/airflow/.local/lib/python3.8/site-packages/sqlalchemy/util/compat.py", line 211, in raise_
    raise exception
  File "/home/airflow/.local/lib/python3.8/site-packages/sqlalchemy/pool/base.py", line 686, in __connect
    self.dbapi_connection = connection = pool._invoke_creator(self)
  File "/home/airflow/.local/lib/python3.8/site-packages/sqlalchemy/engine/create.py", line 574, in connect
    return dialect.connect(*cargs, **cparams)
  File "/home/airflow/.local/lib/python3.8/site-packages/sqlalchemy/engine/default.py", line 598, in connect
    return self.dbapi.connect(*cargs, **cparams)
  File "/home/airflow/.local/lib/python3.8/site-packages/psycopg2/__init__.py", line 122, in connect
    conn = _connect(dsn, connection_factory=connection_factory, **kwasync)
psycopg2.OperationalError: could not translate host name "db" to address: Temporary failure in name resolution


The above exception was the direct cause of the following exception:

Traceback (most recent call last):
  File "/home/airflow/.local/lib/python3.8/site-packages/airflow/dag_processing/processor.py", line 182, in _run_file_processor
    _handle_dag_file_processing()
  File "/home/airflow/.local/lib/python3.8/site-packages/airflow/dag_processing/processor.py", line 163, in _handle_dag_file_processing
    result: tuple[int, int] = dag_file_processor.process_file(
  File "/home/airflow/.local/lib/python3.8/site-packages/airflow/utils/session.py", line 79, in wrapper
    return func(*args, session=session, **kwargs)
  File "/home/airflow/.local/lib/python3.8/site-packages/airflow/dag_processing/processor.py", line 859, in process_file
    serialize_errors = DagFileProcessor.save_dag_to_db(
  File "/home/airflow/.local/lib/python3.8/site-packages/airflow/api_internal/internal_api_call.py", line 114, in wrapper
    return func(*args, **kwargs)
  File "/home/airflow/.local/lib/python3.8/site-packages/airflow/utils/session.py", line 79, in wrapper
    return func(*args, session=session, **kwargs)
  File "/home/airflow/.local/lib/python3.8/site-packages/airflow/dag_processing/processor.py", line 895, in save_dag_to_db
    import_errors = DagBag._sync_to_db(dags=dags, processor_subdir=dag_directory, session=session)
  File "/home/airflow/.local/lib/python3.8/site-packages/airflow/utils/session.py", line 76, in wrapper
    return func(*args, **kwargs)
  File "/home/airflow/.local/lib/python3.8/site-packages/airflow/models/dagbag.py", line 659, in _sync_to_db
    for attempt in run_with_db_retries(logger=log):
  File "/home/airflow/.local/lib/python3.8/site-packages/tenacity/__init__.py", line 347, in __iter__
    do = self.iter(retry_state=retry_state)
  File "/home/airflow/.local/lib/python3.8/site-packages/tenacity/__init__.py", line 325, in iter
    raise retry_exc.reraise()
  File "/home/airflow/.local/lib/python3.8/site-packages/tenacity/__init__.py", line 158, in reraise
    raise self.last_attempt.result()
  File "/usr/local/lib/python3.8/concurrent/futures/_base.py", line 437, in result
    return self.__get_result()
  File "/usr/local/lib/python3.8/concurrent/futures/_base.py", line 389, in __get_result
    raise self._exception
  File "/home/airflow/.local/lib/python3.8/site-packages/airflow/models/dagbag.py", line 672, in _sync_to_db
    _serialize_dag_capturing_errors(dag, session, processor_subdir)
  File "/home/airflow/.local/lib/python3.8/site-packages/airflow/models/dagbag.py", line 637, in _serialize_dag_capturing_errors
    dag_was_updated = SerializedDagModel.write_dag(
  File "/home/airflow/.local/lib/python3.8/site-packages/airflow/utils/session.py", line 76, in wrapper
    return func(*args, **kwargs)
  File "/home/airflow/.local/lib/python3.8/site-packages/airflow/models/serialized_dag.py", line 157, in write_dag
    if session.scalar(
  File "/home/airflow/.local/lib/python3.8/site-packages/sqlalchemy/orm/session.py", line 1747, in scalar
    return self.execute(
  File "/home/airflow/.local/lib/python3.8/site-packages/sqlalchemy/orm/session.py", line 1716, in execute
    conn = self._connection_for_bind(bind)
  File "/home/airflow/.local/lib/python3.8/site-packages/sqlalchemy/orm/session.py", line 1555, in _connection_for_bind
    return self._transaction._connection_for_bind(
  File "/home/airflow/.local/lib/python3.8/site-packages/sqlalchemy/orm/session.py", line 750, in _connection_for_bind
    conn = bind.connect()
  File "/home/airflow/.local/lib/python3.8/site-packages/sqlalchemy/future/engine.py", line 412, in connect
    return super(Engine, self).connect()
  File "/home/airflow/.local/lib/python3.8/site-packages/sqlalchemy/engine/base.py", line 3325, in connect
    return self._connection_cls(self, close_with_result=close_with_result)
  File "/home/airflow/.local/lib/python3.8/site-packages/sqlalchemy/engine/base.py", line 96, in __init__
    else engine.raw_connection()
  File "/home/airflow/.local/lib/python3.8/site-packages/sqlalchemy/engine/base.py", line 3404, in raw_connection
    return self._wrap_pool_connect(self.pool.connect, _connection)
  File "/home/airflow/.local/lib/python3.8/site-packages/sqlalchemy/engine/base.py", line 3374, in _wrap_pool_connect
    Connection._handle_dbapi_exception_noconnection(
  File "/home/airflow/.local/lib/python3.8/site-packages/sqlalchemy/engine/base.py", line 2208, in _handle_dbapi_exception_noconnection
    util.raise_(
  File "/home/airflow/.local/lib/python3.8/site-packages/sqlalchemy/util/compat.py", line 211, in raise_
    raise exception
  File "/home/airflow/.local/lib/python3.8/site-packages/sqlalchemy/engine/base.py", line 3371, in _wrap_pool_connect
    return fn()
  File "/home/airflow/.local/lib/python3.8/site-packages/sqlalchemy/pool/base.py", line 327, in connect
    return _ConnectionFairy._checkout(self)
  File "/home/airflow/.local/lib/python3.8/site-packages/sqlalchemy/pool/base.py", line 894, in _checkout
    fairy = _ConnectionRecord.checkout(pool)
  File "/home/airflow/.local/lib/python3.8/site-packages/sqlalchemy/pool/base.py", line 493, in checkout
    rec = pool._do_get()
  File "/home/airflow/.local/lib/python3.8/site-packages/sqlalchemy/pool/impl.py", line 146, in _do_get
    self._dec_overflow()
  File "/home/airflow/.local/lib/python3.8/site-packages/sqlalchemy/util/langhelpers.py", line 70, in __exit__
    compat.raise_(
  File "/home/airflow/.local/lib/python3.8/site-packages/sqlalchemy/util/compat.py", line 211, in raise_
    raise exception
  File "/home/airflow/.local/lib/python3.8/site-packages/sqlalchemy/pool/impl.py", line 143, in _do_get
    return self._create_connection()
  File "/home/airflow/.local/lib/python3.8/site-packages/sqlalchemy/pool/base.py", line 273, in _create_connection
    return _ConnectionRecord(self)
  File "/home/airflow/.local/lib/python3.8/site-packages/sqlalchemy/pool/base.py", line 388, in __init__
    self.__connect()
  File "/home/airflow/.local/lib/python3.8/site-packages/sqlalchemy/pool/base.py", line 691, in __connect
    pool.logger.debug("Error on connect(): %s", e)
  File "/home/airflow/.local/lib/python3.8/site-packages/sqlalchemy/util/langhelpers.py", line 70, in __exit__
    compat.raise_(
  File "/home/airflow/.local/lib/python3.8/site-packages/sqlalchemy/util/compat.py", line 211, in raise_
    raise exception
  File "/home/airflow/.local/lib/python3.8/site-packages/sqlalchemy/pool/base.py", line 686, in __connect
    self.dbapi_connection = connection = pool._invoke_creator(self)
  File "/home/airflow/.local/lib/python3.8/site-packages/sqlalchemy/engine/create.py", line 574, in connect
    return dialect.connect(*cargs, **cparams)
  File "/home/airflow/.local/lib/python3.8/site-packages/sqlalchemy/engine/default.py", line 598, in connect
    return self.dbapi.connect(*cargs, **cparams)
  File "/home/airflow/.local/lib/python3.8/site-packages/psycopg2/__init__.py", line 122, in connect
    conn = _connect(dsn, connection_factory=connection_factory, **kwasync)
sqlalchemy.exc.OperationalError: (psycopg2.OperationalError) could not translate host name "db" to address: Temporary failure in name resolution

(Background on this error at: https://sqlalche.me/e/14/e3q8)
[2025-08-18T23:15:21.943+0000] {processor.py:161} INFO - Started process (PID=987) to work on /opt/airflow/dags/generate_data.py
[2025-08-18T23:15:21.945+0000] {processor.py:830} INFO - Processing file /opt/airflow/dags/generate_data.py for tasks to queue
[2025-08-18T23:15:21.958+0000] {logging_mixin.py:188} INFO - [2025-08-18T23:15:21.954+0000] {dagbag.py:540} INFO - Filling up the DagBag from /opt/airflow/dags/generate_data.py
[2025-08-18T23:15:24.702+0000] {processor.py:840} INFO - DAG(s) 'generate_data' retrieved from /opt/airflow/dags/generate_data.py
[2025-08-18T23:15:56.237+0000] {processor.py:186} ERROR - Got an exception! Propagating...
Traceback (most recent call last):
  File "/home/airflow/.local/lib/python3.8/site-packages/sqlalchemy/engine/base.py", line 3371, in _wrap_pool_connect
    return fn()
  File "/home/airflow/.local/lib/python3.8/site-packages/sqlalchemy/pool/base.py", line 327, in connect
    return _ConnectionFairy._checkout(self)
  File "/home/airflow/.local/lib/python3.8/site-packages/sqlalchemy/pool/base.py", line 894, in _checkout
    fairy = _ConnectionRecord.checkout(pool)
  File "/home/airflow/.local/lib/python3.8/site-packages/sqlalchemy/pool/base.py", line 493, in checkout
    rec = pool._do_get()
  File "/home/airflow/.local/lib/python3.8/site-packages/sqlalchemy/pool/impl.py", line 146, in _do_get
    self._dec_overflow()
  File "/home/airflow/.local/lib/python3.8/site-packages/sqlalchemy/util/langhelpers.py", line 70, in __exit__
    compat.raise_(
  File "/home/airflow/.local/lib/python3.8/site-packages/sqlalchemy/util/compat.py", line 211, in raise_
    raise exception
  File "/home/airflow/.local/lib/python3.8/site-packages/sqlalchemy/pool/impl.py", line 143, in _do_get
    return self._create_connection()
  File "/home/airflow/.local/lib/python3.8/site-packages/sqlalchemy/pool/base.py", line 273, in _create_connection
    return _ConnectionRecord(self)
  File "/home/airflow/.local/lib/python3.8/site-packages/sqlalchemy/pool/base.py", line 388, in __init__
    self.__connect()
  File "/home/airflow/.local/lib/python3.8/site-packages/sqlalchemy/pool/base.py", line 691, in __connect
    pool.logger.debug("Error on connect(): %s", e)
  File "/home/airflow/.local/lib/python3.8/site-packages/sqlalchemy/util/langhelpers.py", line 70, in __exit__
    compat.raise_(
  File "/home/airflow/.local/lib/python3.8/site-packages/sqlalchemy/util/compat.py", line 211, in raise_
    raise exception
  File "/home/airflow/.local/lib/python3.8/site-packages/sqlalchemy/pool/base.py", line 686, in __connect
    self.dbapi_connection = connection = pool._invoke_creator(self)
  File "/home/airflow/.local/lib/python3.8/site-packages/sqlalchemy/engine/create.py", line 574, in connect
    return dialect.connect(*cargs, **cparams)
  File "/home/airflow/.local/lib/python3.8/site-packages/sqlalchemy/engine/default.py", line 598, in connect
    return self.dbapi.connect(*cargs, **cparams)
  File "/home/airflow/.local/lib/python3.8/site-packages/psycopg2/__init__.py", line 122, in connect
    conn = _connect(dsn, connection_factory=connection_factory, **kwasync)
psycopg2.OperationalError: could not translate host name "db" to address: Temporary failure in name resolution


The above exception was the direct cause of the following exception:

Traceback (most recent call last):
  File "/home/airflow/.local/lib/python3.8/site-packages/airflow/dag_processing/processor.py", line 182, in _run_file_processor
    _handle_dag_file_processing()
  File "/home/airflow/.local/lib/python3.8/site-packages/airflow/dag_processing/processor.py", line 163, in _handle_dag_file_processing
    result: tuple[int, int] = dag_file_processor.process_file(
  File "/home/airflow/.local/lib/python3.8/site-packages/airflow/utils/session.py", line 79, in wrapper
    return func(*args, session=session, **kwargs)
  File "/home/airflow/.local/lib/python3.8/site-packages/airflow/dag_processing/processor.py", line 859, in process_file
    serialize_errors = DagFileProcessor.save_dag_to_db(
  File "/home/airflow/.local/lib/python3.8/site-packages/airflow/api_internal/internal_api_call.py", line 114, in wrapper
    return func(*args, **kwargs)
  File "/home/airflow/.local/lib/python3.8/site-packages/airflow/utils/session.py", line 79, in wrapper
    return func(*args, session=session, **kwargs)
  File "/home/airflow/.local/lib/python3.8/site-packages/airflow/dag_processing/processor.py", line 895, in save_dag_to_db
    import_errors = DagBag._sync_to_db(dags=dags, processor_subdir=dag_directory, session=session)
  File "/home/airflow/.local/lib/python3.8/site-packages/airflow/utils/session.py", line 76, in wrapper
    return func(*args, **kwargs)
  File "/home/airflow/.local/lib/python3.8/site-packages/airflow/models/dagbag.py", line 659, in _sync_to_db
    for attempt in run_with_db_retries(logger=log):
  File "/home/airflow/.local/lib/python3.8/site-packages/tenacity/__init__.py", line 347, in __iter__
    do = self.iter(retry_state=retry_state)
  File "/home/airflow/.local/lib/python3.8/site-packages/tenacity/__init__.py", line 325, in iter
    raise retry_exc.reraise()
  File "/home/airflow/.local/lib/python3.8/site-packages/tenacity/__init__.py", line 158, in reraise
    raise self.last_attempt.result()
  File "/usr/local/lib/python3.8/concurrent/futures/_base.py", line 437, in result
    return self.__get_result()
  File "/usr/local/lib/python3.8/concurrent/futures/_base.py", line 389, in __get_result
    raise self._exception
  File "/home/airflow/.local/lib/python3.8/site-packages/airflow/models/dagbag.py", line 672, in _sync_to_db
    _serialize_dag_capturing_errors(dag, session, processor_subdir)
  File "/home/airflow/.local/lib/python3.8/site-packages/airflow/models/dagbag.py", line 637, in _serialize_dag_capturing_errors
    dag_was_updated = SerializedDagModel.write_dag(
  File "/home/airflow/.local/lib/python3.8/site-packages/airflow/utils/session.py", line 76, in wrapper
    return func(*args, **kwargs)
  File "/home/airflow/.local/lib/python3.8/site-packages/airflow/models/serialized_dag.py", line 157, in write_dag
    if session.scalar(
  File "/home/airflow/.local/lib/python3.8/site-packages/sqlalchemy/orm/session.py", line 1747, in scalar
    return self.execute(
  File "/home/airflow/.local/lib/python3.8/site-packages/sqlalchemy/orm/session.py", line 1716, in execute
    conn = self._connection_for_bind(bind)
  File "/home/airflow/.local/lib/python3.8/site-packages/sqlalchemy/orm/session.py", line 1555, in _connection_for_bind
    return self._transaction._connection_for_bind(
  File "/home/airflow/.local/lib/python3.8/site-packages/sqlalchemy/orm/session.py", line 750, in _connection_for_bind
    conn = bind.connect()
  File "/home/airflow/.local/lib/python3.8/site-packages/sqlalchemy/future/engine.py", line 412, in connect
    return super(Engine, self).connect()
  File "/home/airflow/.local/lib/python3.8/site-packages/sqlalchemy/engine/base.py", line 3325, in connect
    return self._connection_cls(self, close_with_result=close_with_result)
  File "/home/airflow/.local/lib/python3.8/site-packages/sqlalchemy/engine/base.py", line 96, in __init__
    else engine.raw_connection()
  File "/home/airflow/.local/lib/python3.8/site-packages/sqlalchemy/engine/base.py", line 3404, in raw_connection
    return self._wrap_pool_connect(self.pool.connect, _connection)
  File "/home/airflow/.local/lib/python3.8/site-packages/sqlalchemy/engine/base.py", line 3374, in _wrap_pool_connect
    Connection._handle_dbapi_exception_noconnection(
  File "/home/airflow/.local/lib/python3.8/site-packages/sqlalchemy/engine/base.py", line 2208, in _handle_dbapi_exception_noconnection
    util.raise_(
  File "/home/airflow/.local/lib/python3.8/site-packages/sqlalchemy/util/compat.py", line 211, in raise_
    raise exception
  File "/home/airflow/.local/lib/python3.8/site-packages/sqlalchemy/engine/base.py", line 3371, in _wrap_pool_connect
    return fn()
  File "/home/airflow/.local/lib/python3.8/site-packages/sqlalchemy/pool/base.py", line 327, in connect
    return _ConnectionFairy._checkout(self)
  File "/home/airflow/.local/lib/python3.8/site-packages/sqlalchemy/pool/base.py", line 894, in _checkout
    fairy = _ConnectionRecord.checkout(pool)
  File "/home/airflow/.local/lib/python3.8/site-packages/sqlalchemy/pool/base.py", line 493, in checkout
    rec = pool._do_get()
  File "/home/airflow/.local/lib/python3.8/site-packages/sqlalchemy/pool/impl.py", line 146, in _do_get
    self._dec_overflow()
  File "/home/airflow/.local/lib/python3.8/site-packages/sqlalchemy/util/langhelpers.py", line 70, in __exit__
    compat.raise_(
  File "/home/airflow/.local/lib/python3.8/site-packages/sqlalchemy/util/compat.py", line 211, in raise_
    raise exception
  File "/home/airflow/.local/lib/python3.8/site-packages/sqlalchemy/pool/impl.py", line 143, in _do_get
    return self._create_connection()
  File "/home/airflow/.local/lib/python3.8/site-packages/sqlalchemy/pool/base.py", line 273, in _create_connection
    return _ConnectionRecord(self)
  File "/home/airflow/.local/lib/python3.8/site-packages/sqlalchemy/pool/base.py", line 388, in __init__
    self.__connect()
  File "/home/airflow/.local/lib/python3.8/site-packages/sqlalchemy/pool/base.py", line 691, in __connect
    pool.logger.debug("Error on connect(): %s", e)
  File "/home/airflow/.local/lib/python3.8/site-packages/sqlalchemy/util/langhelpers.py", line 70, in __exit__
    compat.raise_(
  File "/home/airflow/.local/lib/python3.8/site-packages/sqlalchemy/util/compat.py", line 211, in raise_
    raise exception
  File "/home/airflow/.local/lib/python3.8/site-packages/sqlalchemy/pool/base.py", line 686, in __connect
    self.dbapi_connection = connection = pool._invoke_creator(self)
  File "/home/airflow/.local/lib/python3.8/site-packages/sqlalchemy/engine/create.py", line 574, in connect
    return dialect.connect(*cargs, **cparams)
  File "/home/airflow/.local/lib/python3.8/site-packages/sqlalchemy/engine/default.py", line 598, in connect
    return self.dbapi.connect(*cargs, **cparams)
  File "/home/airflow/.local/lib/python3.8/site-packages/psycopg2/__init__.py", line 122, in connect
    conn = _connect(dsn, connection_factory=connection_factory, **kwasync)
sqlalchemy.exc.OperationalError: (psycopg2.OperationalError) could not translate host name "db" to address: Temporary failure in name resolution

(Background on this error at: https://sqlalche.me/e/14/e3q8)
[2025-08-18T23:16:31.977+0000] {processor.py:161} INFO - Started process (PID=992) to work on /opt/airflow/dags/generate_data.py
[2025-08-18T23:16:31.981+0000] {processor.py:830} INFO - Processing file /opt/airflow/dags/generate_data.py for tasks to queue
[2025-08-18T23:16:31.990+0000] {logging_mixin.py:188} INFO - [2025-08-18T23:16:31.986+0000] {dagbag.py:540} INFO - Filling up the DagBag from /opt/airflow/dags/generate_data.py
[2025-08-18T23:17:13.823+0000] {logging_mixin.py:188} INFO - [2025-08-18T23:17:03.428+0000] {timeout.py:68} ERROR - Process timed out, PID: 992
[2025-08-18T23:20:42.100+0000] {processor.py:161} INFO - Started process (PID=997) to work on /opt/airflow/dags/generate_data.py
[2025-08-18T23:20:42.103+0000] {processor.py:830} INFO - Processing file /opt/airflow/dags/generate_data.py for tasks to queue
[2025-08-18T23:20:42.111+0000] {logging_mixin.py:188} INFO - [2025-08-18T23:20:42.106+0000] {dagbag.py:540} INFO - Filling up the DagBag from /opt/airflow/dags/generate_data.py
[2025-08-18T23:20:42.911+0000] {processor.py:840} INFO - DAG(s) 'generate_data' retrieved from /opt/airflow/dags/generate_data.py
[2025-08-18T23:20:44.133+0000] {processor.py:186} ERROR - Got an exception! Propagating...
Traceback (most recent call last):
  File "/home/airflow/.local/lib/python3.8/site-packages/sqlalchemy/engine/base.py", line 3371, in _wrap_pool_connect
    return fn()
  File "/home/airflow/.local/lib/python3.8/site-packages/sqlalchemy/pool/base.py", line 327, in connect
    return _ConnectionFairy._checkout(self)
  File "/home/airflow/.local/lib/python3.8/site-packages/sqlalchemy/pool/base.py", line 894, in _checkout
    fairy = _ConnectionRecord.checkout(pool)
  File "/home/airflow/.local/lib/python3.8/site-packages/sqlalchemy/pool/base.py", line 493, in checkout
    rec = pool._do_get()
  File "/home/airflow/.local/lib/python3.8/site-packages/sqlalchemy/pool/impl.py", line 146, in _do_get
    self._dec_overflow()
  File "/home/airflow/.local/lib/python3.8/site-packages/sqlalchemy/util/langhelpers.py", line 70, in __exit__
    compat.raise_(
  File "/home/airflow/.local/lib/python3.8/site-packages/sqlalchemy/util/compat.py", line 211, in raise_
    raise exception
  File "/home/airflow/.local/lib/python3.8/site-packages/sqlalchemy/pool/impl.py", line 143, in _do_get
    return self._create_connection()
  File "/home/airflow/.local/lib/python3.8/site-packages/sqlalchemy/pool/base.py", line 273, in _create_connection
    return _ConnectionRecord(self)
  File "/home/airflow/.local/lib/python3.8/site-packages/sqlalchemy/pool/base.py", line 388, in __init__
    self.__connect()
  File "/home/airflow/.local/lib/python3.8/site-packages/sqlalchemy/pool/base.py", line 691, in __connect
    pool.logger.debug("Error on connect(): %s", e)
  File "/home/airflow/.local/lib/python3.8/site-packages/sqlalchemy/util/langhelpers.py", line 70, in __exit__
    compat.raise_(
  File "/home/airflow/.local/lib/python3.8/site-packages/sqlalchemy/util/compat.py", line 211, in raise_
    raise exception
  File "/home/airflow/.local/lib/python3.8/site-packages/sqlalchemy/pool/base.py", line 686, in __connect
    self.dbapi_connection = connection = pool._invoke_creator(self)
  File "/home/airflow/.local/lib/python3.8/site-packages/sqlalchemy/engine/create.py", line 574, in connect
    return dialect.connect(*cargs, **cparams)
  File "/home/airflow/.local/lib/python3.8/site-packages/sqlalchemy/engine/default.py", line 598, in connect
    return self.dbapi.connect(*cargs, **cparams)
  File "/home/airflow/.local/lib/python3.8/site-packages/psycopg2/__init__.py", line 122, in connect
    conn = _connect(dsn, connection_factory=connection_factory, **kwasync)
psycopg2.OperationalError: could not translate host name "db" to address: Temporary failure in name resolution


The above exception was the direct cause of the following exception:

Traceback (most recent call last):
  File "/home/airflow/.local/lib/python3.8/site-packages/airflow/dag_processing/processor.py", line 182, in _run_file_processor
    _handle_dag_file_processing()
  File "/home/airflow/.local/lib/python3.8/site-packages/airflow/dag_processing/processor.py", line 163, in _handle_dag_file_processing
    result: tuple[int, int] = dag_file_processor.process_file(
  File "/home/airflow/.local/lib/python3.8/site-packages/airflow/utils/session.py", line 79, in wrapper
    return func(*args, session=session, **kwargs)
  File "/home/airflow/.local/lib/python3.8/site-packages/airflow/dag_processing/processor.py", line 859, in process_file
    serialize_errors = DagFileProcessor.save_dag_to_db(
  File "/home/airflow/.local/lib/python3.8/site-packages/airflow/api_internal/internal_api_call.py", line 114, in wrapper
    return func(*args, **kwargs)
  File "/home/airflow/.local/lib/python3.8/site-packages/airflow/utils/session.py", line 79, in wrapper
    return func(*args, session=session, **kwargs)
  File "/home/airflow/.local/lib/python3.8/site-packages/airflow/dag_processing/processor.py", line 895, in save_dag_to_db
    import_errors = DagBag._sync_to_db(dags=dags, processor_subdir=dag_directory, session=session)
  File "/home/airflow/.local/lib/python3.8/site-packages/airflow/utils/session.py", line 76, in wrapper
    return func(*args, **kwargs)
  File "/home/airflow/.local/lib/python3.8/site-packages/airflow/models/dagbag.py", line 659, in _sync_to_db
    for attempt in run_with_db_retries(logger=log):
  File "/home/airflow/.local/lib/python3.8/site-packages/tenacity/__init__.py", line 347, in __iter__
    do = self.iter(retry_state=retry_state)
  File "/home/airflow/.local/lib/python3.8/site-packages/tenacity/__init__.py", line 325, in iter
    raise retry_exc.reraise()
  File "/home/airflow/.local/lib/python3.8/site-packages/tenacity/__init__.py", line 158, in reraise
    raise self.last_attempt.result()
  File "/usr/local/lib/python3.8/concurrent/futures/_base.py", line 437, in result
    return self.__get_result()
  File "/usr/local/lib/python3.8/concurrent/futures/_base.py", line 389, in __get_result
    raise self._exception
  File "/home/airflow/.local/lib/python3.8/site-packages/airflow/models/dagbag.py", line 672, in _sync_to_db
    _serialize_dag_capturing_errors(dag, session, processor_subdir)
  File "/home/airflow/.local/lib/python3.8/site-packages/airflow/models/dagbag.py", line 637, in _serialize_dag_capturing_errors
    dag_was_updated = SerializedDagModel.write_dag(
  File "/home/airflow/.local/lib/python3.8/site-packages/airflow/utils/session.py", line 76, in wrapper
    return func(*args, **kwargs)
  File "/home/airflow/.local/lib/python3.8/site-packages/airflow/models/serialized_dag.py", line 157, in write_dag
    if session.scalar(
  File "/home/airflow/.local/lib/python3.8/site-packages/sqlalchemy/orm/session.py", line 1747, in scalar
    return self.execute(
  File "/home/airflow/.local/lib/python3.8/site-packages/sqlalchemy/orm/session.py", line 1716, in execute
    conn = self._connection_for_bind(bind)
  File "/home/airflow/.local/lib/python3.8/site-packages/sqlalchemy/orm/session.py", line 1555, in _connection_for_bind
    return self._transaction._connection_for_bind(
  File "/home/airflow/.local/lib/python3.8/site-packages/sqlalchemy/orm/session.py", line 750, in _connection_for_bind
    conn = bind.connect()
  File "/home/airflow/.local/lib/python3.8/site-packages/sqlalchemy/future/engine.py", line 412, in connect
    return super(Engine, self).connect()
  File "/home/airflow/.local/lib/python3.8/site-packages/sqlalchemy/engine/base.py", line 3325, in connect
    return self._connection_cls(self, close_with_result=close_with_result)
  File "/home/airflow/.local/lib/python3.8/site-packages/sqlalchemy/engine/base.py", line 96, in __init__
    else engine.raw_connection()
  File "/home/airflow/.local/lib/python3.8/site-packages/sqlalchemy/engine/base.py", line 3404, in raw_connection
    return self._wrap_pool_connect(self.pool.connect, _connection)
  File "/home/airflow/.local/lib/python3.8/site-packages/sqlalchemy/engine/base.py", line 3374, in _wrap_pool_connect
    Connection._handle_dbapi_exception_noconnection(
  File "/home/airflow/.local/lib/python3.8/site-packages/sqlalchemy/engine/base.py", line 2208, in _handle_dbapi_exception_noconnection
    util.raise_(
  File "/home/airflow/.local/lib/python3.8/site-packages/sqlalchemy/util/compat.py", line 211, in raise_
    raise exception
  File "/home/airflow/.local/lib/python3.8/site-packages/sqlalchemy/engine/base.py", line 3371, in _wrap_pool_connect
    return fn()
  File "/home/airflow/.local/lib/python3.8/site-packages/sqlalchemy/pool/base.py", line 327, in connect
    return _ConnectionFairy._checkout(self)
  File "/home/airflow/.local/lib/python3.8/site-packages/sqlalchemy/pool/base.py", line 894, in _checkout
    fairy = _ConnectionRecord.checkout(pool)
  File "/home/airflow/.local/lib/python3.8/site-packages/sqlalchemy/pool/base.py", line 493, in checkout
    rec = pool._do_get()
  File "/home/airflow/.local/lib/python3.8/site-packages/sqlalchemy/pool/impl.py", line 146, in _do_get
    self._dec_overflow()
  File "/home/airflow/.local/lib/python3.8/site-packages/sqlalchemy/util/langhelpers.py", line 70, in __exit__
    compat.raise_(
  File "/home/airflow/.local/lib/python3.8/site-packages/sqlalchemy/util/compat.py", line 211, in raise_
    raise exception
  File "/home/airflow/.local/lib/python3.8/site-packages/sqlalchemy/pool/impl.py", line 143, in _do_get
    return self._create_connection()
  File "/home/airflow/.local/lib/python3.8/site-packages/sqlalchemy/pool/base.py", line 273, in _create_connection
    return _ConnectionRecord(self)
  File "/home/airflow/.local/lib/python3.8/site-packages/sqlalchemy/pool/base.py", line 388, in __init__
    self.__connect()
  File "/home/airflow/.local/lib/python3.8/site-packages/sqlalchemy/pool/base.py", line 691, in __connect
    pool.logger.debug("Error on connect(): %s", e)
  File "/home/airflow/.local/lib/python3.8/site-packages/sqlalchemy/util/langhelpers.py", line 70, in __exit__
    compat.raise_(
  File "/home/airflow/.local/lib/python3.8/site-packages/sqlalchemy/util/compat.py", line 211, in raise_
    raise exception
  File "/home/airflow/.local/lib/python3.8/site-packages/sqlalchemy/pool/base.py", line 686, in __connect
    self.dbapi_connection = connection = pool._invoke_creator(self)
  File "/home/airflow/.local/lib/python3.8/site-packages/sqlalchemy/engine/create.py", line 574, in connect
    return dialect.connect(*cargs, **cparams)
  File "/home/airflow/.local/lib/python3.8/site-packages/sqlalchemy/engine/default.py", line 598, in connect
    return self.dbapi.connect(*cargs, **cparams)
  File "/home/airflow/.local/lib/python3.8/site-packages/psycopg2/__init__.py", line 122, in connect
    conn = _connect(dsn, connection_factory=connection_factory, **kwasync)
sqlalchemy.exc.OperationalError: (psycopg2.OperationalError) could not translate host name "db" to address: Temporary failure in name resolution

(Background on this error at: https://sqlalche.me/e/14/e3q8)
[2025-08-18T23:21:14.480+0000] {processor.py:161} INFO - Started process (PID=1002) to work on /opt/airflow/dags/generate_data.py
[2025-08-18T23:21:14.482+0000] {processor.py:830} INFO - Processing file /opt/airflow/dags/generate_data.py for tasks to queue
[2025-08-18T23:21:14.485+0000] {logging_mixin.py:188} INFO - [2025-08-18T23:21:14.484+0000] {dagbag.py:540} INFO - Filling up the DagBag from /opt/airflow/dags/generate_data.py
[2025-08-18T23:21:14.846+0000] {processor.py:840} INFO - DAG(s) 'generate_data' retrieved from /opt/airflow/dags/generate_data.py
[2025-08-18T23:21:15.472+0000] {processor.py:186} ERROR - Got an exception! Propagating...
Traceback (most recent call last):
  File "/home/airflow/.local/lib/python3.8/site-packages/sqlalchemy/engine/base.py", line 3371, in _wrap_pool_connect
    return fn()
  File "/home/airflow/.local/lib/python3.8/site-packages/sqlalchemy/pool/base.py", line 327, in connect
    return _ConnectionFairy._checkout(self)
  File "/home/airflow/.local/lib/python3.8/site-packages/sqlalchemy/pool/base.py", line 894, in _checkout
    fairy = _ConnectionRecord.checkout(pool)
  File "/home/airflow/.local/lib/python3.8/site-packages/sqlalchemy/pool/base.py", line 493, in checkout
    rec = pool._do_get()
  File "/home/airflow/.local/lib/python3.8/site-packages/sqlalchemy/pool/impl.py", line 146, in _do_get
    self._dec_overflow()
  File "/home/airflow/.local/lib/python3.8/site-packages/sqlalchemy/util/langhelpers.py", line 70, in __exit__
    compat.raise_(
  File "/home/airflow/.local/lib/python3.8/site-packages/sqlalchemy/util/compat.py", line 211, in raise_
    raise exception
  File "/home/airflow/.local/lib/python3.8/site-packages/sqlalchemy/pool/impl.py", line 143, in _do_get
    return self._create_connection()
  File "/home/airflow/.local/lib/python3.8/site-packages/sqlalchemy/pool/base.py", line 273, in _create_connection
    return _ConnectionRecord(self)
  File "/home/airflow/.local/lib/python3.8/site-packages/sqlalchemy/pool/base.py", line 388, in __init__
    self.__connect()
  File "/home/airflow/.local/lib/python3.8/site-packages/sqlalchemy/pool/base.py", line 691, in __connect
    pool.logger.debug("Error on connect(): %s", e)
  File "/home/airflow/.local/lib/python3.8/site-packages/sqlalchemy/util/langhelpers.py", line 70, in __exit__
    compat.raise_(
  File "/home/airflow/.local/lib/python3.8/site-packages/sqlalchemy/util/compat.py", line 211, in raise_
    raise exception
  File "/home/airflow/.local/lib/python3.8/site-packages/sqlalchemy/pool/base.py", line 686, in __connect
    self.dbapi_connection = connection = pool._invoke_creator(self)
  File "/home/airflow/.local/lib/python3.8/site-packages/sqlalchemy/engine/create.py", line 574, in connect
    return dialect.connect(*cargs, **cparams)
  File "/home/airflow/.local/lib/python3.8/site-packages/sqlalchemy/engine/default.py", line 598, in connect
    return self.dbapi.connect(*cargs, **cparams)
  File "/home/airflow/.local/lib/python3.8/site-packages/psycopg2/__init__.py", line 122, in connect
    conn = _connect(dsn, connection_factory=connection_factory, **kwasync)
psycopg2.OperationalError: could not translate host name "db" to address: Temporary failure in name resolution


The above exception was the direct cause of the following exception:

Traceback (most recent call last):
  File "/home/airflow/.local/lib/python3.8/site-packages/airflow/dag_processing/processor.py", line 182, in _run_file_processor
    _handle_dag_file_processing()
  File "/home/airflow/.local/lib/python3.8/site-packages/airflow/dag_processing/processor.py", line 163, in _handle_dag_file_processing
    result: tuple[int, int] = dag_file_processor.process_file(
  File "/home/airflow/.local/lib/python3.8/site-packages/airflow/utils/session.py", line 79, in wrapper
    return func(*args, session=session, **kwargs)
  File "/home/airflow/.local/lib/python3.8/site-packages/airflow/dag_processing/processor.py", line 859, in process_file
    serialize_errors = DagFileProcessor.save_dag_to_db(
  File "/home/airflow/.local/lib/python3.8/site-packages/airflow/api_internal/internal_api_call.py", line 114, in wrapper
    return func(*args, **kwargs)
  File "/home/airflow/.local/lib/python3.8/site-packages/airflow/utils/session.py", line 79, in wrapper
    return func(*args, session=session, **kwargs)
  File "/home/airflow/.local/lib/python3.8/site-packages/airflow/dag_processing/processor.py", line 895, in save_dag_to_db
    import_errors = DagBag._sync_to_db(dags=dags, processor_subdir=dag_directory, session=session)
  File "/home/airflow/.local/lib/python3.8/site-packages/airflow/utils/session.py", line 76, in wrapper
    return func(*args, **kwargs)
  File "/home/airflow/.local/lib/python3.8/site-packages/airflow/models/dagbag.py", line 659, in _sync_to_db
    for attempt in run_with_db_retries(logger=log):
  File "/home/airflow/.local/lib/python3.8/site-packages/tenacity/__init__.py", line 347, in __iter__
    do = self.iter(retry_state=retry_state)
  File "/home/airflow/.local/lib/python3.8/site-packages/tenacity/__init__.py", line 325, in iter
    raise retry_exc.reraise()
  File "/home/airflow/.local/lib/python3.8/site-packages/tenacity/__init__.py", line 158, in reraise
    raise self.last_attempt.result()
  File "/usr/local/lib/python3.8/concurrent/futures/_base.py", line 437, in result
    return self.__get_result()
  File "/usr/local/lib/python3.8/concurrent/futures/_base.py", line 389, in __get_result
    raise self._exception
  File "/home/airflow/.local/lib/python3.8/site-packages/airflow/models/dagbag.py", line 672, in _sync_to_db
    _serialize_dag_capturing_errors(dag, session, processor_subdir)
  File "/home/airflow/.local/lib/python3.8/site-packages/airflow/models/dagbag.py", line 637, in _serialize_dag_capturing_errors
    dag_was_updated = SerializedDagModel.write_dag(
  File "/home/airflow/.local/lib/python3.8/site-packages/airflow/utils/session.py", line 76, in wrapper
    return func(*args, **kwargs)
  File "/home/airflow/.local/lib/python3.8/site-packages/airflow/models/serialized_dag.py", line 157, in write_dag
    if session.scalar(
  File "/home/airflow/.local/lib/python3.8/site-packages/sqlalchemy/orm/session.py", line 1747, in scalar
    return self.execute(
  File "/home/airflow/.local/lib/python3.8/site-packages/sqlalchemy/orm/session.py", line 1716, in execute
    conn = self._connection_for_bind(bind)
  File "/home/airflow/.local/lib/python3.8/site-packages/sqlalchemy/orm/session.py", line 1555, in _connection_for_bind
    return self._transaction._connection_for_bind(
  File "/home/airflow/.local/lib/python3.8/site-packages/sqlalchemy/orm/session.py", line 750, in _connection_for_bind
    conn = bind.connect()
  File "/home/airflow/.local/lib/python3.8/site-packages/sqlalchemy/future/engine.py", line 412, in connect
    return super(Engine, self).connect()
  File "/home/airflow/.local/lib/python3.8/site-packages/sqlalchemy/engine/base.py", line 3325, in connect
    return self._connection_cls(self, close_with_result=close_with_result)
  File "/home/airflow/.local/lib/python3.8/site-packages/sqlalchemy/engine/base.py", line 96, in __init__
    else engine.raw_connection()
  File "/home/airflow/.local/lib/python3.8/site-packages/sqlalchemy/engine/base.py", line 3404, in raw_connection
    return self._wrap_pool_connect(self.pool.connect, _connection)
  File "/home/airflow/.local/lib/python3.8/site-packages/sqlalchemy/engine/base.py", line 3374, in _wrap_pool_connect
    Connection._handle_dbapi_exception_noconnection(
  File "/home/airflow/.local/lib/python3.8/site-packages/sqlalchemy/engine/base.py", line 2208, in _handle_dbapi_exception_noconnection
    util.raise_(
  File "/home/airflow/.local/lib/python3.8/site-packages/sqlalchemy/util/compat.py", line 211, in raise_
    raise exception
  File "/home/airflow/.local/lib/python3.8/site-packages/sqlalchemy/engine/base.py", line 3371, in _wrap_pool_connect
    return fn()
  File "/home/airflow/.local/lib/python3.8/site-packages/sqlalchemy/pool/base.py", line 327, in connect
    return _ConnectionFairy._checkout(self)
  File "/home/airflow/.local/lib/python3.8/site-packages/sqlalchemy/pool/base.py", line 894, in _checkout
    fairy = _ConnectionRecord.checkout(pool)
  File "/home/airflow/.local/lib/python3.8/site-packages/sqlalchemy/pool/base.py", line 493, in checkout
    rec = pool._do_get()
  File "/home/airflow/.local/lib/python3.8/site-packages/sqlalchemy/pool/impl.py", line 146, in _do_get
    self._dec_overflow()
  File "/home/airflow/.local/lib/python3.8/site-packages/sqlalchemy/util/langhelpers.py", line 70, in __exit__
    compat.raise_(
  File "/home/airflow/.local/lib/python3.8/site-packages/sqlalchemy/util/compat.py", line 211, in raise_
    raise exception
  File "/home/airflow/.local/lib/python3.8/site-packages/sqlalchemy/pool/impl.py", line 143, in _do_get
    return self._create_connection()
  File "/home/airflow/.local/lib/python3.8/site-packages/sqlalchemy/pool/base.py", line 273, in _create_connection
    return _ConnectionRecord(self)
  File "/home/airflow/.local/lib/python3.8/site-packages/sqlalchemy/pool/base.py", line 388, in __init__
    self.__connect()
  File "/home/airflow/.local/lib/python3.8/site-packages/sqlalchemy/pool/base.py", line 691, in __connect
    pool.logger.debug("Error on connect(): %s", e)
  File "/home/airflow/.local/lib/python3.8/site-packages/sqlalchemy/util/langhelpers.py", line 70, in __exit__
    compat.raise_(
  File "/home/airflow/.local/lib/python3.8/site-packages/sqlalchemy/util/compat.py", line 211, in raise_
    raise exception
  File "/home/airflow/.local/lib/python3.8/site-packages/sqlalchemy/pool/base.py", line 686, in __connect
    self.dbapi_connection = connection = pool._invoke_creator(self)
  File "/home/airflow/.local/lib/python3.8/site-packages/sqlalchemy/engine/create.py", line 574, in connect
    return dialect.connect(*cargs, **cparams)
  File "/home/airflow/.local/lib/python3.8/site-packages/sqlalchemy/engine/default.py", line 598, in connect
    return self.dbapi.connect(*cargs, **cparams)
  File "/home/airflow/.local/lib/python3.8/site-packages/psycopg2/__init__.py", line 122, in connect
    conn = _connect(dsn, connection_factory=connection_factory, **kwasync)
sqlalchemy.exc.OperationalError: (psycopg2.OperationalError) could not translate host name "db" to address: Temporary failure in name resolution

(Background on this error at: https://sqlalche.me/e/14/e3q8)
[2025-08-18T23:21:45.836+0000] {processor.py:161} INFO - Started process (PID=1007) to work on /opt/airflow/dags/generate_data.py
[2025-08-18T23:21:45.838+0000] {processor.py:830} INFO - Processing file /opt/airflow/dags/generate_data.py for tasks to queue
[2025-08-18T23:21:45.840+0000] {logging_mixin.py:188} INFO - [2025-08-18T23:21:45.839+0000] {dagbag.py:540} INFO - Filling up the DagBag from /opt/airflow/dags/generate_data.py
[2025-08-18T23:21:46.221+0000] {processor.py:840} INFO - DAG(s) 'generate_data' retrieved from /opt/airflow/dags/generate_data.py
[2025-08-18T23:21:47.439+0000] {processor.py:186} ERROR - Got an exception! Propagating...
Traceback (most recent call last):
  File "/home/airflow/.local/lib/python3.8/site-packages/sqlalchemy/engine/base.py", line 3371, in _wrap_pool_connect
    return fn()
  File "/home/airflow/.local/lib/python3.8/site-packages/sqlalchemy/pool/base.py", line 327, in connect
    return _ConnectionFairy._checkout(self)
  File "/home/airflow/.local/lib/python3.8/site-packages/sqlalchemy/pool/base.py", line 894, in _checkout
    fairy = _ConnectionRecord.checkout(pool)
  File "/home/airflow/.local/lib/python3.8/site-packages/sqlalchemy/pool/base.py", line 493, in checkout
    rec = pool._do_get()
  File "/home/airflow/.local/lib/python3.8/site-packages/sqlalchemy/pool/impl.py", line 146, in _do_get
    self._dec_overflow()
  File "/home/airflow/.local/lib/python3.8/site-packages/sqlalchemy/util/langhelpers.py", line 70, in __exit__
    compat.raise_(
  File "/home/airflow/.local/lib/python3.8/site-packages/sqlalchemy/util/compat.py", line 211, in raise_
    raise exception
  File "/home/airflow/.local/lib/python3.8/site-packages/sqlalchemy/pool/impl.py", line 143, in _do_get
    return self._create_connection()
  File "/home/airflow/.local/lib/python3.8/site-packages/sqlalchemy/pool/base.py", line 273, in _create_connection
    return _ConnectionRecord(self)
  File "/home/airflow/.local/lib/python3.8/site-packages/sqlalchemy/pool/base.py", line 388, in __init__
    self.__connect()
  File "/home/airflow/.local/lib/python3.8/site-packages/sqlalchemy/pool/base.py", line 691, in __connect
    pool.logger.debug("Error on connect(): %s", e)
  File "/home/airflow/.local/lib/python3.8/site-packages/sqlalchemy/util/langhelpers.py", line 70, in __exit__
    compat.raise_(
  File "/home/airflow/.local/lib/python3.8/site-packages/sqlalchemy/util/compat.py", line 211, in raise_
    raise exception
  File "/home/airflow/.local/lib/python3.8/site-packages/sqlalchemy/pool/base.py", line 686, in __connect
    self.dbapi_connection = connection = pool._invoke_creator(self)
  File "/home/airflow/.local/lib/python3.8/site-packages/sqlalchemy/engine/create.py", line 574, in connect
    return dialect.connect(*cargs, **cparams)
  File "/home/airflow/.local/lib/python3.8/site-packages/sqlalchemy/engine/default.py", line 598, in connect
    return self.dbapi.connect(*cargs, **cparams)
  File "/home/airflow/.local/lib/python3.8/site-packages/psycopg2/__init__.py", line 122, in connect
    conn = _connect(dsn, connection_factory=connection_factory, **kwasync)
psycopg2.OperationalError: could not translate host name "db" to address: Temporary failure in name resolution


The above exception was the direct cause of the following exception:

Traceback (most recent call last):
  File "/home/airflow/.local/lib/python3.8/site-packages/airflow/dag_processing/processor.py", line 182, in _run_file_processor
    _handle_dag_file_processing()
  File "/home/airflow/.local/lib/python3.8/site-packages/airflow/dag_processing/processor.py", line 163, in _handle_dag_file_processing
    result: tuple[int, int] = dag_file_processor.process_file(
  File "/home/airflow/.local/lib/python3.8/site-packages/airflow/utils/session.py", line 79, in wrapper
    return func(*args, session=session, **kwargs)
  File "/home/airflow/.local/lib/python3.8/site-packages/airflow/dag_processing/processor.py", line 859, in process_file
    serialize_errors = DagFileProcessor.save_dag_to_db(
  File "/home/airflow/.local/lib/python3.8/site-packages/airflow/api_internal/internal_api_call.py", line 114, in wrapper
    return func(*args, **kwargs)
  File "/home/airflow/.local/lib/python3.8/site-packages/airflow/utils/session.py", line 79, in wrapper
    return func(*args, session=session, **kwargs)
  File "/home/airflow/.local/lib/python3.8/site-packages/airflow/dag_processing/processor.py", line 895, in save_dag_to_db
    import_errors = DagBag._sync_to_db(dags=dags, processor_subdir=dag_directory, session=session)
  File "/home/airflow/.local/lib/python3.8/site-packages/airflow/utils/session.py", line 76, in wrapper
    return func(*args, **kwargs)
  File "/home/airflow/.local/lib/python3.8/site-packages/airflow/models/dagbag.py", line 659, in _sync_to_db
    for attempt in run_with_db_retries(logger=log):
  File "/home/airflow/.local/lib/python3.8/site-packages/tenacity/__init__.py", line 347, in __iter__
    do = self.iter(retry_state=retry_state)
  File "/home/airflow/.local/lib/python3.8/site-packages/tenacity/__init__.py", line 325, in iter
    raise retry_exc.reraise()
  File "/home/airflow/.local/lib/python3.8/site-packages/tenacity/__init__.py", line 158, in reraise
    raise self.last_attempt.result()
  File "/usr/local/lib/python3.8/concurrent/futures/_base.py", line 437, in result
    return self.__get_result()
  File "/usr/local/lib/python3.8/concurrent/futures/_base.py", line 389, in __get_result
    raise self._exception
  File "/home/airflow/.local/lib/python3.8/site-packages/airflow/models/dagbag.py", line 672, in _sync_to_db
    _serialize_dag_capturing_errors(dag, session, processor_subdir)
  File "/home/airflow/.local/lib/python3.8/site-packages/airflow/models/dagbag.py", line 637, in _serialize_dag_capturing_errors
    dag_was_updated = SerializedDagModel.write_dag(
  File "/home/airflow/.local/lib/python3.8/site-packages/airflow/utils/session.py", line 76, in wrapper
    return func(*args, **kwargs)
  File "/home/airflow/.local/lib/python3.8/site-packages/airflow/models/serialized_dag.py", line 157, in write_dag
    if session.scalar(
  File "/home/airflow/.local/lib/python3.8/site-packages/sqlalchemy/orm/session.py", line 1747, in scalar
    return self.execute(
  File "/home/airflow/.local/lib/python3.8/site-packages/sqlalchemy/orm/session.py", line 1716, in execute
    conn = self._connection_for_bind(bind)
  File "/home/airflow/.local/lib/python3.8/site-packages/sqlalchemy/orm/session.py", line 1555, in _connection_for_bind
    return self._transaction._connection_for_bind(
  File "/home/airflow/.local/lib/python3.8/site-packages/sqlalchemy/orm/session.py", line 750, in _connection_for_bind
    conn = bind.connect()
  File "/home/airflow/.local/lib/python3.8/site-packages/sqlalchemy/future/engine.py", line 412, in connect
    return super(Engine, self).connect()
  File "/home/airflow/.local/lib/python3.8/site-packages/sqlalchemy/engine/base.py", line 3325, in connect
    return self._connection_cls(self, close_with_result=close_with_result)
  File "/home/airflow/.local/lib/python3.8/site-packages/sqlalchemy/engine/base.py", line 96, in __init__
    else engine.raw_connection()
  File "/home/airflow/.local/lib/python3.8/site-packages/sqlalchemy/engine/base.py", line 3404, in raw_connection
    return self._wrap_pool_connect(self.pool.connect, _connection)
  File "/home/airflow/.local/lib/python3.8/site-packages/sqlalchemy/engine/base.py", line 3374, in _wrap_pool_connect
    Connection._handle_dbapi_exception_noconnection(
  File "/home/airflow/.local/lib/python3.8/site-packages/sqlalchemy/engine/base.py", line 2208, in _handle_dbapi_exception_noconnection
    util.raise_(
  File "/home/airflow/.local/lib/python3.8/site-packages/sqlalchemy/util/compat.py", line 211, in raise_
    raise exception
  File "/home/airflow/.local/lib/python3.8/site-packages/sqlalchemy/engine/base.py", line 3371, in _wrap_pool_connect
    return fn()
  File "/home/airflow/.local/lib/python3.8/site-packages/sqlalchemy/pool/base.py", line 327, in connect
    return _ConnectionFairy._checkout(self)
  File "/home/airflow/.local/lib/python3.8/site-packages/sqlalchemy/pool/base.py", line 894, in _checkout
    fairy = _ConnectionRecord.checkout(pool)
  File "/home/airflow/.local/lib/python3.8/site-packages/sqlalchemy/pool/base.py", line 493, in checkout
    rec = pool._do_get()
  File "/home/airflow/.local/lib/python3.8/site-packages/sqlalchemy/pool/impl.py", line 146, in _do_get
    self._dec_overflow()
  File "/home/airflow/.local/lib/python3.8/site-packages/sqlalchemy/util/langhelpers.py", line 70, in __exit__
    compat.raise_(
  File "/home/airflow/.local/lib/python3.8/site-packages/sqlalchemy/util/compat.py", line 211, in raise_
    raise exception
  File "/home/airflow/.local/lib/python3.8/site-packages/sqlalchemy/pool/impl.py", line 143, in _do_get
    return self._create_connection()
  File "/home/airflow/.local/lib/python3.8/site-packages/sqlalchemy/pool/base.py", line 273, in _create_connection
    return _ConnectionRecord(self)
  File "/home/airflow/.local/lib/python3.8/site-packages/sqlalchemy/pool/base.py", line 388, in __init__
    self.__connect()
  File "/home/airflow/.local/lib/python3.8/site-packages/sqlalchemy/pool/base.py", line 691, in __connect
    pool.logger.debug("Error on connect(): %s", e)
  File "/home/airflow/.local/lib/python3.8/site-packages/sqlalchemy/util/langhelpers.py", line 70, in __exit__
    compat.raise_(
  File "/home/airflow/.local/lib/python3.8/site-packages/sqlalchemy/util/compat.py", line 211, in raise_
    raise exception
  File "/home/airflow/.local/lib/python3.8/site-packages/sqlalchemy/pool/base.py", line 686, in __connect
    self.dbapi_connection = connection = pool._invoke_creator(self)
  File "/home/airflow/.local/lib/python3.8/site-packages/sqlalchemy/engine/create.py", line 574, in connect
    return dialect.connect(*cargs, **cparams)
  File "/home/airflow/.local/lib/python3.8/site-packages/sqlalchemy/engine/default.py", line 598, in connect
    return self.dbapi.connect(*cargs, **cparams)
  File "/home/airflow/.local/lib/python3.8/site-packages/psycopg2/__init__.py", line 122, in connect
    conn = _connect(dsn, connection_factory=connection_factory, **kwasync)
sqlalchemy.exc.OperationalError: (psycopg2.OperationalError) could not translate host name "db" to address: Temporary failure in name resolution

(Background on this error at: https://sqlalche.me/e/14/e3q8)
[2025-08-18T23:22:17.855+0000] {processor.py:161} INFO - Started process (PID=1012) to work on /opt/airflow/dags/generate_data.py
[2025-08-18T23:22:17.857+0000] {processor.py:830} INFO - Processing file /opt/airflow/dags/generate_data.py for tasks to queue
[2025-08-18T23:22:17.860+0000] {logging_mixin.py:188} INFO - [2025-08-18T23:22:17.859+0000] {dagbag.py:540} INFO - Filling up the DagBag from /opt/airflow/dags/generate_data.py
[2025-08-18T23:22:18.128+0000] {processor.py:840} INFO - DAG(s) 'generate_data' retrieved from /opt/airflow/dags/generate_data.py
[2025-08-18T23:22:19.173+0000] {processor.py:186} ERROR - Got an exception! Propagating...
Traceback (most recent call last):
  File "/home/airflow/.local/lib/python3.8/site-packages/sqlalchemy/engine/base.py", line 3371, in _wrap_pool_connect
    return fn()
  File "/home/airflow/.local/lib/python3.8/site-packages/sqlalchemy/pool/base.py", line 327, in connect
    return _ConnectionFairy._checkout(self)
  File "/home/airflow/.local/lib/python3.8/site-packages/sqlalchemy/pool/base.py", line 894, in _checkout
    fairy = _ConnectionRecord.checkout(pool)
  File "/home/airflow/.local/lib/python3.8/site-packages/sqlalchemy/pool/base.py", line 493, in checkout
    rec = pool._do_get()
  File "/home/airflow/.local/lib/python3.8/site-packages/sqlalchemy/pool/impl.py", line 146, in _do_get
    self._dec_overflow()
  File "/home/airflow/.local/lib/python3.8/site-packages/sqlalchemy/util/langhelpers.py", line 70, in __exit__
    compat.raise_(
  File "/home/airflow/.local/lib/python3.8/site-packages/sqlalchemy/util/compat.py", line 211, in raise_
    raise exception
  File "/home/airflow/.local/lib/python3.8/site-packages/sqlalchemy/pool/impl.py", line 143, in _do_get
    return self._create_connection()
  File "/home/airflow/.local/lib/python3.8/site-packages/sqlalchemy/pool/base.py", line 273, in _create_connection
    return _ConnectionRecord(self)
  File "/home/airflow/.local/lib/python3.8/site-packages/sqlalchemy/pool/base.py", line 388, in __init__
    self.__connect()
  File "/home/airflow/.local/lib/python3.8/site-packages/sqlalchemy/pool/base.py", line 691, in __connect
    pool.logger.debug("Error on connect(): %s", e)
  File "/home/airflow/.local/lib/python3.8/site-packages/sqlalchemy/util/langhelpers.py", line 70, in __exit__
    compat.raise_(
  File "/home/airflow/.local/lib/python3.8/site-packages/sqlalchemy/util/compat.py", line 211, in raise_
    raise exception
  File "/home/airflow/.local/lib/python3.8/site-packages/sqlalchemy/pool/base.py", line 686, in __connect
    self.dbapi_connection = connection = pool._invoke_creator(self)
  File "/home/airflow/.local/lib/python3.8/site-packages/sqlalchemy/engine/create.py", line 574, in connect
    return dialect.connect(*cargs, **cparams)
  File "/home/airflow/.local/lib/python3.8/site-packages/sqlalchemy/engine/default.py", line 598, in connect
    return self.dbapi.connect(*cargs, **cparams)
  File "/home/airflow/.local/lib/python3.8/site-packages/psycopg2/__init__.py", line 122, in connect
    conn = _connect(dsn, connection_factory=connection_factory, **kwasync)
psycopg2.OperationalError: could not translate host name "db" to address: Temporary failure in name resolution


The above exception was the direct cause of the following exception:

Traceback (most recent call last):
  File "/home/airflow/.local/lib/python3.8/site-packages/airflow/dag_processing/processor.py", line 182, in _run_file_processor
    _handle_dag_file_processing()
  File "/home/airflow/.local/lib/python3.8/site-packages/airflow/dag_processing/processor.py", line 163, in _handle_dag_file_processing
    result: tuple[int, int] = dag_file_processor.process_file(
  File "/home/airflow/.local/lib/python3.8/site-packages/airflow/utils/session.py", line 79, in wrapper
    return func(*args, session=session, **kwargs)
  File "/home/airflow/.local/lib/python3.8/site-packages/airflow/dag_processing/processor.py", line 859, in process_file
    serialize_errors = DagFileProcessor.save_dag_to_db(
  File "/home/airflow/.local/lib/python3.8/site-packages/airflow/api_internal/internal_api_call.py", line 114, in wrapper
    return func(*args, **kwargs)
  File "/home/airflow/.local/lib/python3.8/site-packages/airflow/utils/session.py", line 79, in wrapper
    return func(*args, session=session, **kwargs)
  File "/home/airflow/.local/lib/python3.8/site-packages/airflow/dag_processing/processor.py", line 895, in save_dag_to_db
    import_errors = DagBag._sync_to_db(dags=dags, processor_subdir=dag_directory, session=session)
  File "/home/airflow/.local/lib/python3.8/site-packages/airflow/utils/session.py", line 76, in wrapper
    return func(*args, **kwargs)
  File "/home/airflow/.local/lib/python3.8/site-packages/airflow/models/dagbag.py", line 659, in _sync_to_db
    for attempt in run_with_db_retries(logger=log):
  File "/home/airflow/.local/lib/python3.8/site-packages/tenacity/__init__.py", line 347, in __iter__
    do = self.iter(retry_state=retry_state)
  File "/home/airflow/.local/lib/python3.8/site-packages/tenacity/__init__.py", line 325, in iter
    raise retry_exc.reraise()
  File "/home/airflow/.local/lib/python3.8/site-packages/tenacity/__init__.py", line 158, in reraise
    raise self.last_attempt.result()
  File "/usr/local/lib/python3.8/concurrent/futures/_base.py", line 437, in result
    return self.__get_result()
  File "/usr/local/lib/python3.8/concurrent/futures/_base.py", line 389, in __get_result
    raise self._exception
  File "/home/airflow/.local/lib/python3.8/site-packages/airflow/models/dagbag.py", line 672, in _sync_to_db
    _serialize_dag_capturing_errors(dag, session, processor_subdir)
  File "/home/airflow/.local/lib/python3.8/site-packages/airflow/models/dagbag.py", line 637, in _serialize_dag_capturing_errors
    dag_was_updated = SerializedDagModel.write_dag(
  File "/home/airflow/.local/lib/python3.8/site-packages/airflow/utils/session.py", line 76, in wrapper
    return func(*args, **kwargs)
  File "/home/airflow/.local/lib/python3.8/site-packages/airflow/models/serialized_dag.py", line 157, in write_dag
    if session.scalar(
  File "/home/airflow/.local/lib/python3.8/site-packages/sqlalchemy/orm/session.py", line 1747, in scalar
    return self.execute(
  File "/home/airflow/.local/lib/python3.8/site-packages/sqlalchemy/orm/session.py", line 1716, in execute
    conn = self._connection_for_bind(bind)
  File "/home/airflow/.local/lib/python3.8/site-packages/sqlalchemy/orm/session.py", line 1555, in _connection_for_bind
    return self._transaction._connection_for_bind(
  File "/home/airflow/.local/lib/python3.8/site-packages/sqlalchemy/orm/session.py", line 750, in _connection_for_bind
    conn = bind.connect()
  File "/home/airflow/.local/lib/python3.8/site-packages/sqlalchemy/future/engine.py", line 412, in connect
    return super(Engine, self).connect()
  File "/home/airflow/.local/lib/python3.8/site-packages/sqlalchemy/engine/base.py", line 3325, in connect
    return self._connection_cls(self, close_with_result=close_with_result)
  File "/home/airflow/.local/lib/python3.8/site-packages/sqlalchemy/engine/base.py", line 96, in __init__
    else engine.raw_connection()
  File "/home/airflow/.local/lib/python3.8/site-packages/sqlalchemy/engine/base.py", line 3404, in raw_connection
    return self._wrap_pool_connect(self.pool.connect, _connection)
  File "/home/airflow/.local/lib/python3.8/site-packages/sqlalchemy/engine/base.py", line 3374, in _wrap_pool_connect
    Connection._handle_dbapi_exception_noconnection(
  File "/home/airflow/.local/lib/python3.8/site-packages/sqlalchemy/engine/base.py", line 2208, in _handle_dbapi_exception_noconnection
    util.raise_(
  File "/home/airflow/.local/lib/python3.8/site-packages/sqlalchemy/util/compat.py", line 211, in raise_
    raise exception
  File "/home/airflow/.local/lib/python3.8/site-packages/sqlalchemy/engine/base.py", line 3371, in _wrap_pool_connect
    return fn()
  File "/home/airflow/.local/lib/python3.8/site-packages/sqlalchemy/pool/base.py", line 327, in connect
    return _ConnectionFairy._checkout(self)
  File "/home/airflow/.local/lib/python3.8/site-packages/sqlalchemy/pool/base.py", line 894, in _checkout
    fairy = _ConnectionRecord.checkout(pool)
  File "/home/airflow/.local/lib/python3.8/site-packages/sqlalchemy/pool/base.py", line 493, in checkout
    rec = pool._do_get()
  File "/home/airflow/.local/lib/python3.8/site-packages/sqlalchemy/pool/impl.py", line 146, in _do_get
    self._dec_overflow()
  File "/home/airflow/.local/lib/python3.8/site-packages/sqlalchemy/util/langhelpers.py", line 70, in __exit__
    compat.raise_(
  File "/home/airflow/.local/lib/python3.8/site-packages/sqlalchemy/util/compat.py", line 211, in raise_
    raise exception
  File "/home/airflow/.local/lib/python3.8/site-packages/sqlalchemy/pool/impl.py", line 143, in _do_get
    return self._create_connection()
  File "/home/airflow/.local/lib/python3.8/site-packages/sqlalchemy/pool/base.py", line 273, in _create_connection
    return _ConnectionRecord(self)
  File "/home/airflow/.local/lib/python3.8/site-packages/sqlalchemy/pool/base.py", line 388, in __init__
    self.__connect()
  File "/home/airflow/.local/lib/python3.8/site-packages/sqlalchemy/pool/base.py", line 691, in __connect
    pool.logger.debug("Error on connect(): %s", e)
  File "/home/airflow/.local/lib/python3.8/site-packages/sqlalchemy/util/langhelpers.py", line 70, in __exit__
    compat.raise_(
  File "/home/airflow/.local/lib/python3.8/site-packages/sqlalchemy/util/compat.py", line 211, in raise_
    raise exception
  File "/home/airflow/.local/lib/python3.8/site-packages/sqlalchemy/pool/base.py", line 686, in __connect
    self.dbapi_connection = connection = pool._invoke_creator(self)
  File "/home/airflow/.local/lib/python3.8/site-packages/sqlalchemy/engine/create.py", line 574, in connect
    return dialect.connect(*cargs, **cparams)
  File "/home/airflow/.local/lib/python3.8/site-packages/sqlalchemy/engine/default.py", line 598, in connect
    return self.dbapi.connect(*cargs, **cparams)
  File "/home/airflow/.local/lib/python3.8/site-packages/psycopg2/__init__.py", line 122, in connect
    conn = _connect(dsn, connection_factory=connection_factory, **kwasync)
sqlalchemy.exc.OperationalError: (psycopg2.OperationalError) could not translate host name "db" to address: Temporary failure in name resolution

(Background on this error at: https://sqlalche.me/e/14/e3q8)
[2025-08-18T23:22:49.528+0000] {processor.py:161} INFO - Started process (PID=1017) to work on /opt/airflow/dags/generate_data.py
[2025-08-18T23:22:49.530+0000] {processor.py:830} INFO - Processing file /opt/airflow/dags/generate_data.py for tasks to queue
[2025-08-18T23:22:49.532+0000] {logging_mixin.py:188} INFO - [2025-08-18T23:22:49.532+0000] {dagbag.py:540} INFO - Filling up the DagBag from /opt/airflow/dags/generate_data.py
[2025-08-18T23:22:49.760+0000] {processor.py:840} INFO - DAG(s) 'generate_data' retrieved from /opt/airflow/dags/generate_data.py
[2025-08-18T23:22:50.600+0000] {processor.py:186} ERROR - Got an exception! Propagating...
Traceback (most recent call last):
  File "/home/airflow/.local/lib/python3.8/site-packages/sqlalchemy/engine/base.py", line 3371, in _wrap_pool_connect
    return fn()
  File "/home/airflow/.local/lib/python3.8/site-packages/sqlalchemy/pool/base.py", line 327, in connect
    return _ConnectionFairy._checkout(self)
  File "/home/airflow/.local/lib/python3.8/site-packages/sqlalchemy/pool/base.py", line 894, in _checkout
    fairy = _ConnectionRecord.checkout(pool)
  File "/home/airflow/.local/lib/python3.8/site-packages/sqlalchemy/pool/base.py", line 493, in checkout
    rec = pool._do_get()
  File "/home/airflow/.local/lib/python3.8/site-packages/sqlalchemy/pool/impl.py", line 146, in _do_get
    self._dec_overflow()
  File "/home/airflow/.local/lib/python3.8/site-packages/sqlalchemy/util/langhelpers.py", line 70, in __exit__
    compat.raise_(
  File "/home/airflow/.local/lib/python3.8/site-packages/sqlalchemy/util/compat.py", line 211, in raise_
    raise exception
  File "/home/airflow/.local/lib/python3.8/site-packages/sqlalchemy/pool/impl.py", line 143, in _do_get
    return self._create_connection()
  File "/home/airflow/.local/lib/python3.8/site-packages/sqlalchemy/pool/base.py", line 273, in _create_connection
    return _ConnectionRecord(self)
  File "/home/airflow/.local/lib/python3.8/site-packages/sqlalchemy/pool/base.py", line 388, in __init__
    self.__connect()
  File "/home/airflow/.local/lib/python3.8/site-packages/sqlalchemy/pool/base.py", line 691, in __connect
    pool.logger.debug("Error on connect(): %s", e)
  File "/home/airflow/.local/lib/python3.8/site-packages/sqlalchemy/util/langhelpers.py", line 70, in __exit__
    compat.raise_(
  File "/home/airflow/.local/lib/python3.8/site-packages/sqlalchemy/util/compat.py", line 211, in raise_
    raise exception
  File "/home/airflow/.local/lib/python3.8/site-packages/sqlalchemy/pool/base.py", line 686, in __connect
    self.dbapi_connection = connection = pool._invoke_creator(self)
  File "/home/airflow/.local/lib/python3.8/site-packages/sqlalchemy/engine/create.py", line 574, in connect
    return dialect.connect(*cargs, **cparams)
  File "/home/airflow/.local/lib/python3.8/site-packages/sqlalchemy/engine/default.py", line 598, in connect
    return self.dbapi.connect(*cargs, **cparams)
  File "/home/airflow/.local/lib/python3.8/site-packages/psycopg2/__init__.py", line 122, in connect
    conn = _connect(dsn, connection_factory=connection_factory, **kwasync)
psycopg2.OperationalError: could not translate host name "db" to address: Temporary failure in name resolution


The above exception was the direct cause of the following exception:

Traceback (most recent call last):
  File "/home/airflow/.local/lib/python3.8/site-packages/airflow/dag_processing/processor.py", line 182, in _run_file_processor
    _handle_dag_file_processing()
  File "/home/airflow/.local/lib/python3.8/site-packages/airflow/dag_processing/processor.py", line 163, in _handle_dag_file_processing
    result: tuple[int, int] = dag_file_processor.process_file(
  File "/home/airflow/.local/lib/python3.8/site-packages/airflow/utils/session.py", line 79, in wrapper
    return func(*args, session=session, **kwargs)
  File "/home/airflow/.local/lib/python3.8/site-packages/airflow/dag_processing/processor.py", line 859, in process_file
    serialize_errors = DagFileProcessor.save_dag_to_db(
  File "/home/airflow/.local/lib/python3.8/site-packages/airflow/api_internal/internal_api_call.py", line 114, in wrapper
    return func(*args, **kwargs)
  File "/home/airflow/.local/lib/python3.8/site-packages/airflow/utils/session.py", line 79, in wrapper
    return func(*args, session=session, **kwargs)
  File "/home/airflow/.local/lib/python3.8/site-packages/airflow/dag_processing/processor.py", line 895, in save_dag_to_db
    import_errors = DagBag._sync_to_db(dags=dags, processor_subdir=dag_directory, session=session)
  File "/home/airflow/.local/lib/python3.8/site-packages/airflow/utils/session.py", line 76, in wrapper
    return func(*args, **kwargs)
  File "/home/airflow/.local/lib/python3.8/site-packages/airflow/models/dagbag.py", line 659, in _sync_to_db
    for attempt in run_with_db_retries(logger=log):
  File "/home/airflow/.local/lib/python3.8/site-packages/tenacity/__init__.py", line 347, in __iter__
    do = self.iter(retry_state=retry_state)
  File "/home/airflow/.local/lib/python3.8/site-packages/tenacity/__init__.py", line 325, in iter
    raise retry_exc.reraise()
  File "/home/airflow/.local/lib/python3.8/site-packages/tenacity/__init__.py", line 158, in reraise
    raise self.last_attempt.result()
  File "/usr/local/lib/python3.8/concurrent/futures/_base.py", line 437, in result
    return self.__get_result()
  File "/usr/local/lib/python3.8/concurrent/futures/_base.py", line 389, in __get_result
    raise self._exception
  File "/home/airflow/.local/lib/python3.8/site-packages/airflow/models/dagbag.py", line 672, in _sync_to_db
    _serialize_dag_capturing_errors(dag, session, processor_subdir)
  File "/home/airflow/.local/lib/python3.8/site-packages/airflow/models/dagbag.py", line 637, in _serialize_dag_capturing_errors
    dag_was_updated = SerializedDagModel.write_dag(
  File "/home/airflow/.local/lib/python3.8/site-packages/airflow/utils/session.py", line 76, in wrapper
    return func(*args, **kwargs)
  File "/home/airflow/.local/lib/python3.8/site-packages/airflow/models/serialized_dag.py", line 157, in write_dag
    if session.scalar(
  File "/home/airflow/.local/lib/python3.8/site-packages/sqlalchemy/orm/session.py", line 1747, in scalar
    return self.execute(
  File "/home/airflow/.local/lib/python3.8/site-packages/sqlalchemy/orm/session.py", line 1716, in execute
    conn = self._connection_for_bind(bind)
  File "/home/airflow/.local/lib/python3.8/site-packages/sqlalchemy/orm/session.py", line 1555, in _connection_for_bind
    return self._transaction._connection_for_bind(
  File "/home/airflow/.local/lib/python3.8/site-packages/sqlalchemy/orm/session.py", line 750, in _connection_for_bind
    conn = bind.connect()
  File "/home/airflow/.local/lib/python3.8/site-packages/sqlalchemy/future/engine.py", line 412, in connect
    return super(Engine, self).connect()
  File "/home/airflow/.local/lib/python3.8/site-packages/sqlalchemy/engine/base.py", line 3325, in connect
    return self._connection_cls(self, close_with_result=close_with_result)
  File "/home/airflow/.local/lib/python3.8/site-packages/sqlalchemy/engine/base.py", line 96, in __init__
    else engine.raw_connection()
  File "/home/airflow/.local/lib/python3.8/site-packages/sqlalchemy/engine/base.py", line 3404, in raw_connection
    return self._wrap_pool_connect(self.pool.connect, _connection)
  File "/home/airflow/.local/lib/python3.8/site-packages/sqlalchemy/engine/base.py", line 3374, in _wrap_pool_connect
    Connection._handle_dbapi_exception_noconnection(
  File "/home/airflow/.local/lib/python3.8/site-packages/sqlalchemy/engine/base.py", line 2208, in _handle_dbapi_exception_noconnection
    util.raise_(
  File "/home/airflow/.local/lib/python3.8/site-packages/sqlalchemy/util/compat.py", line 211, in raise_
    raise exception
  File "/home/airflow/.local/lib/python3.8/site-packages/sqlalchemy/engine/base.py", line 3371, in _wrap_pool_connect
    return fn()
  File "/home/airflow/.local/lib/python3.8/site-packages/sqlalchemy/pool/base.py", line 327, in connect
    return _ConnectionFairy._checkout(self)
  File "/home/airflow/.local/lib/python3.8/site-packages/sqlalchemy/pool/base.py", line 894, in _checkout
    fairy = _ConnectionRecord.checkout(pool)
  File "/home/airflow/.local/lib/python3.8/site-packages/sqlalchemy/pool/base.py", line 493, in checkout
    rec = pool._do_get()
  File "/home/airflow/.local/lib/python3.8/site-packages/sqlalchemy/pool/impl.py", line 146, in _do_get
    self._dec_overflow()
  File "/home/airflow/.local/lib/python3.8/site-packages/sqlalchemy/util/langhelpers.py", line 70, in __exit__
    compat.raise_(
  File "/home/airflow/.local/lib/python3.8/site-packages/sqlalchemy/util/compat.py", line 211, in raise_
    raise exception
  File "/home/airflow/.local/lib/python3.8/site-packages/sqlalchemy/pool/impl.py", line 143, in _do_get
    return self._create_connection()
  File "/home/airflow/.local/lib/python3.8/site-packages/sqlalchemy/pool/base.py", line 273, in _create_connection
    return _ConnectionRecord(self)
  File "/home/airflow/.local/lib/python3.8/site-packages/sqlalchemy/pool/base.py", line 388, in __init__
    self.__connect()
  File "/home/airflow/.local/lib/python3.8/site-packages/sqlalchemy/pool/base.py", line 691, in __connect
    pool.logger.debug("Error on connect(): %s", e)
  File "/home/airflow/.local/lib/python3.8/site-packages/sqlalchemy/util/langhelpers.py", line 70, in __exit__
    compat.raise_(
  File "/home/airflow/.local/lib/python3.8/site-packages/sqlalchemy/util/compat.py", line 211, in raise_
    raise exception
  File "/home/airflow/.local/lib/python3.8/site-packages/sqlalchemy/pool/base.py", line 686, in __connect
    self.dbapi_connection = connection = pool._invoke_creator(self)
  File "/home/airflow/.local/lib/python3.8/site-packages/sqlalchemy/engine/create.py", line 574, in connect
    return dialect.connect(*cargs, **cparams)
  File "/home/airflow/.local/lib/python3.8/site-packages/sqlalchemy/engine/default.py", line 598, in connect
    return self.dbapi.connect(*cargs, **cparams)
  File "/home/airflow/.local/lib/python3.8/site-packages/psycopg2/__init__.py", line 122, in connect
    conn = _connect(dsn, connection_factory=connection_factory, **kwasync)
sqlalchemy.exc.OperationalError: (psycopg2.OperationalError) could not translate host name "db" to address: Temporary failure in name resolution

(Background on this error at: https://sqlalche.me/e/14/e3q8)
[2025-08-18T23:23:20.816+0000] {processor.py:161} INFO - Started process (PID=1022) to work on /opt/airflow/dags/generate_data.py
[2025-08-18T23:23:20.817+0000] {processor.py:830} INFO - Processing file /opt/airflow/dags/generate_data.py for tasks to queue
[2025-08-18T23:23:20.818+0000] {logging_mixin.py:188} INFO - [2025-08-18T23:23:20.818+0000] {dagbag.py:540} INFO - Filling up the DagBag from /opt/airflow/dags/generate_data.py
[2025-08-18T23:23:21.032+0000] {processor.py:840} INFO - DAG(s) 'generate_data' retrieved from /opt/airflow/dags/generate_data.py
[2025-08-18T23:23:21.641+0000] {processor.py:186} ERROR - Got an exception! Propagating...
Traceback (most recent call last):
  File "/home/airflow/.local/lib/python3.8/site-packages/sqlalchemy/engine/base.py", line 3371, in _wrap_pool_connect
    return fn()
  File "/home/airflow/.local/lib/python3.8/site-packages/sqlalchemy/pool/base.py", line 327, in connect
    return _ConnectionFairy._checkout(self)
  File "/home/airflow/.local/lib/python3.8/site-packages/sqlalchemy/pool/base.py", line 894, in _checkout
    fairy = _ConnectionRecord.checkout(pool)
  File "/home/airflow/.local/lib/python3.8/site-packages/sqlalchemy/pool/base.py", line 493, in checkout
    rec = pool._do_get()
  File "/home/airflow/.local/lib/python3.8/site-packages/sqlalchemy/pool/impl.py", line 146, in _do_get
    self._dec_overflow()
  File "/home/airflow/.local/lib/python3.8/site-packages/sqlalchemy/util/langhelpers.py", line 70, in __exit__
    compat.raise_(
  File "/home/airflow/.local/lib/python3.8/site-packages/sqlalchemy/util/compat.py", line 211, in raise_
    raise exception
  File "/home/airflow/.local/lib/python3.8/site-packages/sqlalchemy/pool/impl.py", line 143, in _do_get
    return self._create_connection()
  File "/home/airflow/.local/lib/python3.8/site-packages/sqlalchemy/pool/base.py", line 273, in _create_connection
    return _ConnectionRecord(self)
  File "/home/airflow/.local/lib/python3.8/site-packages/sqlalchemy/pool/base.py", line 388, in __init__
    self.__connect()
  File "/home/airflow/.local/lib/python3.8/site-packages/sqlalchemy/pool/base.py", line 691, in __connect
    pool.logger.debug("Error on connect(): %s", e)
  File "/home/airflow/.local/lib/python3.8/site-packages/sqlalchemy/util/langhelpers.py", line 70, in __exit__
    compat.raise_(
  File "/home/airflow/.local/lib/python3.8/site-packages/sqlalchemy/util/compat.py", line 211, in raise_
    raise exception
  File "/home/airflow/.local/lib/python3.8/site-packages/sqlalchemy/pool/base.py", line 686, in __connect
    self.dbapi_connection = connection = pool._invoke_creator(self)
  File "/home/airflow/.local/lib/python3.8/site-packages/sqlalchemy/engine/create.py", line 574, in connect
    return dialect.connect(*cargs, **cparams)
  File "/home/airflow/.local/lib/python3.8/site-packages/sqlalchemy/engine/default.py", line 598, in connect
    return self.dbapi.connect(*cargs, **cparams)
  File "/home/airflow/.local/lib/python3.8/site-packages/psycopg2/__init__.py", line 122, in connect
    conn = _connect(dsn, connection_factory=connection_factory, **kwasync)
psycopg2.OperationalError: could not translate host name "db" to address: Temporary failure in name resolution


The above exception was the direct cause of the following exception:

Traceback (most recent call last):
  File "/home/airflow/.local/lib/python3.8/site-packages/airflow/dag_processing/processor.py", line 182, in _run_file_processor
    _handle_dag_file_processing()
  File "/home/airflow/.local/lib/python3.8/site-packages/airflow/dag_processing/processor.py", line 163, in _handle_dag_file_processing
    result: tuple[int, int] = dag_file_processor.process_file(
  File "/home/airflow/.local/lib/python3.8/site-packages/airflow/utils/session.py", line 79, in wrapper
    return func(*args, session=session, **kwargs)
  File "/home/airflow/.local/lib/python3.8/site-packages/airflow/dag_processing/processor.py", line 859, in process_file
    serialize_errors = DagFileProcessor.save_dag_to_db(
  File "/home/airflow/.local/lib/python3.8/site-packages/airflow/api_internal/internal_api_call.py", line 114, in wrapper
    return func(*args, **kwargs)
  File "/home/airflow/.local/lib/python3.8/site-packages/airflow/utils/session.py", line 79, in wrapper
    return func(*args, session=session, **kwargs)
  File "/home/airflow/.local/lib/python3.8/site-packages/airflow/dag_processing/processor.py", line 895, in save_dag_to_db
    import_errors = DagBag._sync_to_db(dags=dags, processor_subdir=dag_directory, session=session)
  File "/home/airflow/.local/lib/python3.8/site-packages/airflow/utils/session.py", line 76, in wrapper
    return func(*args, **kwargs)
  File "/home/airflow/.local/lib/python3.8/site-packages/airflow/models/dagbag.py", line 659, in _sync_to_db
    for attempt in run_with_db_retries(logger=log):
  File "/home/airflow/.local/lib/python3.8/site-packages/tenacity/__init__.py", line 347, in __iter__
    do = self.iter(retry_state=retry_state)
  File "/home/airflow/.local/lib/python3.8/site-packages/tenacity/__init__.py", line 325, in iter
    raise retry_exc.reraise()
  File "/home/airflow/.local/lib/python3.8/site-packages/tenacity/__init__.py", line 158, in reraise
    raise self.last_attempt.result()
  File "/usr/local/lib/python3.8/concurrent/futures/_base.py", line 437, in result
    return self.__get_result()
  File "/usr/local/lib/python3.8/concurrent/futures/_base.py", line 389, in __get_result
    raise self._exception
  File "/home/airflow/.local/lib/python3.8/site-packages/airflow/models/dagbag.py", line 672, in _sync_to_db
    _serialize_dag_capturing_errors(dag, session, processor_subdir)
  File "/home/airflow/.local/lib/python3.8/site-packages/airflow/models/dagbag.py", line 637, in _serialize_dag_capturing_errors
    dag_was_updated = SerializedDagModel.write_dag(
  File "/home/airflow/.local/lib/python3.8/site-packages/airflow/utils/session.py", line 76, in wrapper
    return func(*args, **kwargs)
  File "/home/airflow/.local/lib/python3.8/site-packages/airflow/models/serialized_dag.py", line 157, in write_dag
    if session.scalar(
  File "/home/airflow/.local/lib/python3.8/site-packages/sqlalchemy/orm/session.py", line 1747, in scalar
    return self.execute(
  File "/home/airflow/.local/lib/python3.8/site-packages/sqlalchemy/orm/session.py", line 1716, in execute
    conn = self._connection_for_bind(bind)
  File "/home/airflow/.local/lib/python3.8/site-packages/sqlalchemy/orm/session.py", line 1555, in _connection_for_bind
    return self._transaction._connection_for_bind(
  File "/home/airflow/.local/lib/python3.8/site-packages/sqlalchemy/orm/session.py", line 750, in _connection_for_bind
    conn = bind.connect()
  File "/home/airflow/.local/lib/python3.8/site-packages/sqlalchemy/future/engine.py", line 412, in connect
    return super(Engine, self).connect()
  File "/home/airflow/.local/lib/python3.8/site-packages/sqlalchemy/engine/base.py", line 3325, in connect
    return self._connection_cls(self, close_with_result=close_with_result)
  File "/home/airflow/.local/lib/python3.8/site-packages/sqlalchemy/engine/base.py", line 96, in __init__
    else engine.raw_connection()
  File "/home/airflow/.local/lib/python3.8/site-packages/sqlalchemy/engine/base.py", line 3404, in raw_connection
    return self._wrap_pool_connect(self.pool.connect, _connection)
  File "/home/airflow/.local/lib/python3.8/site-packages/sqlalchemy/engine/base.py", line 3374, in _wrap_pool_connect
    Connection._handle_dbapi_exception_noconnection(
  File "/home/airflow/.local/lib/python3.8/site-packages/sqlalchemy/engine/base.py", line 2208, in _handle_dbapi_exception_noconnection
    util.raise_(
  File "/home/airflow/.local/lib/python3.8/site-packages/sqlalchemy/util/compat.py", line 211, in raise_
    raise exception
  File "/home/airflow/.local/lib/python3.8/site-packages/sqlalchemy/engine/base.py", line 3371, in _wrap_pool_connect
    return fn()
  File "/home/airflow/.local/lib/python3.8/site-packages/sqlalchemy/pool/base.py", line 327, in connect
    return _ConnectionFairy._checkout(self)
  File "/home/airflow/.local/lib/python3.8/site-packages/sqlalchemy/pool/base.py", line 894, in _checkout
    fairy = _ConnectionRecord.checkout(pool)
  File "/home/airflow/.local/lib/python3.8/site-packages/sqlalchemy/pool/base.py", line 493, in checkout
    rec = pool._do_get()
  File "/home/airflow/.local/lib/python3.8/site-packages/sqlalchemy/pool/impl.py", line 146, in _do_get
    self._dec_overflow()
  File "/home/airflow/.local/lib/python3.8/site-packages/sqlalchemy/util/langhelpers.py", line 70, in __exit__
    compat.raise_(
  File "/home/airflow/.local/lib/python3.8/site-packages/sqlalchemy/util/compat.py", line 211, in raise_
    raise exception
  File "/home/airflow/.local/lib/python3.8/site-packages/sqlalchemy/pool/impl.py", line 143, in _do_get
    return self._create_connection()
  File "/home/airflow/.local/lib/python3.8/site-packages/sqlalchemy/pool/base.py", line 273, in _create_connection
    return _ConnectionRecord(self)
  File "/home/airflow/.local/lib/python3.8/site-packages/sqlalchemy/pool/base.py", line 388, in __init__
    self.__connect()
  File "/home/airflow/.local/lib/python3.8/site-packages/sqlalchemy/pool/base.py", line 691, in __connect
    pool.logger.debug("Error on connect(): %s", e)
  File "/home/airflow/.local/lib/python3.8/site-packages/sqlalchemy/util/langhelpers.py", line 70, in __exit__
    compat.raise_(
  File "/home/airflow/.local/lib/python3.8/site-packages/sqlalchemy/util/compat.py", line 211, in raise_
    raise exception
  File "/home/airflow/.local/lib/python3.8/site-packages/sqlalchemy/pool/base.py", line 686, in __connect
    self.dbapi_connection = connection = pool._invoke_creator(self)
  File "/home/airflow/.local/lib/python3.8/site-packages/sqlalchemy/engine/create.py", line 574, in connect
    return dialect.connect(*cargs, **cparams)
  File "/home/airflow/.local/lib/python3.8/site-packages/sqlalchemy/engine/default.py", line 598, in connect
    return self.dbapi.connect(*cargs, **cparams)
  File "/home/airflow/.local/lib/python3.8/site-packages/psycopg2/__init__.py", line 122, in connect
    conn = _connect(dsn, connection_factory=connection_factory, **kwasync)
sqlalchemy.exc.OperationalError: (psycopg2.OperationalError) could not translate host name "db" to address: Temporary failure in name resolution

(Background on this error at: https://sqlalche.me/e/14/e3q8)
[2025-08-18T23:23:52.106+0000] {processor.py:161} INFO - Started process (PID=1027) to work on /opt/airflow/dags/generate_data.py
[2025-08-18T23:23:52.108+0000] {processor.py:830} INFO - Processing file /opt/airflow/dags/generate_data.py for tasks to queue
[2025-08-18T23:23:52.112+0000] {logging_mixin.py:188} INFO - [2025-08-18T23:23:52.110+0000] {dagbag.py:540} INFO - Filling up the DagBag from /opt/airflow/dags/generate_data.py
[2025-08-18T23:23:52.460+0000] {processor.py:840} INFO - DAG(s) 'generate_data' retrieved from /opt/airflow/dags/generate_data.py
[2025-08-18T23:23:53.391+0000] {processor.py:186} ERROR - Got an exception! Propagating...
Traceback (most recent call last):
  File "/home/airflow/.local/lib/python3.8/site-packages/sqlalchemy/engine/base.py", line 3371, in _wrap_pool_connect
    return fn()
  File "/home/airflow/.local/lib/python3.8/site-packages/sqlalchemy/pool/base.py", line 327, in connect
    return _ConnectionFairy._checkout(self)
  File "/home/airflow/.local/lib/python3.8/site-packages/sqlalchemy/pool/base.py", line 894, in _checkout
    fairy = _ConnectionRecord.checkout(pool)
  File "/home/airflow/.local/lib/python3.8/site-packages/sqlalchemy/pool/base.py", line 493, in checkout
    rec = pool._do_get()
  File "/home/airflow/.local/lib/python3.8/site-packages/sqlalchemy/pool/impl.py", line 146, in _do_get
    self._dec_overflow()
  File "/home/airflow/.local/lib/python3.8/site-packages/sqlalchemy/util/langhelpers.py", line 70, in __exit__
    compat.raise_(
  File "/home/airflow/.local/lib/python3.8/site-packages/sqlalchemy/util/compat.py", line 211, in raise_
    raise exception
  File "/home/airflow/.local/lib/python3.8/site-packages/sqlalchemy/pool/impl.py", line 143, in _do_get
    return self._create_connection()
  File "/home/airflow/.local/lib/python3.8/site-packages/sqlalchemy/pool/base.py", line 273, in _create_connection
    return _ConnectionRecord(self)
  File "/home/airflow/.local/lib/python3.8/site-packages/sqlalchemy/pool/base.py", line 388, in __init__
    self.__connect()
  File "/home/airflow/.local/lib/python3.8/site-packages/sqlalchemy/pool/base.py", line 691, in __connect
    pool.logger.debug("Error on connect(): %s", e)
  File "/home/airflow/.local/lib/python3.8/site-packages/sqlalchemy/util/langhelpers.py", line 70, in __exit__
    compat.raise_(
  File "/home/airflow/.local/lib/python3.8/site-packages/sqlalchemy/util/compat.py", line 211, in raise_
    raise exception
  File "/home/airflow/.local/lib/python3.8/site-packages/sqlalchemy/pool/base.py", line 686, in __connect
    self.dbapi_connection = connection = pool._invoke_creator(self)
  File "/home/airflow/.local/lib/python3.8/site-packages/sqlalchemy/engine/create.py", line 574, in connect
    return dialect.connect(*cargs, **cparams)
  File "/home/airflow/.local/lib/python3.8/site-packages/sqlalchemy/engine/default.py", line 598, in connect
    return self.dbapi.connect(*cargs, **cparams)
  File "/home/airflow/.local/lib/python3.8/site-packages/psycopg2/__init__.py", line 122, in connect
    conn = _connect(dsn, connection_factory=connection_factory, **kwasync)
psycopg2.OperationalError: could not translate host name "db" to address: Temporary failure in name resolution


The above exception was the direct cause of the following exception:

Traceback (most recent call last):
  File "/home/airflow/.local/lib/python3.8/site-packages/airflow/dag_processing/processor.py", line 182, in _run_file_processor
    _handle_dag_file_processing()
  File "/home/airflow/.local/lib/python3.8/site-packages/airflow/dag_processing/processor.py", line 163, in _handle_dag_file_processing
    result: tuple[int, int] = dag_file_processor.process_file(
  File "/home/airflow/.local/lib/python3.8/site-packages/airflow/utils/session.py", line 79, in wrapper
    return func(*args, session=session, **kwargs)
  File "/home/airflow/.local/lib/python3.8/site-packages/airflow/dag_processing/processor.py", line 859, in process_file
    serialize_errors = DagFileProcessor.save_dag_to_db(
  File "/home/airflow/.local/lib/python3.8/site-packages/airflow/api_internal/internal_api_call.py", line 114, in wrapper
    return func(*args, **kwargs)
  File "/home/airflow/.local/lib/python3.8/site-packages/airflow/utils/session.py", line 79, in wrapper
    return func(*args, session=session, **kwargs)
  File "/home/airflow/.local/lib/python3.8/site-packages/airflow/dag_processing/processor.py", line 895, in save_dag_to_db
    import_errors = DagBag._sync_to_db(dags=dags, processor_subdir=dag_directory, session=session)
  File "/home/airflow/.local/lib/python3.8/site-packages/airflow/utils/session.py", line 76, in wrapper
    return func(*args, **kwargs)
  File "/home/airflow/.local/lib/python3.8/site-packages/airflow/models/dagbag.py", line 659, in _sync_to_db
    for attempt in run_with_db_retries(logger=log):
  File "/home/airflow/.local/lib/python3.8/site-packages/tenacity/__init__.py", line 347, in __iter__
    do = self.iter(retry_state=retry_state)
  File "/home/airflow/.local/lib/python3.8/site-packages/tenacity/__init__.py", line 325, in iter
    raise retry_exc.reraise()
  File "/home/airflow/.local/lib/python3.8/site-packages/tenacity/__init__.py", line 158, in reraise
    raise self.last_attempt.result()
  File "/usr/local/lib/python3.8/concurrent/futures/_base.py", line 437, in result
    return self.__get_result()
  File "/usr/local/lib/python3.8/concurrent/futures/_base.py", line 389, in __get_result
    raise self._exception
  File "/home/airflow/.local/lib/python3.8/site-packages/airflow/models/dagbag.py", line 672, in _sync_to_db
    _serialize_dag_capturing_errors(dag, session, processor_subdir)
  File "/home/airflow/.local/lib/python3.8/site-packages/airflow/models/dagbag.py", line 637, in _serialize_dag_capturing_errors
    dag_was_updated = SerializedDagModel.write_dag(
  File "/home/airflow/.local/lib/python3.8/site-packages/airflow/utils/session.py", line 76, in wrapper
    return func(*args, **kwargs)
  File "/home/airflow/.local/lib/python3.8/site-packages/airflow/models/serialized_dag.py", line 157, in write_dag
    if session.scalar(
  File "/home/airflow/.local/lib/python3.8/site-packages/sqlalchemy/orm/session.py", line 1747, in scalar
    return self.execute(
  File "/home/airflow/.local/lib/python3.8/site-packages/sqlalchemy/orm/session.py", line 1716, in execute
    conn = self._connection_for_bind(bind)
  File "/home/airflow/.local/lib/python3.8/site-packages/sqlalchemy/orm/session.py", line 1555, in _connection_for_bind
    return self._transaction._connection_for_bind(
  File "/home/airflow/.local/lib/python3.8/site-packages/sqlalchemy/orm/session.py", line 750, in _connection_for_bind
    conn = bind.connect()
  File "/home/airflow/.local/lib/python3.8/site-packages/sqlalchemy/future/engine.py", line 412, in connect
    return super(Engine, self).connect()
  File "/home/airflow/.local/lib/python3.8/site-packages/sqlalchemy/engine/base.py", line 3325, in connect
    return self._connection_cls(self, close_with_result=close_with_result)
  File "/home/airflow/.local/lib/python3.8/site-packages/sqlalchemy/engine/base.py", line 96, in __init__
    else engine.raw_connection()
  File "/home/airflow/.local/lib/python3.8/site-packages/sqlalchemy/engine/base.py", line 3404, in raw_connection
    return self._wrap_pool_connect(self.pool.connect, _connection)
  File "/home/airflow/.local/lib/python3.8/site-packages/sqlalchemy/engine/base.py", line 3374, in _wrap_pool_connect
    Connection._handle_dbapi_exception_noconnection(
  File "/home/airflow/.local/lib/python3.8/site-packages/sqlalchemy/engine/base.py", line 2208, in _handle_dbapi_exception_noconnection
    util.raise_(
  File "/home/airflow/.local/lib/python3.8/site-packages/sqlalchemy/util/compat.py", line 211, in raise_
    raise exception
  File "/home/airflow/.local/lib/python3.8/site-packages/sqlalchemy/engine/base.py", line 3371, in _wrap_pool_connect
    return fn()
  File "/home/airflow/.local/lib/python3.8/site-packages/sqlalchemy/pool/base.py", line 327, in connect
    return _ConnectionFairy._checkout(self)
  File "/home/airflow/.local/lib/python3.8/site-packages/sqlalchemy/pool/base.py", line 894, in _checkout
    fairy = _ConnectionRecord.checkout(pool)
  File "/home/airflow/.local/lib/python3.8/site-packages/sqlalchemy/pool/base.py", line 493, in checkout
    rec = pool._do_get()
  File "/home/airflow/.local/lib/python3.8/site-packages/sqlalchemy/pool/impl.py", line 146, in _do_get
    self._dec_overflow()
  File "/home/airflow/.local/lib/python3.8/site-packages/sqlalchemy/util/langhelpers.py", line 70, in __exit__
    compat.raise_(
  File "/home/airflow/.local/lib/python3.8/site-packages/sqlalchemy/util/compat.py", line 211, in raise_
    raise exception
  File "/home/airflow/.local/lib/python3.8/site-packages/sqlalchemy/pool/impl.py", line 143, in _do_get
    return self._create_connection()
  File "/home/airflow/.local/lib/python3.8/site-packages/sqlalchemy/pool/base.py", line 273, in _create_connection
    return _ConnectionRecord(self)
  File "/home/airflow/.local/lib/python3.8/site-packages/sqlalchemy/pool/base.py", line 388, in __init__
    self.__connect()
  File "/home/airflow/.local/lib/python3.8/site-packages/sqlalchemy/pool/base.py", line 691, in __connect
    pool.logger.debug("Error on connect(): %s", e)
  File "/home/airflow/.local/lib/python3.8/site-packages/sqlalchemy/util/langhelpers.py", line 70, in __exit__
    compat.raise_(
  File "/home/airflow/.local/lib/python3.8/site-packages/sqlalchemy/util/compat.py", line 211, in raise_
    raise exception
  File "/home/airflow/.local/lib/python3.8/site-packages/sqlalchemy/pool/base.py", line 686, in __connect
    self.dbapi_connection = connection = pool._invoke_creator(self)
  File "/home/airflow/.local/lib/python3.8/site-packages/sqlalchemy/engine/create.py", line 574, in connect
    return dialect.connect(*cargs, **cparams)
  File "/home/airflow/.local/lib/python3.8/site-packages/sqlalchemy/engine/default.py", line 598, in connect
    return self.dbapi.connect(*cargs, **cparams)
  File "/home/airflow/.local/lib/python3.8/site-packages/psycopg2/__init__.py", line 122, in connect
    conn = _connect(dsn, connection_factory=connection_factory, **kwasync)
sqlalchemy.exc.OperationalError: (psycopg2.OperationalError) could not translate host name "db" to address: Temporary failure in name resolution

(Background on this error at: https://sqlalche.me/e/14/e3q8)
[2025-08-18T23:27:47.184+0000] {processor.py:161} INFO - Started process (PID=205) to work on /opt/airflow/dags/generate_data.py
[2025-08-18T23:27:47.189+0000] {processor.py:830} INFO - Processing file /opt/airflow/dags/generate_data.py for tasks to queue
[2025-08-18T23:27:47.195+0000] {logging_mixin.py:188} INFO - [2025-08-18T23:27:47.194+0000] {dagbag.py:540} INFO - Filling up the DagBag from /opt/airflow/dags/generate_data.py
[2025-08-18T23:27:48.244+0000] {processor.py:840} INFO - DAG(s) 'generate_data' retrieved from /opt/airflow/dags/generate_data.py
[2025-08-18T23:27:48.936+0000] {logging_mixin.py:188} INFO - [2025-08-18T23:27:48.935+0000] {dag.py:3047} INFO - Sync 1 DAGs
[2025-08-18T23:27:49.053+0000] {logging_mixin.py:188} INFO - [2025-08-18T23:27:49.052+0000] {dag.py:3834} INFO - Setting next_dagrun for generate_data to 2025-08-18 00:00:00+00:00, run_after=2025-08-19 00:00:00+00:00
[2025-08-18T23:27:49.136+0000] {processor.py:183} INFO - Processing /opt/airflow/dags/generate_data.py took 1.973 seconds
[2025-08-18T23:28:19.628+0000] {processor.py:161} INFO - Started process (PID=216) to work on /opt/airflow/dags/generate_data.py
[2025-08-18T23:28:19.630+0000] {processor.py:830} INFO - Processing file /opt/airflow/dags/generate_data.py for tasks to queue
[2025-08-18T23:28:19.643+0000] {logging_mixin.py:188} INFO - [2025-08-18T23:28:19.637+0000] {dagbag.py:540} INFO - Filling up the DagBag from /opt/airflow/dags/generate_data.py
[2025-08-18T23:28:20.216+0000] {processor.py:840} INFO - DAG(s) 'generate_data' retrieved from /opt/airflow/dags/generate_data.py
[2025-08-18T23:28:20.321+0000] {logging_mixin.py:188} INFO - [2025-08-18T23:28:20.321+0000] {dag.py:3047} INFO - Sync 1 DAGs
[2025-08-18T23:28:20.480+0000] {logging_mixin.py:188} INFO - [2025-08-18T23:28:20.479+0000] {dag.py:3834} INFO - Setting next_dagrun for generate_data to 2025-08-18 00:00:00+00:00, run_after=2025-08-19 00:00:00+00:00
[2025-08-18T23:28:20.568+0000] {processor.py:183} INFO - Processing /opt/airflow/dags/generate_data.py took 0.965 seconds
[2025-08-18T23:28:50.990+0000] {processor.py:161} INFO - Started process (PID=227) to work on /opt/airflow/dags/generate_data.py
[2025-08-18T23:28:50.992+0000] {processor.py:830} INFO - Processing file /opt/airflow/dags/generate_data.py for tasks to queue
[2025-08-18T23:28:50.997+0000] {logging_mixin.py:188} INFO - [2025-08-18T23:28:50.995+0000] {dagbag.py:540} INFO - Filling up the DagBag from /opt/airflow/dags/generate_data.py
[2025-08-18T23:28:51.464+0000] {processor.py:840} INFO - DAG(s) 'generate_data' retrieved from /opt/airflow/dags/generate_data.py
[2025-08-18T23:28:51.586+0000] {logging_mixin.py:188} INFO - [2025-08-18T23:28:51.586+0000] {dag.py:3047} INFO - Sync 1 DAGs
[2025-08-18T23:28:51.652+0000] {logging_mixin.py:188} INFO - [2025-08-18T23:28:51.651+0000] {dag.py:3834} INFO - Setting next_dagrun for generate_data to 2025-08-18 00:00:00+00:00, run_after=2025-08-19 00:00:00+00:00
[2025-08-18T23:28:51.700+0000] {processor.py:183} INFO - Processing /opt/airflow/dags/generate_data.py took 0.722 seconds
